<?xml version="1.0" encoding="UTF-8" ?>

<robot name="Golem" xmlns:xacro="http://ros.org/wiki/xacro">

<!-- ****************************************************** Golem Robot **************************************************************  -->
<!-- Muthanna Alwahash                                                                                                                  -->
<!-- March 2022                                                                                                                         -->
<!-- *********************************************************************************************************************************  -->

<!-- ****************************************************** Parameters ***************************************************************  --> 

    <xacro:property name="mesh_path"            value="package://robot_gazebo/meshes/golem/"/>
    <xacro:property name="body_length_x"        value="0.3556"/>
    <xacro:property name="body_length_y"        value="0.165"/>
    <xacro:property name="coxa_length"          value="0.05893"/>
    <xacro:property name="femur_length"         value="0.10798"/>
    <xacro:property name="tibia_length"         value="0.08774"/>
    <xacro:property name="tarsus_length"        value="0.12065"/>

    <xacro:property name="joint_lower_limit"    value="-${radians(180)}"/>
    <xacro:property name="joint_upper_limit"    value=" ${radians(180)}"/>
    <xacro:property name="joint_effort"         value=" 6.0"/>
    <xacro:property name="joint_velocity"       value=" ${radians(300)}"/>

<!-- ****************************************************** Colors *******************************************************************  -->

    <material name="red">
        <color rgba="1.0 0.0 0.0 1.0"/>
    </material>

    <material name="green">
        <color rgba="0.0 1.0 0.0 1.0"/>
    </material>

    <material name="blue">
        <color rgba="0.0 0.0 1.0 1.0"/>
    </material>

    <material name="black">
        <color rgba="0.3 0.3 0.3 1.0"/>
    </material>

    <material name="white">
        <color rgba="1.0 1.0 1.0 1.0"/>
    </material>

<!-- ****************************************************** Base Footprint ***********************************************************  -->

    <link name="base_footprint"/>

<!-- ****************************************************** Base Joint ***************************************************************  -->

    <joint name="base_joint" type="fixed">
        <parent link="base_footprint"/>
        <child link="base_link"/>
        <origin xyz="0.0 0.0 0.064" rpy="0.0 0.0 0.0"/>
    </joint>

<!-- ****************************************************** Base Link ****************************************************************  -->

    <link name="base_link">
        <visual>
            <origin xyz="0.0 0.0 0.0" rpy="0.0 0.0 0.0"/>
            <geometry>
                <mesh filename="${mesh_path}body.stl" scale="0.001 0.001 0.001"/>
            </geometry>
            <material name="blue"/>
        </visual>
        <collision>
            <origin xyz="0.0 0.0 0.0" rpy="0.0 0.0 0.0"/>
            <geometry>
                <mesh filename="${mesh_path}body.stl" scale="0.001 0.001 0.001"/>
            </geometry>
            <material name="blue"/>
        </collision>
        <inertial>
            <origin xyz="0.0 0.0 0.0" rpy="0.0 0.0 0.0" />
            <mass value="0.00001"/>
            <inertia
                ixx="1.0" ixy="0.0"  ixz="0.0"
                iyy="1.0" iyz="0.0"
                izz="1.0" />
        </inertial>
    </link>

    <gazebo reference="base_link"> 
        <material>Gazebo/Blue</material> 
    </gazebo> 

<!-- ****************************************************** Camera RGB Joint *********************************************************  -->
    
    <joint name="camera_rgb_joint" type="fixed">
        <parent link="base_link"/>
        <child link="camera_rgb_optical_frame"/>
        <origin xyz="0.150 0.0255 0.034" rpy="${pi/2} ${pi} ${pi/2}"/>
    </joint>

<!-- ****************************************************** Camera RGB Optical Frame Link ********************************************  -->

    <link name="camera_rgb_optical_frame">
        <inertial>
            <origin xyz="0.0 0.0 0.0" rpy="0.0 0.0 0.0" />
            <mass value="0.00001"/>
            <inertia
                ixx="1.0" ixy="0.0"  ixz="0.0"
                iyy="1.0" iyz="0.0"
                izz="1.0" />
        </inertial>
    </link>

<!-- ****************************************************** Camera Depth Joint *******************************************************  -->

    <joint name="camera_depth_joint" type="fixed">
        <parent link="base_link"/>
        <child link="camera_depth_optical_frame"/>
        <origin xyz="0.150 -0.0225 0.034" rpy="${pi/2} ${pi} ${pi/2}"/>
    </joint>

<!-- ****************************************************** Camera Depth Optical Frame Link ****************************************** -->

    <link name="camera_depth_optical_frame">
        <inertial>
            <origin xyz="0.0 0.0 0.0" rpy="0.0 0.0 0.0" />
            <mass value="0.00001"/>
            <inertia
                ixx="1.0" ixy="0.0"  ixz="0.0"
                iyy="1.0" iyz="0.0"
                izz="1.0" />
        </inertial>
    </link>

<!-- ****************************************************** IMU Joint ****************************************************************  -->
    
    <joint name="imu_joint" type="fixed">
        <parent link="base_link"/>
        <child link="imu_link"/>
        <origin xyz="0.0 0.0 0.034" rpy="0.0 0.0 0.0"/>
    </joint>

<!-- ****************************************************** IMU Link *****************************************************************  -->

    <link name="imu_link">
        <inertial>
            <origin xyz="0.0 0.0 0.0" rpy="0.0 0.0 0.0" />
            <mass value="0.00001"/>
            <inertia
                ixx="1.0" ixy="0.0"  ixz="0.0"
                iyy="1.0" iyz="0.0"
                izz="1.0" />
        </inertial>
    </link>

<!-- ****************************************************** Pan Joint ****************************************************************  -->

    <joint name="pan_joint" type="revolute">
        <parent link="base_link"/>
        <child link="pan_link"/>
        <origin xyz="0.1 0.0 0.034" rpy="0.0 0.0 0.0"/>
        <axis xyz="0.0 0.0 1.0"/>
        <limit lower="${joint_lower_limit}" upper="${joint_upper_limit}" effort="${joint_effort}" velocity="${joint_velocity}"/>
    </joint>

<!-- ****************************************************** Pan Link *****************************************************************  -->

    <link name="pan_link">
        <inertial>
            <origin xyz="0.0 0.0 0.0" rpy="0.0 0.0 0.0" />
            <mass value="0.00001"/>
            <inertia
                ixx="1.0" ixy="0.0"  ixz="0.0"
                iyy="1.0" iyz="0.0"
                izz="1.0" />
        </inertial>
    </link>

<!-- ****************************************************** Leg Macro ****************************************************************  -->

    <xacro:macro name="leg" params="side position x y angle axis">

<!-- ****************************************************** Leg Center Joint *********************************************************  -->

    <joint name="leg_center_joint_${side}${position}" type="fixed">
        <origin xyz="${x} ${y} 0.0" rpy="0.0 0.0 0.0"/>
        <parent link="base_link"/>
        <child link="leg_center_${side}${position}"/>
    </joint>

<!-- ****************************************************** Leg Center Link **********************************************************  -->

    <link name="leg_center_${side}${position}">
        <inertial>
            <origin xyz="0.0 0.0 0.0" rpy="0.0 0.0 0.0" />
            <mass value="0.00001"/>
            <inertia
                ixx="1.0" ixy="0.0"  ixz="0.0"
                iyy="1.0" iyz="0.0"
                izz="1.0" />
        </inertial>
    </link>

<!-- ****************************************************** Coxa Joint ***************************************************************  -->

    <joint name="coxa_joint_${side}${position}" type="revolute">
        <origin xyz="0.0 0.0 0.0" rpy="0.0 0.0 ${angle}"/>
        <parent link="leg_center_${side}${position}"/>
        <child link="coxa_${side}${position}"/>
        <axis xyz="0.0 0.0 1.0"/>
        <limit lower="${joint_lower_limit}" upper="${joint_upper_limit}" effort="${joint_effort}" velocity="${joint_velocity}"/>
    </joint>

<!-- ****************************************************** Coxa Transmission ********************************************************  -->

    <transmission name="coxa_transmission_${side}${position}">
        <type>transmission_interface/SimpleTransmission</type>
        <joint name="coxa_joint_${side}${position}">
            <hardwareInterface>EffortJointInterface</hardwareInterface>
        </joint>
        <actuator name="coxa_motor_${side}${position}">
            <hardwareInterface>EffortJointInterface</hardwareInterface>
            <mechanicalReduction>1</mechanicalReduction>
        </actuator>
    </transmission>

<!-- ****************************************************** Coxa Link ****************************************************************  -->

    <link name="coxa_${side}${position}">
        <visual>
            <origin xyz="0.0 0.0 0.0" rpy="0.0 0.0 0.0"/>
            <geometry>
                <mesh filename="${mesh_path}coxa.stl" scale="0.001 0.001 0.001"/>
            </geometry>
            <material name="green"/>
        </visual>
        <collision>
            <origin xyz="0.0 0.0 0.0" rpy="0.0 0.0 0.0" />
            <geometry>
                <mesh filename="${mesh_path}coxa.stl" scale="0.001 0.001 0.001"/>
            </geometry>
            <material name="green"/>
        </collision>
        <inertial>
            <origin xyz="0.0 0.0 0.0" rpy="0.0 0.0 0.0" />
            <mass value="0.00001"/>
            <inertia
                ixx="1.0" ixy="0.0"  ixz="0.0"
                iyy="1.0" iyz="0.0"
                izz="1.0" />
        </inertial>
    </link>

    <gazebo reference="coxa_${side}${position}"> 
        <material>Gazebo/Green</material> 
    </gazebo> 

<!-- ****************************************************** Femur Joint **************************************************************  -->

    <joint name="femur_joint_${side}${position}" type="revolute">
        <origin xyz="${coxa_length} 0.0 0.0" rpy="-${pi/2} ${pi/2} 0.0"/>
        <parent link="coxa_${side}${position}"/>
        <child link="femur_${side}${position}"/>
        <axis xyz="0.0 0.0 ${axis}"/>
        <limit lower="${joint_lower_limit}" upper="${joint_upper_limit}" effort="${joint_effort}" velocity="${joint_velocity}"/>
    </joint>

<!-- ****************************************************** Femur Transmission *******************************************************  -->

    <transmission name="femur_transmission_${side}${position}">
        <type>transmission_interface/SimpleTransmission</type>
        <joint name="femur_joint_${side}${position}">
            <hardwareInterface>EffortJointInterface</hardwareInterface>
        </joint>
        <actuator name="femur_motor_${side}${position}">
            <hardwareInterface>EffortJointInterface</hardwareInterface>
            <mechanicalReduction>1</mechanicalReduction>
        </actuator>
    </transmission>

<!-- ****************************************************** Femur Link ***************************************************************  -->

    <link name="femur_${side}${position}">
        <visual>
            <origin xyz="0.0 0.0 0.0" rpy="0.0 0.0 0.0"/>
            <geometry>
                <mesh filename="${mesh_path}femur.stl" scale="0.001 0.001 0.001"/>
            </geometry>
            <material name="red"/>
        </visual>
        <collision>
            <origin xyz="0.0 0.0 0.0" rpy="0.0 0.0 0.0" />
            <geometry>
                <mesh filename="${mesh_path}femur.stl" scale="0.001 0.001 0.001"/>
            </geometry>
            <material name="read"/>
        </collision>
        <inertial>
            <origin xyz="0.0 0.0 0.0" rpy="0.0 0.0 0.0" />
            <mass value="0.00001"/>
            <inertia
                ixx="1.0" ixy="0.0"  ixz="0.0"
                iyy="1.0" iyz="0.0"
                izz="1.0" />
        </inertial>
    </link>
    
    <gazebo reference="femur_${side}${position}"> 
        <material>Gazebo/Red</material> 
    </gazebo> 
<!-- ****************************************************** Tibia Joint **************************************************************  -->

    <joint name="tibia_joint_${side}${position}" type="revolute">
        <origin xyz="0.0 -${femur_length} 0.0" rpy="${pi} 0.0 0.0"/>
        <parent link="femur_${side}${position}"/>
        <child link="tibia_${side}${position}"/>
        <axis xyz="0.0 0.0 ${axis}"/>
        <limit lower="${joint_lower_limit}" upper="${joint_upper_limit}" effort="${joint_effort}" velocity="${joint_velocity}"/>
    </joint>

<!-- ****************************************************** Tibia Transmission *******************************************************  -->

    <transmission name="tibia_transmission_${side}${position}">
        <type>transmission_interface/SimpleTransmission</type>
        <joint name="tibia_joint_${side}${position}">
            <hardwareInterface>EffortJointInterface</hardwareInterface>
        </joint>
        <actuator name="tibia_motor_${side}${position}">
            <hardwareInterface>EffortJointInterface</hardwareInterface>
            <mechanicalReduction>1</mechanicalReduction>
        </actuator>
    </transmission>

<!-- ****************************************************** Tibia Link ***************************************************************  -->

    <link name="tibia_${side}${position}">
        <visual>
            <origin xyz="0.0 0.0 0.0" rpy="0.0 0.0 0.0"/>
            <geometry>
                <mesh filename="${mesh_path}tibia.stl" scale="0.001 0.001 0.001"/>
            </geometry>
            <material name="green"/>
        </visual>
        <collision>
            <origin xyz="0.0 0.0 0.0" rpy="0.0 0.0 0.0" />
            <geometry>
                <mesh filename="${mesh_path}tibia.stl" scale="0.001 0.001 0.001"/>
            </geometry>
            <material name="green"/>
        </collision>
        <inertial>
            <origin xyz="0.0 0.0 0.0" rpy="0.0 0.0 0.0" />
            <mass value="0.00001"/>
            <inertia
                ixx="1.0" ixy="0.0"  ixz="0.0"
                iyy="1.0" iyz="0.0"
                izz="1.0" />
        </inertial>
    </link>
    
    <gazebo reference="tibia_${side}${position}"> 
        <material>Gazebo/Green</material> 
    </gazebo> 

<!-- ****************************************************** Tarsus Joint *************************************************************  -->
    
    <joint name="tarsus_joint_${side}${position}" type="revolute">
        <origin xyz="${tibia_length} 0.0 0.0" rpy="0.0 0.0 0.0"/>
        <parent link="tibia_${side}${position}"/>
        <child link="tarsus_${side}${position}"/>
        <axis xyz="0.0 0.0 ${axis}"/>
        <limit lower="${joint_lower_limit}" upper="${joint_upper_limit}" effort="${joint_effort}" velocity="${joint_velocity}"/>
    </joint>
    
<!-- ****************************************************** Tarsus Transmission ******************************************************  -->

    <transmission name="tarsus_transmission_${side}${position}">
        <type>transmission_interface/SimpleTransmission</type>
        <joint name="tarsus_joint_${side}${position}">
            <hardwareInterface>EffortJointInterface</hardwareInterface>
        </joint>
        <actuator name="tarsus_motor_${side}${position}">
            <hardwareInterface>EffortJointInterface</hardwareInterface>
            <mechanicalReduction>1</mechanicalReduction>
        </actuator>
    </transmission>
    
<!-- ****************************************************** Tarsus Link **************************************************************  -->

    <link name="tarsus_${side}${position}">
        <visual>
            <origin xyz="0.0 0.0 0.0" rpy="0.0 0.0 0.0"/>
            <geometry>
                <mesh filename="${mesh_path}tarsus.stl" scale="0.001 0.001 0.001"/>
            </geometry>
            <material name="red"/>
        </visual>
        <collision>
            <origin xyz="0.0 0.0 0.0" rpy="0.0 0.0 0.0" />
            <geometry>
                <mesh filename="${mesh_path}tarsus.stl" scale="0.001 0.001 0.001"/>
            </geometry>
            <material name="red"/>
        </collision>
        <inertial>
            <origin xyz="0.0 0.0 0.0" rpy="0.0 0.0 0.0" />
            <mass value="0.00001"/>
            <inertia
                ixx="1.0" ixy="0.0"  ixz="0.0"
                iyy="1.0" iyz="0.0"
                izz="1.0" />
        </inertial>
    </link>
    
    <gazebo reference="tarsus_${side}${position}"> 
            <material>Gazebo/Red</material> 
    </gazebo> 
<!-- ****************************************************** Foot Joint ***************************************************************  -->

    <joint name="foot_joint_${side}${position}" type="fixed">
        <origin xyz="${tarsus_length} 0.0 0.0" rpy="0.0 0.0 0.0" />
        <parent link="tarsus_${side}${position}" />
        <child link="foot_${side}${position}" />
    </joint>

<!-- ****************************************************** Foot Link ****************************************************************  -->

    <link name="foot_${side}${position}">
        <inertial>
            <origin xyz="0.0 0.0 0.0" rpy="0.0 0.0 0.0" />
            <mass value="0.00001"/>
            <inertia
                ixx="1.0" ixy="0.0"  ixz="0.0"
                iyy="1.0" iyz="0.0"
                izz="1.0" />
        </inertial>
    </link>

<!-- ******************************************************  End of Macro ************************************************************  -->

    </xacro:macro>

<!-- ****************************************************** Build Robot Model ********************************************************  -->
 
    <xacro:leg side="R" position="R" x="-0.1778" y="-0.0825"  angle="-${pi*3/4}" axis="1"/>
    <xacro:leg side="R" position="M" x="0.0"     y="-0.13335" angle="-${pi/2}"   axis="1"/>
    <xacro:leg side="R" position="F" x="0.1778"  y="-0.0825"  angle="-${pi/4}"   axis="1"/>
    <xacro:leg side="L" position="R" x="-0.1778" y="0.0825"   angle="${pi*3/4}"  axis="-1"/>
    <xacro:leg side="L" position="M" x="0.0"     y="0.13335"  angle="${pi/2}"    axis="-1"/>
    <xacro:leg side="L" position="F" x="0.1778"  y="0.0825"   angle="${pi/4}"    axis="-1"/>

<!-- ******************************************************  End *********************************************************************  -->

</robot>
