<?xml version="1.0"?>

<robot name="kr3r540" xmlns:xacro="http://wiki.ros.org/xacro">

<!-- ****************************************************** Parameters ***************************************************************  --> 

  <xacro:property name="mesh_path" value="package://robot_gazebo/meshes/kr3r540/"/>

<!-- ****************************************************** Includes *****************************************************************  --> 

  <xacro:include filename="$(find robot_gazebo)/xacro/common_rviz_materials.xacro" />   <!-- RVIZ Colors                                -->
  <xacro:include filename="$(find robot_gazebo)/gazebo/gz_kr3r540.xacro" />             <!-- Gazebo                                     -->

<!-- ****************************************************** Macro ******************************************************************** -->

  <xacro:macro name="kuka_kr3r540" params="parent prefix">

<!-- ****************************************************** LINKS ******************************************************************** -->
<!-- ****************************************************** base link **************************************************************** -->

    <link name="${prefix}base_link">
      <inertial>
        <origin xyz="0 0 0" rpy="0 0 0" />
        <mass value="1.0" />
        <inertia
            ixx="0" ixy="0" ixz="0"
            iyy="0" iyz="0"
            izz="0" />
      </inertial>
      <visual>
        <origin xyz="0 0 0" rpy="0 0 0" />
        <geometry>
          <mesh filename="${mesh_path}visual/base_link.stl" />
        </geometry>
        <xacro:material_kuka_pedestal />
      </visual>
      <collision>
        <origin xyz="0 0 0" rpy="0 0 0" />
        <geometry>
          <mesh filename="${mesh_path}collision/base_link.stl" />
        </geometry>
      </collision>
    </link>

<!-- ****************************************************** link 1 (A1) ************************************************************** -->

    <link name="${prefix}link_1">
      <inertial>
        <origin xyz="0 0 0" rpy="0 0 0" />
        <mass value="1.0" />
        <inertia
            ixx="0" ixy="0" ixz="0"
            iyy="0" iyz="0"
            izz="0" />
      </inertial>
      <visual>
        <origin xyz="0 0 0" rpy="0 0 0" />
        <geometry>
          <mesh filename="${mesh_path}visual/link_1.stl" />
        </geometry>
        <xacro:material_kuka_ral_pure_white />
      </visual>
      <collision>
        <origin xyz="0 0 0" rpy="0 0 0" />
        <geometry>
          <mesh filename="${mesh_path}collision/link_1.stl" />
        </geometry>
      </collision>
    </link>

<!-- ****************************************************** link 2 ******************************************************************* -->
    
    <link name="${prefix}link_2">
      <inertial>
        <origin xyz="0 0 0" rpy="0 0 0" />
        <mass value="1.0" />
        <inertia
            ixx="0" ixy="0" ixz="0"
            iyy="0" iyz="0"
            izz="0" />
      </inertial>
      <visual>
        <origin xyz="0 0 0" rpy="0 0 0" />
        <geometry>
          <mesh filename="${mesh_path}visual/link_2.stl" />
        </geometry>
        <xacro:material_kuka_ral_pure_white />
      </visual>
      <collision>
        <origin xyz="0 0 0" rpy="0 0 0" />
        <geometry>
          <mesh filename="${mesh_path}collision/link_2.stl" />
        </geometry>
      </collision>
    </link>

<!-- ****************************************************** link 2 ******************************************************************* -->

    <link name="${prefix}link_3">
      <inertial>
        <origin xyz="0 0 0" rpy="0 0 0" />
        <mass value="1.0" />
        <inertia
            ixx="0" ixy="0" ixz="0"
            iyy="0" iyz="0"
            izz="0" />
      </inertial>
      <visual>
        <origin xyz="0 0 0" rpy="0 0 0" />
        <geometry>
          <mesh filename="${mesh_path}visual/link_3.stl" />
        </geometry>
        <xacro:material_kuka_ral_pure_white />
      </visual>
      <collision>
        <origin xyz="0 0 0" rpy="0 0 0" />
        <geometry>
          <mesh filename="${mesh_path}collision/link_3.stl" />
        </geometry>
      </collision>
    </link>

<!-- ****************************************************** link 4 ******************************************************************* -->

    <link name="${prefix}link_4">
      <inertial>
        <origin xyz="0 0 0" rpy="0 0 0" />
        <mass value="1.0" />
        <inertia
            ixx="0" ixy="0" ixz="0"
            iyy="0" iyz="0"
            izz="0" />
      </inertial>
      <visual>
        <origin xyz="0 0 0" rpy="0 0 0" />
        <geometry>
          <mesh filename="${mesh_path}visual/link_4.stl" />
        </geometry>
        <xacro:material_kuka_ral_pure_white />
      </visual>
      <collision>
        <origin xyz="0 0 0" rpy="0 0 0" />
        <geometry>
          <mesh filename="${mesh_path}collision/link_4.stl" />
        </geometry>
      </collision>
    </link>
    
<!-- ****************************************************** link 5 ******************************************************************* -->

    <link name="${prefix}link_5">
      <inertial>
        <origin xyz="0 0 0" rpy="0 0 0" />
        <mass value="1.0" />
        <inertia
            ixx="0" ixy="0" ixz="0"
            iyy="0" iyz="0"
            izz="0" />
      </inertial>    
      <visual>
        <origin xyz="0 0 0" rpy="0 0 0" />
        <geometry>
          <mesh filename="${mesh_path}visual/link_5.stl" />
        </geometry>
        <xacro:material_kuka_ral_pure_white />
      </visual>
      <collision>
        <origin xyz="0 0 0" rpy="0 0 0" />
        <geometry>
          <mesh filename="${mesh_path}collision/link_5.stl" />
        </geometry>
      </collision>
    </link>

<!-- ****************************************************** link 6 ******************************************************************* -->

    <link name="${prefix}link_6">
      <inertial>
        <origin xyz="0 0 0" rpy="0 0 0" />
        <mass value="1.0" />
        <inertia
            ixx="0" ixy="0" ixz="0"
            iyy="0" iyz="0"
            izz="0" />
      </inertial>
      <visual>
        <origin xyz="0 0 0" rpy="0 0 0" />
        <geometry>
          <mesh filename="${mesh_path}visual/link_6.stl" />
        </geometry>
        <xacro:material_kuka_pedestal />
      </visual>
      <collision>
        <origin xyz="0 0 0" rpy="0 0 0" />
        <geometry>
          <mesh filename="${mesh_path}collision/link_6.stl" />
        </geometry>
      </collision>
    </link>

<!-- ****************************************************** tool 0 ******************************************************************* -->
<!-- ************************************** Following REP199, this frame shall be use to attach EEF or other equipment *************** -->
    
    <link name="${prefix}flange" />
    
<!-- ****************************************************** END LINKS **************************************************************** -->

<!-- ****************************************************** JOINTS ******************************************************************* -->

<!-- ****************************************************** Base Joint ***************************************************************  -->

    <joint name="${prefix}base_joint" type="fixed">
      <origin xyz="0 0 0" rpy="0 0 0" />
      <parent link="${parent}"/>
      <child link="${prefix}base_link" />
    </joint>

<!-- ****************************************************** joint 1 (A1) ************************************************************* -->
    
    <joint name="${prefix}joint_a1" type="revolute">
      <origin xyz="0 0 0.345" rpy="0 0 0"/>
      <parent link="${prefix}base_link"/>
      <child link="${prefix}link_1"/>
      <axis xyz="0 0 -1"/>
      <limit lower="${radians(-170)}" upper="${radians(170)}" effort="0" velocity="${radians(530)}"/>
    </joint>
    
<!-- ****************************************************** joint 2 (A2) ************************************************************* -->

    <joint name="${prefix}joint_a2" type="revolute">
      <origin xyz="0.020 0 0" rpy="0 0 0"/>
      <parent link="${prefix}link_1"/>
      <child link="${prefix}link_2"/>
      <axis xyz="0 1 0"/>
      <limit lower="${radians(-170)}" upper="${radians(50)}" effort="0" velocity="${radians(529)}"/>
    </joint>
    
<!-- ****************************************************** joint 3 (A3) ************************************************************* -->

    <joint name="${prefix}joint_a3" type="revolute">
      <origin xyz="0.260 0 0" rpy="0 0 0"/>
      <parent link="${prefix}link_2"/>
      <child link="${prefix}link_3"/>
      <axis xyz="0 1 0"/>
      <limit lower="${radians(-110)}" upper="${radians(155)}" effort="0" velocity="${radians(538)}"/>
    </joint>
    
<!-- ****************************************************** joint 4 (A4) ************************************************************* -->

    <joint name="${prefix}joint_a4" type="revolute">
      <origin xyz="0 0 0.020" rpy="0 0 0"/>
      <parent link="${prefix}link_3"/>
      <child link="${prefix}link_4"/>
      <axis xyz="-1 0 0"/>
      <limit lower="${radians(-175)}" upper="${radians(175)}" effort="0" velocity="${radians(600)}"/>
    </joint>
    
<!-- ****************************************************** joint 5 (A5) ************************************************************* -->

    <joint name="${prefix}joint_a5" type="revolute">
      <origin xyz="0.260 0 0" rpy="0 0 0"/>
      <parent link="${prefix}link_4"/>
      <child link="${prefix}link_5"/>
      <axis xyz="0 1 0"/>
      <limit lower="${radians(-120)}" upper="${radians(120)}" effort="0" velocity="${radians(600)}"/>
    </joint>
    
<!-- ****************************************************** joint 6 (A6) ************************************************************* -->

    <joint name="${prefix}joint_a6" type="revolute">
      <origin xyz="0.075 0 0" rpy="0 0 0"/>
      <parent link="${prefix}link_5"/>
      <child link="${prefix}link_6"/>
      <axis xyz="-1 0 0"/>
      <limit lower="${radians(-350)}" upper="${radians(350)}" effort="0" velocity="${radians(800)}"/>
    </joint>
    
<!-- ****************************************************** tool frame - fixed frame ************************************************* -->

    <joint name="${prefix}joint_a6-tool0" type="fixed">
      <parent link="${prefix}link_6"/>
      <child link="${prefix}flange"/>
      <origin xyz="0 0 0" rpy="0 0 0"/>
    </joint>
    
<!-- ****************************************************** END JOINTS *************************************************************** -->

<!-- ****************************** ROS base_link to KUKA $ROBROOT coordinate system transform *************************************** -->
   
    <link name="${prefix}base" />

    <joint name="${prefix}base_link-base" type="fixed">
      <origin xyz="0 0 0" rpy="0 0 0"/>
      <parent link="${prefix}base_link"/>
      <child link="${prefix}base"/>
    </joint>

<!-- ********************** This frame corresponds to the $TOOL coordinate system in KUKA KRC controllers **************************** -->
    
    <link name="${prefix}tool0" />

    <joint name="${prefix}flange-tool0" type="fixed">
      <parent link="${prefix}flange"/>
      <child link="${prefix}tool0"/>
      <origin xyz="0 0 0" rpy="0 ${radians(90)} 0"/>
    </joint>
    
<!-- ****************************************************** End Macro **************************************************************** -->

  </xacro:macro>

<!-- ****************************************************** Generates a urdf from macro ********************************************** -->

  <xacro:kuka_kr3r540 parent="world" prefix=""/>
  
<!-- ****************************************************** End ********************************************************************** -->

</robot>
