<?xml version="1.0" ?>
<robot name="tb3_burger" xmlns:xacro="http://ros.org/wiki/xacro">

<!-- ****************************************************** Turtlebot 3 Burger Robot *************************************************  -->
<!-- Muthanna Alwahash                                                                                                                  -->
<!-- March 2022                                                                                                                         -->
<!-- *********************************************************************************************************************************  -->

<!-- ****************************************************** Includes *****************************************************************  --> 

  <xacro:include filename="$(find robot_gazebo)/xacro/common_rviz_materials.xacro" />   <!-- RVIZ Colors                                -->
  <xacro:include filename="$(find robot_gazebo)/gazebo/gz_tb3_burger.xacro" />          <!-- Gazebo                                     -->


<!-- ****************************************************** Base Footprint Link ******************************************************  -->
  
  <link name="base_footprint"/>

<!-- ****************************************************** Base Joint ***************************************************************  -->
  
  <joint name="base_joint" type="fixed">
    <parent link="base_footprint"/>
    <child link="base_link"/>
    <origin xyz="0.0 0.0 0.010" rpy="0 0 0"/>
  </joint>

<!-- ****************************************************** Base Link ****************************************************************  -->
  
  <link name="base_link">
    <visual>
      <origin xyz="-0.032 0 0.0" rpy="0 0 0"/>
      <geometry>
        <mesh filename="package://robot_gazebo/meshes/tb3/burger_base.stl" scale="0.001 0.001 0.001"/>
      </geometry>
      <material name="blue"/>
    </visual>
    <collision>
      <origin xyz="-0.032 0 0.070" rpy="0 0 0"/>
      <geometry>
        <box size="0.140 0.140 0.143"/>
      </geometry>
    </collision>
    <inertial>
      <origin xyz="0 0 0" rpy="0 0 0"/>
      <mass value="8.2573504e-01"/>
      <inertia ixx="2.2124416e-03" ixy="-1.2294101e-05" ixz="3.4938785e-05"
               iyy="2.1193702e-03" iyz="-5.0120904e-06" izz="2.0064271e-03" 
               />
    </inertial>
  </link>

<!-- ****************************************************** Wheel Left Joint *********************************************************  -->
  
  <joint name="wheel_left_joint" type="continuous">
    <parent link="base_link"/>
    <child link="wheel_left_link"/>
    <origin xyz="0.0 0.08 0.023" rpy="-1.57 0 0"/>
    <axis xyz="0 0 1"/>
  </joint>

<!-- ****************************************************** Wheel Left Link **********************************************************  -->
  
  <link name="wheel_left_link">
    <visual>
      <origin xyz="0 0 0" rpy="1.57 0 0"/>
      <geometry>
        <mesh filename="package://robot_gazebo/meshes/tb3/left_tire.stl" scale="0.001 0.001 0.001"/>
      </geometry>
      <material name="black"/>
    </visual>
    <collision>
      <origin xyz="0 0 0" rpy="0 0 0"/>
      <geometry>
        <cylinder length="0.018" radius="0.033"/>
      </geometry>
    </collision>
    <inertial>
      <origin xyz="0 0 0" />
      <mass value="2.8498940e-02" />
      <inertia ixx="1.1175580e-05" ixy="-4.2369783e-11" ixz="-5.9381719e-09" 
               iyy="1.1192413e-05" iyz="-1.4400107e-11" izz="2.0712558e-05" 
               />
    </inertial>
  </link>

<!-- ****************************************************** Wheel Right Joint ********************************************************  -->
  
  <joint name="wheel_right_joint" type="continuous">
    <parent link="base_link"/>
    <child link="wheel_right_link"/>
    <origin xyz="0.0 -0.080 0.023" rpy="-1.57 0 0"/>
    <axis xyz="0 0 1"/>
  </joint>

<!-- ****************************************************** Wheel Right Link *********************************************************  -->
  
  <link name="wheel_right_link">
      <visual>
      <origin xyz="0 0 0" rpy="1.57 0 0"/>
      <geometry>
        <mesh filename="package://robot_gazebo/meshes/tb3/right_tire.stl" scale="0.001 0.001 0.001"/>
      </geometry>
      <material name="black"/>
    </visual>
    <collision>
      <origin xyz="0 0 0" rpy="0 0 0"/>
      <geometry>
        <cylinder length="0.018" radius="0.033"/>
      </geometry>
    </collision>
    <inertial>
      <origin xyz="0 0 0" />
      <mass value="2.8498940e-02" />
      <inertia ixx="1.1175580e-05" ixy="-4.2369783e-11" ixz="-5.9381719e-09" 
               iyy="1.1192413e-05" iyz="-1.4400107e-11" izz="2.0712558e-05" 
               />
    </inertial>
  </link>

<!-- ****************************************************** Caster Back Joint ********************************************************  -->
  
  <joint name="caster_back_joint" type="fixed">
    <parent link="base_link"/>
    <child link="caster_back_link"/>
    <origin xyz="-0.081 0 -0.004" rpy="-1.57 0 0"/>
  </joint>

<!-- ****************************************************** Caster Back Link *********************************************************  -->
  
  <link name="caster_back_link">
    <visual>
      <geometry>
        <sphere radius="0.007"/>
      </geometry>
      <material name="white"/>
    </visual>
    <collision>
      <origin xyz="0 0.001 0" rpy="0 0 0"/>
      <geometry>
        <box size="0.030 0.009 0.020"/>
      </geometry>
    </collision>
    <inertial>
      <origin xyz="0 0 0" />
      <mass value="0.005" />
      <inertia ixx="0.001" ixy="0.0" ixz="0.0" 
               iyy="0.001" iyz="0.0" 
               izz="0.001" />
    </inertial>
  </link>

<!-- ****************************************************** IMU Joint ****************************************************************  -->
  
  <joint name="imu_joint" type="fixed">
    <parent link="base_link"/>
    <child link="imu_link"/>
    <origin xyz="-0.032 0 0.068" rpy="0 0 0"/>
  </joint>

<!-- ****************************************************** IMU Link *****************************************************************  -->
  
  <link name="imu_link"/>

<!-- ****************************************************** Laser Scan Joint *********************************************************  -->
  
  <joint name="scan_joint" type="fixed">
    <parent link="base_link"/>
    <child link="base_scan"/>
    <origin xyz="-0.032 0 0.172" rpy="0 0 0"/>
  </joint>

<!-- ****************************************************** Laser Scan Link **********************************************************  -->
  
  <link name="base_scan">
    <visual>
      <origin xyz="0 0 0.0" rpy="0 0 0"/>
      <geometry>
        <mesh filename="package://robot_gazebo/meshes/tb3/lds.stl" scale="0.001 0.001 0.001"/>
      </geometry>
      <material name="green"/>
    </visual>
    <collision>
      <origin xyz="0.015 0 -0.0065" rpy="0 0 0"/>
      <geometry>
        <cylinder length="0.0315" radius="0.055"/>
      </geometry>
    </collision>
    <inertial>
      <mass value="0.114" />
      <origin xyz="0 0 0" />
      <inertia ixx="0.001" ixy="0.0" ixz="0.0" 
               iyy="0.001" iyz="0.0" 
               izz="0.001" />
    </inertial>
  </link>

<!-- *********************************************************************************************************************************  -->
</robot>
