<?xml version="1.0" ?>

<robot name="gripper"  xmlns:xacro="http://ros.org/wiki/xacro">

<!-- ****************************************************** World Link *************************************************************** -->

  <link name="world"/>

<!-- ****************************************************** Base Link **************************************************************** -->

  <link name="base">
    <visual>
      <geometry>
        <box size="0.5 1 1"/>
      </geometry>
      <origin xyz="0 0 0.5"/>
      <material name="violet">
        <color rgba="0.4 0.18 0.57 1.0" />
      </material>
    </visual>
    <inertial>
      <mass value="50"/>
      <inertia ixx="1.0" ixy="0.0" ixz="0.0" iyy="1.0" iyz="0.0" izz="1.0"/>
    </inertial>
  </link>

  <gazebo reference="base">
    <material>Gazebo/Orange</material>
  </gazebo>

<!-- ****************************************************** finger_right Link ******************************************************** -->

  <link name="finger_right">
    <visual>
      <geometry>
        <box size="0.4 0.1 1"/>
      </geometry>
      <origin xyz="0 0.05 0.5"/>
      <material name="grey">
        <color rgba="0.2 0.2 0.2 1"/>
      </material>
    </visual>
    <inertial>
      <mass value="5"/>
      <inertia ixx="1.0" ixy="0.0" ixz="0.0" iyy="1.0" iyz="0.0" izz="1.0"/>
    </inertial>
  </link>

<!-- ****************************************************** finger_left Link ********************************************************* -->

  <link name="finger_left">
    <visual>
      <geometry>
        <box size="0.4 0.1 1"/>
      </geometry>
      <origin xyz="0 0.05 0.5"/>
      <material name="grey">
        <color rgba="0.2 0.2 0.2 1"/>
      </material>
    </visual>
    <inertial>
      <mass value="5"/>
      <inertia ixx="1.0" ixy="0.0" ixz="0.0" iyy="1.0" iyz="0.0" izz="1.0"/>
    </inertial>
  </link>

<!-- ****************************************************** world to base Joint ****************************************************** -->

  <joint name="world_to_base" type="fixed">
    <origin rpy="0 0 0" xyz="0 0 0"/>
    <parent link="world"/>
    <child link="base"/>
  </joint>

<!-- ****************************************************** right_finger Joint ******************************************************* -->

  <joint name="right_finger_joint" type="prismatic">
    <axis xyz="0 1 0"/>
    <origin xyz="0.0 -0.48 1" rpy="0.0 0.0 0.0"/>
    <parent link="base"/>
    <child link="finger_right"/>
    <limit effort="1000.0" lower="0" upper="0.38" velocity="10"/>
  </joint>

<!-- ****************************************************** left_finger Joint ******************************************************** -->

  <joint name="left_finger_joint" type="prismatic">
    <mimic joint="right_finger_joint"/>
    <axis xyz="0 1 0"/>
    <origin xyz="0.0 0.48 1" rpy="0.0 0.0 3.1415926535"/>
    <parent link="base"/>
    <child link="finger_left"/>
    <limit effort="1000.0" lower="0" upper="0.38" velocity="10"/>
  </joint>

<!-- ****************************************************** End ********************************************************************** -->

</robot>
