<sdf version='1.7'>
  <model name='skidbot'>
    <link name='footprint'>
      <inertial>
        <pose>0 0 0 0 -0 0</pose>
        <mass>15</mass>
        <inertia>
          <ixx>0.100002</ixx>
          <ixy>0</ixy>
          <ixz>-9.38298e-08</ixz>
          <iyy>0.100003</iyy>
          <iyz>0</iyz>
          <izz>0.100003</izz>
        </inertia>
      </inertial>
      <collision name='footprint_fixed_joint_lump__collision_collision'>
        <pose>0 0 0 0 -0 0</pose>
        <geometry>
          <mesh>
            <scale>1 1 1</scale>
            <uri>model://bots/meshes/skidbot/base.stl</uri>
          </mesh>
        </geometry>
      </collision>
      <collision name='footprint_fixed_joint_lump__camera_colision_collision_1'>
        <pose>0.2 0 0 0 -0 0</pose>
        <geometry>
          <box>
            <size>0.05 0.05 0.05</size>
          </box>
        </geometry>
      </collision>
      <collision name='footprint_fixed_joint_lump__hokuyo_colision_collision_2'>
        <pose>0.11 0 0.0853 0 -0 0</pose>
        <geometry>
          <box>
            <size>0.05 0.05 0.0706</size>
          </box>
        </geometry>
      </collision>
      <visual name='footprint_fixed_joint_lump__base_visual_visual'>
        <pose>0 0 0 0 -0 0</pose>
        <geometry>
          <mesh>
            <scale>1 1 1</scale>
            <uri>model://bots/meshes/skidbot/base.stl</uri>
          </mesh>
        </geometry>
        <material>
          <script>
            <name>Gazebo/Blue</name>
            <uri>file://media/materials/scripts/gazebo.material</uri>
          </script>
        </material>
      </visual>
      <visual name='footprint_fixed_joint_lump__camera_visual_visual_1'>
        <pose>0.2 0 0 0 -0 0</pose>
        <geometry>
          <box>
            <size>0.05 0.05 0.05</size>
          </box>
        </geometry>
      </visual>
      <visual name='footprint_fixed_joint_lump__hokuyo_visual_visual_2'>
        <pose>0.11 0 0.0853 0 -0 0</pose>
        <geometry>
          <mesh>
            <scale>1 1 1</scale>
            <uri>model://bots/meshes/skidbot/hokuyo.dae</uri>
          </mesh>
        </geometry>
      </visual>
    </link>
    <joint name='back_left_wheel_joint' type='revolute'>
      <pose relative_to='footprint'>-0.12 0.135 0 0 -0 0</pose>
      <parent>footprint</parent>
      <child>back_left_wheel</child>
      <axis>
        <xyz>0 1 0</xyz>
        <limit>
          <effort>10000</effort>
          <velocity>1000</velocity>
          <lower>-1e+16</lower>
          <upper>1e+16</upper>
        </limit>
        <dynamics>
          <damping>1</damping>
          <friction>1</friction>
          <spring_reference>0</spring_reference>
          <spring_stiffness>0</spring_stiffness>
        </dynamics>
      </axis>
    </joint>
    <link name='back_left_wheel'>
      <pose relative_to='back_left_wheel_joint'>0 0 0 0 -0 0</pose>
      <inertial>
        <pose>0 0 0 -1.5708 1.5708 0</pose>
        <mass>15</mass>
        <inertia>
          <ixx>0.1</ixx>
          <ixy>0</ixy>
          <ixz>0</ixz>
          <iyy>0.1</iyy>
          <iyz>0</iyz>
          <izz>0.1</izz>
        </inertia>
      </inertial>
      <collision name='back_left_wheel_collision'>
        <pose>0 0 0 -1.5708 1.5708 0</pose>
        <geometry>
          <mesh>
            <scale>1 1 1</scale>
            <uri>model://bots/meshes/skidbot/wheel.dae</uri>
          </mesh>
        </geometry>
      </collision>
      <visual name='back_left_wheel_visual'>
        <pose>0 0 0 -1.5708 1.5708 0</pose>
        <geometry>
          <mesh>
            <scale>1 1 1</scale>
            <uri>model://bots/meshes/skidbot/wheel.dae</uri>
          </mesh>
        </geometry>
      </visual>
    </link>
    <joint name='back_right_wheel_joint' type='revolute'>
      <pose relative_to='footprint'>-0.12 -0.135 0 0 -0 0</pose>
      <parent>footprint</parent>
      <child>back_right_wheel</child>
      <axis>
        <xyz>0 1 0</xyz>
        <limit>
          <effort>10000</effort>
          <velocity>1000</velocity>
          <lower>-1e+16</lower>
          <upper>1e+16</upper>
        </limit>
        <dynamics>
          <damping>1</damping>
          <friction>1</friction>
          <spring_reference>0</spring_reference>
          <spring_stiffness>0</spring_stiffness>
        </dynamics>
      </axis>
    </joint>
    <link name='back_right_wheel'>
      <pose relative_to='back_right_wheel_joint'>0 0 0 0 -0 0</pose>
      <inertial>
        <pose>0 0 0 -1.5708 1.5708 0</pose>
        <mass>15</mass>
        <inertia>
          <ixx>0.1</ixx>
          <ixy>0</ixy>
          <ixz>0</ixz>
          <iyy>0.1</iyy>
          <iyz>0</iyz>
          <izz>0.1</izz>
        </inertia>
      </inertial>
      <collision name='back_right_wheel_collision'>
        <pose>0 0 0 -1.5708 1.5708 0</pose>
        <geometry>
          <mesh>
            <scale>1 1 1</scale>
            <uri>model://bots/meshes/skidbot/wheel.dae</uri>
          </mesh>
        </geometry>
      </collision>
      <visual name='back_right_wheel_visual'>
        <pose>0 0 0 -1.5708 1.5708 0</pose>
        <geometry>
          <mesh>
            <scale>1 1 1</scale>
            <uri>model://bots/meshes/skidbot/wheel.dae</uri>
          </mesh>
        </geometry>
      </visual>
    </link>
    <joint name='front_left_wheel_joint' type='revolute'>
      <pose relative_to='footprint'>0.12 0.135 0 0 -0 0</pose>
      <parent>footprint</parent>
      <child>front_left_wheel</child>
      <axis>
        <xyz>0 1 0</xyz>
        <limit>
          <effort>10000</effort>
          <velocity>1000</velocity>
          <lower>-1e+16</lower>
          <upper>1e+16</upper>
        </limit>
        <dynamics>
          <damping>1</damping>
          <friction>1</friction>
          <spring_reference>0</spring_reference>
          <spring_stiffness>0</spring_stiffness>
        </dynamics>
      </axis>
    </joint>
    <link name='front_left_wheel'>
      <pose relative_to='front_left_wheel_joint'>0 0 0 0 -0 0</pose>
      <inertial>
        <pose>0 0 0 -1.5708 1.5708 0</pose>
        <mass>15</mass>
        <inertia>
          <ixx>0.1</ixx>
          <ixy>0</ixy>
          <ixz>0</ixz>
          <iyy>0.1</iyy>
          <iyz>0</iyz>
          <izz>0.1</izz>
        </inertia>
      </inertial>
      <collision name='front_left_wheel_collision'>
        <pose>0 0 0 -1.5708 1.5708 0</pose>
        <geometry>
          <mesh>
            <scale>1 1 1</scale>
            <uri>model://bots/meshes/skidbot/wheel.dae</uri>
          </mesh>
        </geometry>
      </collision>
      <visual name='front_left_wheel_visual'>
        <pose>0 0 0 -1.5708 1.5708 0</pose>
        <geometry>
          <mesh>
            <scale>1 1 1</scale>
            <uri>model://bots/meshes/skidbot/wheel.dae</uri>
          </mesh>
        </geometry>
      </visual>
    </link>
    <joint name='front_right_wheel_joint' type='revolute'>
      <pose relative_to='footprint'>0.12 -0.135 0 0 -0 0</pose>
      <parent>footprint</parent>
      <child>front_right_wheel</child>
      <axis>
        <xyz>0 1 0</xyz>
        <limit>
          <effort>10000</effort>
          <velocity>1000</velocity>
          <lower>-1e+16</lower>
          <upper>1e+16</upper>
        </limit>
        <dynamics>
          <damping>1</damping>
          <friction>1</friction>
          <spring_reference>0</spring_reference>
          <spring_stiffness>0</spring_stiffness>
        </dynamics>
      </axis>
    </joint>
    <link name='front_right_wheel'>
      <pose relative_to='front_right_wheel_joint'>0 0 0 0 -0 0</pose>
      <inertial>
        <pose>0 0 0 -1.5708 1.5708 0</pose>
        <mass>15</mass>
        <inertia>
          <ixx>0.1</ixx>
          <ixy>0</ixy>
          <ixz>0</ixz>
          <iyy>0.1</iyy>
          <iyz>0</iyz>
          <izz>0.1</izz>
        </inertia>
      </inertial>
      <collision name='front_right_wheel_collision'>
        <pose>0 0 0 -1.5708 1.5708 0</pose>
        <geometry>
          <mesh>
            <scale>1 1 1</scale>
            <uri>model://bots/meshes/skidbot/wheel.dae</uri>
          </mesh>
        </geometry>
      </collision>
      <visual name='front_right_wheel_visual'>
        <pose>0 0 0 -1.5708 1.5708 0</pose>
        <geometry>
          <mesh>
            <scale>1 1 1</scale>
            <uri>model://bots/meshes/skidbot/wheel.dae</uri>
          </mesh>
        </geometry>
      </visual>
    </link>
  </model>
</sdf>
