<?xml version="1.0" ?>
<!-- =================================================================================== -->
<!-- |    This document was autogenerated by xacro from src/robot_gazebo/xacro/bocbot.xacro | -->
<!-- |    EDITING THIS FILE BY HAND IS NOT RECOMMENDED                                 | -->
<!-- =================================================================================== -->
<robot name="bocbot">
  <!-- ****************************************************** bocbot Robot *************************************************************  -->
  <!-- Muthanna Alwahash                                                                                                                  -->
  <!-- March 2022                                                                                                                         -->
  <!-- *********************************************************************************************************************************  -->
  <!-- ****************************************************** Parameters ***************************************************************  -->
  <!-- ****************************************************** Includes *****************************************************************  -->
  <material name="red">
    <color rgba="1.0 0.0 0.0 1.0"/>
  </material>
  <material name="green">
    <color rgba="0.0 1.0 0.0 1.0"/>
  </material>
  <material name="blue">
    <color rgba="0.0 0.0 1.0 1.0"/>
  </material>
  <material name="black">
    <color rgba="0.3 0.3 0.3 1.0"/>
  </material>
  <material name="white">
    <color rgba="1.0 1.0 1.0 1.0"/>
  </material>
  <material name="grey">
    <color rgba="0.2 0.2 0.2 1.0"/>
  </material>
  <material name="orange">
    <color rgba="1.0 0.4235294117647059 0.0392156862745098 1.0"/>
  </material>
  <material name="brown">
    <color rgba="0.8705882352941177 0.8117647058823529 0.7647058823529411 1.0"/>
  </material>
  <material name="yellow">
    <color rgba="1.0 1.0 0.0 1.0"/>
  </material>
  <!-- ****************************************************** bocbot Robot *************************************************************  -->
  <!-- Muthanna Alwahash                                                                                                                  -->
  <!-- March 2022                                                                                                                         -->
  <!-- *********************************************************************************************************************************  -->
  <!-- ****************************************************** Base *********************************************************************  -->
  <gazebo reference="base">
    <material>Gazebo/Blue</material>
  </gazebo>
  <!-- ****************************************************** Front Left Wheel *********************************************************  -->
  <gazebo reference="front_left_wheel">
    <material>Gazebo/Gray</material>
  </gazebo>
  <!-- ****************************************************** Back Left Wheel **********************************************************  -->
  <gazebo reference="back_left_wheel">
    <material>Gazebo/Gray</material>
  </gazebo>
  <!-- ****************************************************** Front Right Wheel ********************************************************  -->
  <gazebo reference="front_right_wheel">
    <material>Gazebo/Gray</material>
  </gazebo>
  <!-- ****************************************************** Back Right Wheel *********************************************************  -->
  <gazebo reference="back_right_wheel">
    <material>Gazebo/Gray</material>
  </gazebo>
  <!-- ******************************************************  Joint States Pub ********************************************************  -->
  <gazebo>
    <plugin filename="libgazebo_ros_joint_state_publisher.so" name="joint_states_pub">
      <joint_name>front_left_wheel_joint</joint_name>
      <joint_name>back_left_wheel_joint</joint_name>
      <joint_name>front_right_wheel_joint</joint_name>
      <joint_name>back_right_wheel_joint</joint_name>
      <update_rate>100.0</update_rate>
    </plugin>
  </gazebo>
  <!-- ******************************************************  Skid Steer Drive Controller *********************************************  -->
  <gazebo>
    <plugin filename="libgazebo_ros_diff_drive.so" name="diff_drive">
      <ros>
        <namespace>bocbot</namespace>
        <argument>--remap cmd_vel:=cme_vel</argument>
        <argument>--remap odom:=odom</argument>
      </ros>
      <update_rate>100.0</update_rate>
      <num_wheel_pairs>2</num_wheel_pairs>
      <odometry_frame>odom</odometry_frame>
      <left_joint>front_left_wheel_joint</left_joint>
      <left_joint>back_left_wheel_joint</left_joint>
      <right_joint>front_right_wheel_joint</right_joint>
      <right_joint>back_right_wheel_joint</right_joint>
      <wheel_separation>0.4</wheel_separation>
      <wheel_diameter>0.2</wheel_diameter>
      <max_wheel_torque>20</max_wheel_torque>
      <robot_base_frame>footprint</robot_base_frame>
      <publish_odom>true</publish_odom>
      <publish_odom_tf>true</publish_odom_tf>
      <publish_wheel_tf>true</publish_wheel_tf>
      <odometry_source>world</odometry_source>
    </plugin>
  </gazebo>
  <!-- ******************************************************  Camera ******************************************************************  -->
  <gazebo reference="camera">
    <sensor name="camera_sensor" type="camera">
      <plugin filename="libgazebo_ros_camera.so" name="camera_controller">
        <ros>
          <namespace>bocbot</namespace>
          <argument>--remap camera/image_raw:=camera/image_raw</argument>
          <argument>--remap camera/camera_info:=camera/camera_info</argument>
        </ros>
        <camera_name>camera</camera_name>
        <frame_name>camera</frame_name>
        <hack_baseline>0.07</hack_baseline>
      </plugin>
      <update_rate>30.0</update_rate>
      <always_on>1</always_on>
      <camera name="camera">
        <horizontal_fov>1.3962634</horizontal_fov>
        <image>
          <width>800</width>
          <height>800</height>
          <format>R8G8B8</format>
        </image>
        <clip>
          <near>0.02</near>
          <far>300</far>
        </clip>
        <distortion>
          <k1>0.0</k1>
          <k2>0.0</k2>
          <k3>0.0</k3>
          <p1>0.0</p1>
          <p2>0.0</p2>
          <center>0.5 0.5</center>
        </distortion>
      </camera>
    </sensor>
    <material>Gazebo/Green</material>
  </gazebo>
  <!-- ****************************************************** hokuyo  ******************************************************************  -->
  <gazebo reference="hokuyo">
    <sensor name="head_hokuyo_sensor" type="ray">
      <pose>0 0 0 0 0 0</pose>
      <visualize>false</visualize>
      <update_rate>40</update_rate>
      <ray>
        <scan>
          <horizontal>
            <samples>720</samples>
            <resolution>1</resolution>
            <min_angle>-1.570796</min_angle>
            <max_angle>1.570796</max_angle>
          </horizontal>
        </scan>
        <range>
          <min>0.10</min>
          <max>30.0</max>
          <resolution>0.01</resolution>
        </range>
        <!-- Noise parameters based on published spec for Hokuyo laser achieving "+-30mm" accuracy at range < 10m.  A mean of 0.0m and stddev   -->
        <!-- of 0.01m will put 99.7% of samples within 0.03m of the true reading.                                                               -->
        <noise>
          <type>gaussian</type>
          <mean>0.0</mean>
          <stddev>0.01</stddev>
        </noise>
      </ray>
      <update_rate>30</update_rate>
      <plugin filename="libgazebo_ros_ray_sensor.so" name="gazebo_ros_head_hokuyo_controller">
        <ros>
          <namespace>bocbot</namespace>
          <argument>--remap ~/out:=scan</argument>
        </ros>
        <output_type>sensor_msgs/LaserScan</output_type>
      </plugin>
    </sensor>
    <material>Gazebo/Red</material>
  </gazebo>
  <!-- ****************************************************** end **********************************************************************  -->
  <!-- Gazebo                                     -->
  <!-- ****************************************************** Base Footprint ***********************************************************  -->
  <link name="footprint"/>
  <!-- ****************************************************** Base *********************************************************************  -->
  <link name="base">
    <pose>0 0 0.1 0 0 0</pose>
    <inertial>
      <mass value="15.0"/>
      <origin rpy=" 0 0 0" xyz="0.0 0 0"/>
      <inertia ixx="0.1" ixy="0" ixz="0" iyy="0.1" iyz="0" izz="0.1"/>
    </inertial>
    <collision name="collision">
      <origin rpy=" 0 0 0" xyz="0 0 0"/>
      <geometry>
        <box size=".4 .2 .1"/>
      </geometry>
    </collision>
    <visual name="base_visual">
      <origin rpy=" 0 0 0" xyz="0 0 0"/>
      <geometry>
        <box size=".4 .2 .1"/>
      </geometry>
      <material name="blue"/>
    </visual>
  </link>
  <!-- ****************************************************** Front Left Wheel *********************************************************  -->
  <link name="front_left_wheel">
    <inertial>
      <mass value="5.0"/>
      <origin rpy=" 0 1.5707 1.5707" xyz="0.0 0 0"/>
      <inertia ixx="0.1" ixy="0" ixz="0" iyy="0.1" iyz="0" izz="0.1"/>
    </inertial>
    <visual>
      <origin rpy=" 0 1.5707 1.5707" xyz="0.0 0 0"/>
      <geometry>
        <cylinder length="0.05" radius="0.1"/>
      </geometry>
      <material name="grey"/>
    </visual>
    <collision>
      <origin rpy=" 0 1.5707 1.5707" xyz="0.0 0 0"/>
      <geometry>
        <cylinder length="0.05" radius="0.1"/>
      </geometry>
    </collision>
  </link>
  <!-- ****************************************************** Back Left Wheel **********************************************************  -->
  <link name="back_left_wheel">
    <inertial>
      <mass value="5.0"/>
      <origin rpy=" 0 1.5707 1.5707" xyz="0.0 0 0"/>
      <inertia ixx="0.1" ixy="0" ixz="0" iyy="0.1" iyz="0" izz="0.1"/>
    </inertial>
    <visual>
      <origin rpy=" 0 1.5707 1.5707" xyz="0.0 0 0"/>
      <geometry>
        <cylinder length="0.05" radius="0.1"/>
      </geometry>
      <material name="grey"/>
    </visual>
    <collision>
      <origin rpy=" 0 1.5707 1.5707" xyz="0.0 0 0"/>
      <geometry>
        <cylinder length="0.05" radius="0.1"/>
      </geometry>
    </collision>
  </link>
  <!-- ****************************************************** Front Right Wheel ********************************************************  -->
  <link name="front_right_wheel">
    <inertial>
      <mass value="5.0"/>
      <origin rpy=" 0 1.5707 1.5707" xyz="0.0 0 0"/>
      <inertia ixx="0.1" ixy="0" ixz="0" iyy="0.1" iyz="0" izz="0.1"/>
    </inertial>
    <visual>
      <origin rpy=" 0 1.5707 1.5707" xyz="0.0 0 0"/>
      <geometry>
        <cylinder length="0.05" radius="0.1"/>
      </geometry>
      <material name="grey"/>
    </visual>
    <collision>
      <origin rpy=" 0 1.5707 1.5707" xyz="0.0 0 0"/>
      <geometry>
        <cylinder length="0.05" radius="0.1"/>
      </geometry>
    </collision>
  </link>
  <!-- ****************************************************** Back Right Wheel *********************************************************  -->
  <link name="back_right_wheel">
    <inertial>
      <mass value="5.0"/>
      <origin rpy=" 0 1.5707 1.5707" xyz="0.0 0 0"/>
      <inertia ixx="0.1" ixy="0" ixz="0" iyy="0.1" iyz="0" izz="0.1"/>
    </inertial>
    <visual>
      <origin rpy=" 0 1.5707 1.5707" xyz="0.0 0 0"/>
      <geometry>
        <cylinder length="0.05" radius="0.1"/>
      </geometry>
      <material name="grey"/>
    </visual>
    <collision>
      <origin rpy=" 0 1.5707 1.5707" xyz="0.0 0 0"/>
      <geometry>
        <cylinder length="0.05" radius="0.1"/>
      </geometry>
    </collision>
  </link>
  <!-- ****************************************************** Camera *******************************************************************  -->
  <link name="camera">
    <inertial>
      <mass value="0.1"/>
      <origin rpy=" 0 0 0" xyz="0.05 0.05 0.05"/>
      <inertia ixx="1e-6" ixy="0" ixz="0" iyy="1e-6" iyz="0" izz="1e-6"/>
    </inertial>
    <visual name="camera_visual">
      <origin rpy="0 0 0" xyz="0 0 0"/>
      <geometry>
        <box size="0.05 0.05 0.05"/>
      </geometry>
      <material name="green"/>
    </visual>
    <collision name="camera_colision">
      <origin rpy="0 0 0" xyz="0 0 0"/>
      <geometry>
        <box size="0.05 0.05 0.05"/>
      </geometry>
    </collision>
  </link>
  <!-- ****************************************************** Hokuyo *******************************************************************  -->
  <link name="hokuyo">
    <inertial>
      <mass value="1e-5"/>
      <origin rpy=" 0 0 0" xyz="0 0 0"/>
      <inertia ixx="1e-6" ixy="0" ixz="0" iyy="1e-6" iyz="0" izz="1e-6"/>
    </inertial>
    <visual name="hokuyo_visual">
      <origin rpy="0 0 0" xyz="0 0 0"/>
      <geometry>
        <mesh filename="package://robot_gazebo/meshes/bocbot/hokuyo.dae"/>
        <!-- <box size="0.05 0.05 0.05"/> -->
      </geometry>
      <material name="red"/>
    </visual>
    <collision name="hokuyo_colision">
      <origin rpy="0 0 0" xyz="0 0 0"/>
      <geometry>
        <box size="0.1 0.1 0.1"/>
      </geometry>
    </collision>
  </link>
  <!-- ****************************************************** Footprint Joint **********************************************************  -->
  <joint name="footprint_joint" type="fixed">
    <origin rpy="0 0 0" xyz="0 0 0"/>
    <parent link="footprint"/>
    <child link="base"/>
  </joint>
  <!-- ****************************************************** Front Left Wheel Joint ***************************************************  -->
  <joint name="front_left_wheel_joint" type="continuous">
    <origin rpy="0 0 0" xyz="0.12 0.15 0"/>
    <child link="front_left_wheel"/>
    <parent link="base"/>
    <axis rpy="0 0 0" xyz="0 1 0"/>
    <limit effort="10000" velocity="1000"/>
    <dynamics damping="1.0" friction="1.0"/>
  </joint>
  <!-- ****************************************************** Front Right Wheel Joint **************************************************  -->
  <joint name="front_right_wheel_joint" type="continuous">
    <origin rpy="0 0 0" xyz="0.12 -0.15 0"/>
    <child link="front_right_wheel"/>
    <parent link="base"/>
    <axis rpy="0 0 0" xyz="0 1 0"/>
    <limit effort="10000" velocity="1000"/>
    <dynamics damping="1.0" friction="1.0"/>
  </joint>
  <!-- ****************************************************** Back Left Wheel Joint ****************************************************  -->
  <joint name="back_left_wheel_joint" type="continuous">
    <origin rpy="0 0 0" xyz="-0.12 0.15 0"/>
    <child link="back_left_wheel"/>
    <parent link="base"/>
    <axis rpy="0 0 0" xyz="0 1 0"/>
    <limit effort="10000" velocity="1000"/>
    <dynamics damping="1.0" friction="1.0"/>
  </joint>
  <!-- ****************************************************** Back Right Wheel Joint ***************************************************  -->
  <joint name="back_right_wheel_joint" type="continuous">
    <origin rpy="0 0 0" xyz="-0.12 -0.15 0"/>
    <child link="back_right_wheel"/>
    <parent link="base"/>
    <axis rpy="0 0 0" xyz="0 1 0"/>
    <limit effort="10000" velocity="1000"/>
    <dynamics damping="1.0" friction="1.0"/>
  </joint>
  <!-- ****************************************************** Camera Joint *************************************************************  -->
  <joint name="camera_joint" type="fixed">
    <origin rpy="0 0 0" xyz="0.2 0 0"/>
    <child link="camera"/>
    <parent link="base"/>
    <axis rpy="0 0 0" xyz="0 1 0"/>
  </joint>
  <!-- ****************************************************** Hokuyo Joint *************************************************************  -->
  <joint name="hokuyo_joint" type="fixed">
    <origin rpy="0 0 0" xyz="0.15 0 0.1"/>
    <child link="hokuyo"/>
    <parent link="base"/>
    <axis rpy="0 0 0" xyz="0 1 0"/>
  </joint>
  <!-- ****************************************************** end **********************************************************************  -->
</robot>
