<?xml version="1.0" ?>
<!-- =================================================================================== -->
<!-- |    This document was autogenerated by xacro from src/bots/xacro/cart.xacro      | -->
<!-- |    EDITING THIS FILE BY HAND IS NOT RECOMMENDED                                 | -->
<!-- =================================================================================== -->
<robot name="cart">
  <!-- ****************************************************** World Link *************************************************************** -->
  <link name="world"/>
  <!-- ****************************************************** slideBar Link ************************************************************ -->
  <link name="slideBar">
    <visual>
      <geometry>
        <box size="30 0.05 0.05"/>
      </geometry>
      <origin xyz="0 0 0"/>
      <material name="green">
        <color rgba="0 0.8 .8 1"/>
      </material>
    </visual>
    <inertial>
      <mass value="100"/>
      <inertia ixx="1.0" ixy="0.0" ixz="0.0" iyy="1.0" iyz="0.0" izz="1.0"/>
    </inertial>
  </link>
  <gazebo reference="slideBar">
    <material>Gazebo/Orange</material>
  </gazebo>
  <!-- ****************************************************** cart Link **************************************************************** -->
  <link name="cart">
    <visual>
      <geometry>
        <box size="0.5 0.5 0.2"/>
      </geometry>
      <origin xyz="0 0 0"/>
      <material name="blue">
        <color rgba="0 0 .8 1"/>
      </material>
    </visual>
    <inertial>
      <mass value="1"/>
      <inertia ixx="1.0" ixy="0.0" ixz="0.0" iyy="1.0" iyz="0.0" izz="1.0"/>
    </inertial>
  </link>
  <gazebo reference="cart">
    <material>Gazebo/Red</material>
  </gazebo>
  <!-- ****************************************************** world to slideBar Joint ************************************************** -->
  <joint name="world_to_base" type="fixed">
    <origin rpy="0 0 0" xyz="0 0 1"/>
    <parent link="world"/>
    <child link="slideBar"/>
  </joint>
  <!-- ****************************************************** slideBar to cart Joint *************************************************** -->
  <joint name="slider_to_cart" type="prismatic">
    <axis xyz="1 0 0"/>
    <origin xyz="0.0 0.0 0.0"/>
    <parent link="slideBar"/>
    <child link="cart"/>
    <limit effort="1000.0" lower="-15" upper="15" velocity="30"/>
    <dynamics damping="0.0" friction="0.0"/>
  </joint>
  <!-- ****************************************************** End ********************************************************************** -->
</robot>
