<?xml version="1.0" ?>
<!-- =================================================================================== -->
<!-- |    This document was autogenerated by xacro from src/robot_gazebo/xacro/diffbot.xacro | -->
<!-- |    EDITING THIS FILE BY HAND IS NOT RECOMMENDED                                 | -->
<!-- =================================================================================== -->
<robot name="diffbot">
  <!-- ****************************************************** RRBot Robot **************************************************************  -->
  <!-- Muthanna Alwahash                                                                                                                  -->
  <!-- March 2022                                                                                                                         -->
  <!-- *********************************************************************************************************************************  -->
  <!-- ****************************************************** Parameters ***************************************************************  -->
  <!-- Space btw top of beam and the each joint  -->
  <!-- ****************************************************** Import RVIZ Materials*****************************************************  -->
  <material name="red">
    <color rgba="1.0 0.0 0.0 1.0"/>
  </material>
  <material name="green">
    <color rgba="0.0 1.0 0.0 1.0"/>
  </material>
  <material name="blue">
    <color rgba="0.0 0.0 1.0 1.0"/>
  </material>
  <material name="black">
    <color rgba="0.3 0.3 0.3 1.0"/>
  </material>
  <material name="white">
    <color rgba="1.0 1.0 1.0 1.0"/>
  </material>
  <material name="grey">
    <color rgba="0.2 0.2 0.2 1.0"/>
  </material>
  <material name="orange">
    <color rgba="1.0 0.4235294117647059 0.0392156862745098 1.0"/>
  </material>
  <material name="brown">
    <color rgba="0.8705882352941177 0.8117647058823529 0.7647058823529411 1.0"/>
  </material>
  <material name="yellow">
    <color rgba="1.0 1.0 0.0 1.0"/>
  </material>
  <!-- ****************************************************** Macro ********************************************************************  -->
  <!-- ****************************************************** Expand Macro *************************************************************  -->
  <!-- ****************************************************** Base Link ****************************************************************  -->
  <link name="base_link">
    <collision>
      <origin rpy="0 0 0" xyz="0 0 0"/>
      <geometry>
        <box size="0.1 0.1 0.05"/>
      </geometry>
    </collision>
    <visual>
      <origin rpy="0 0 0" xyz="0 0 0.025"/>
      <geometry>
        <box size="0.1 0.1 0.05"/>
      </geometry>
      <material name="orange"/>
    </visual>
    <inertial>
      <origin rpy="0 0 0" xyz="0 0 0"/>
      <mass value="0.3"/>
      <inertia ixx="0.00031250000000000006" ixy="0.0" ixz="0.0" iyy="0.00031250000000000006" iyz="0.0" izz="0.0005"/>
    </inertial>
  </link>
  <!-- ****************************************************** Left Wheel Joint *********************************************************  -->
  <joint name="left_wheel_joint" type="continuous">
    <parent link="base_link"/>
    <child link="left_wheel"/>
    <origin rpy="0 0 0" xyz="0 -0.05 -0.025"/>
    <axis xyz="0 1 0"/>
    <dynamics damping="0.2"/>
  </joint>
  <!-- ****************************************************** Left Wheel Link **********************************************************  -->
  <link name="left_wheel">
    <collision>
      <origin rpy="1.5707963267948966 0 0" xyz="0 0 0"/>
      <geometry>
        <cylinder length="0.02" radius="0.015"/>
      </geometry>
    </collision>
    <visual>
      <origin rpy="1.5707963267948966 0 0" xyz="0 0 0"/>
      <geometry>
        <cylinder length="0.02" radius="0.015"/>
      </geometry>
      <material name="black"/>
    </visual>
    <inertial>
      <origin rpy="1.5707963267948966 0 0" xyz="0 0 0"/>
      <mass value="0.3"/>
      <inertia ixx="0.0011349999999999997" ixy="0.0" ixz="0.0" iyy="5.6249999999999995e-06" iyz="0.0" izz="5.6249999999999995e-06"/>
    </inertial>
  </link>
  <!-- ****************************************************** Right Wheel Joint ********************************************************  -->
  <joint name="right_wheel_joint" type="continuous">
    <parent link="base_link"/>
    <child link="right_wheel"/>
    <origin rpy="0 0 0" xyz="0 0.05 -0.025"/>
    <axis xyz="0 1 0"/>
    <dynamics damping="0.2"/>
  </joint>
  <!-- ****************************************************** Right Wheel Link ********************************************************  -->
  <link name="right_wheel">
    <collision>
      <origin rpy="1.5707963267948966 0 0" xyz="0 0 0"/>
      <geometry>
        <cylinder length="0.02" radius="0.015"/>
      </geometry>
    </collision>
    <visual>
      <origin rpy="1.5707963267948966 0 0" xyz="0 0 0"/>
      <geometry>
        <cylinder length="0.02" radius="0.015"/>
      </geometry>
      <material name="black"/>
    </visual>
    <inertial>
      <origin rpy="1.5707963267948966 0 0" xyz="0 0 0"/>
      <mass value="0.3"/>
      <inertia ixx="0.0011349999999999997" ixy="0.0" ixz="0.0" iyy="5.6249999999999995e-06" iyz="0.0" izz="5.6249999999999995e-06"/>
    </inertial>
  </link>
  <!-- ****************************************************** Right Wheel Link ********************************************************  -->
  <joint name="caster_frontal_wheel_joint" type="fixed">
    <parent link="base_link"/>
    <child link="caster_frontal_wheel"/>
    <origin rpy="0 0 0" xyz="0.035 0 -0.025"/>
  </joint>
  <!-- ****************************************************** Right Wheel Link ********************************************************  -->
  <link name="caster_frontal_wheel">
    <collision>
      <origin rpy="0 0 0" xyz="0 0 0"/>
      <geometry>
        <sphere radius="0.015"/>
      </geometry>
    </collision>
    <visual>
      <origin rpy="0 0 0" xyz="0 0 0"/>
      <geometry>
        <sphere radius="0.015"/>
      </geometry>
      <material name="white"/>
    </visual>
    <inertial>
      <origin rpy="0 0 0" xyz="0 0 0"/>
      <mass value="0.1"/>
      <inertia ixx="9.000000000000002e-06" ixy="0.0" ixz="0.0" iyy="9.000000000000002e-06" iyz="0.0" izz="9.000000000000002e-06"/>
    </inertial>
  </link>
  <!-- ****************************************************** Right Wheel Link ********************************************************  -->
  <joint name="caster_rear_wheel_joint" type="fixed">
    <parent link="base_link"/>
    <child link="caster_rear_wheel"/>
    <origin rpy="0 0 0" xyz="-0.035 0 -0.025"/>
  </joint>
  <!-- ****************************************************** Right Wheel Link ********************************************************  -->
  <link name="caster_rear_wheel">
    <collision>
      <origin rpy="0 0 0" xyz="0 0 0"/>
      <geometry>
        <sphere radius="0.015"/>
      </geometry>
    </collision>
    <visual>
      <origin rpy="0 0 0" xyz="0 0 0"/>
      <geometry>
        <sphere radius="0.015"/>
      </geometry>
      <material name="white"/>
    </visual>
    <inertial>
      <origin rpy="0 0 0" xyz="0 0 0"/>
      <mass value="0.1"/>
      <inertia ixx="9.000000000000002e-06" ixy="0.0" ixz="0.0" iyy="9.000000000000002e-06" iyz="0.0" izz="9.000000000000002e-06"/>
    </inertial>
  </link>
  <!-- ****************************************************** End Macro ****************************************************************  -->
  <!-- ****************************************************** END **********************************************************************  -->
</robot>
