<?xml version="1.0" ?>
<!-- =================================================================================== -->
<!-- |    This document was autogenerated by xacro from src/robot_gazebo/xacro/diffbot.xacro | -->
<!-- |    EDITING THIS FILE BY HAND IS NOT RECOMMENDED                                 | -->
<!-- =================================================================================== -->
<robot name="diffbot">
  <!-- ****************************************************** diffbot Robot ************************************************************  -->
  <!-- Muthanna Alwahash                                                                                                                  -->
  <!-- March 2022                                                                                                                         -->
  <!-- *********************************************************************************************************************************  -->
  <!-- ****************************************************** Parameters ***************************************************************  -->
  <!-- Space btw top of beam and the each joint     -->
  <!-- ****************************************************** Includes *****************************************************************  -->
  <material name="red">
    <color rgba="1.0 0.0 0.0 1.0"/>
  </material>
  <material name="green">
    <color rgba="0.0 1.0 0.0 1.0"/>
  </material>
  <material name="blue">
    <color rgba="0.0 0.0 1.0 1.0"/>
  </material>
  <material name="black">
    <color rgba="0.3 0.3 0.3 1.0"/>
  </material>
  <material name="white">
    <color rgba="1.0 1.0 1.0 1.0"/>
  </material>
  <material name="grey">
    <color rgba="0.2 0.2 0.2 1.0"/>
  </material>
  <material name="orange">
    <color rgba="1.0 0.4235294117647059 0.0392156862745098 1.0"/>
  </material>
  <material name="brown">
    <color rgba="0.8705882352941177 0.8117647058823529 0.7647058823529411 1.0"/>
  </material>
  <material name="yellow">
    <color rgba="1.0 1.0 0.0 1.0"/>
  </material>
  <!-- ****************************************************** diffbot Robot ************************************************************  -->
  <!-- Muthanna Alwahash                                                                                                                  -->
  <!-- March 2022                                                                                                                         -->
  <!-- *********************************************************************************************************************************  -->
  <!-- ****************************************************** Base Link ****************************************************************  -->
  <gazebo reference="base_link">
    <material>Gazebo/Blue</material>
  </gazebo>
  <!-- ****************************************************** Front caster Link ********************************************************  -->
  <gazebo reference="front_caster">
    <material>Gazebo/White</material>
  </gazebo>
  <!-- ****************************************************** Rear Caster Link *********************************************************  -->
  <gazebo reference="rear_caster">
    <material>Gazebo/White</material>
  </gazebo>
  <!-- ****************************************************** END **********************************************************************  -->
  <!-- Gazebo                                     -->
  <!-- ****************************************************** Base Footprint ***********************************************************  -->
  <link name="base_footprint"/>
  <!-- ****************************************************** Base Joint ***************************************************************  -->
  <joint name="base_joint" type="fixed">
    <parent link="base_footprint"/>
    <child link="base_link"/>
    <origin rpy="0.0 0.0 0.0" xyz="0.0 0.0 0.10500000000000001"/>
  </joint>
  <!-- ****************************************************** Base Link ****************************************************************  -->
  <link name="base_link">
    <collision>
      <origin rpy="0 0 0" xyz="0 0 0"/>
      <geometry>
        <mesh filename="package://robot_gazebo/meshes/diffbot/base.stl" scale="1 1 1"/>
        <!--  <box size="${base_length} ${base_width} ${base_height}"/> -->
      </geometry>
    </collision>
    <visual>
      <origin rpy="0 0 0" xyz="0 0 0"/>
      <geometry>
        <mesh filename="package://robot_gazebo/meshes/diffbot/base.stl" scale="1 1 1"/>
        <!--  <box size="${base_length} ${base_width} ${base_height}"/> -->
      </geometry>
      <material name="blue"/>
    </visual>
    <inertial>
      <origin rpy="0 0 0" xyz="0 0 0"/>
      <mass value="0.6"/>
      <inertia ixx="0.0085" ixy="0.0" ixz="0.0" iyy="0.0025000000000000005" iyz="0.0" izz="0.010000000000000002"/>
    </inertial>
  </link>
  <!-- ****************************************************** Right Wheel Joint ********************************************************  -->
  <joint name="right_wheel_joint" type="continuous">
    <parent link="base_link"/>
    <child link="right_wheel"/>
    <origin rpy="0 0 0" xyz="0 0.135 -0.025"/>
    <limit effort="30" lower="-3.141592653589793" upper="3.141592653589793" velocity="5.0"/>
    <axis xyz="0 1 0"/>
    <dynamics damping="0.2"/>
  </joint>
  <!-- ****************************************************** Right Wheel Link ********************************************************  -->
  <link name="right_wheel">
    <collision>
      <origin rpy="1.5707963267948966 0 0" xyz="0 0 0"/>
      <geometry>
        <mesh filename="package://robot_gazebo/meshes/diffbot/wheel.dae" scale="1 1 1"/>
        <!-- <cylinder length="${wheel_width}" radius="${wheel_radius}"/> -->
      </geometry>
    </collision>
    <visual>
      <origin rpy="1.5707963267948966 0 0" xyz="0 0 0"/>
      <geometry>
        <mesh filename="package://robot_gazebo/meshes/diffbot/wheel.dae" scale="1 1 1"/>
        <!-- <cylinder length="${wheel_width}" radius="${wheel_radius}"/> -->
      </geometry>
      <material name="black"/>
    </visual>
    <inertial>
      <origin rpy="1.5707963267948966 0 0" xyz="0 0 0"/>
      <mass value="5.0"/>
      <inertia ixx="0.10104166666666667" ixy="0.0" ixz="0.0" iyy="0.0026666666666666666" iyz="0.0" izz="0.0026666666666666666"/>
    </inertial>
  </link>
  <!-- ****************************************************** Left Wheel Joint *********************************************************  -->
  <joint name="left_wheel_joint" type="continuous">
    <parent link="base_link"/>
    <child link="left_wheel"/>
    <origin rpy="0 0 0" xyz="0 -0.135 -0.025"/>
    <limit effort="30" lower="-3.141592653589793" upper="3.141592653589793" velocity="5.0"/>
    <axis xyz="0 1 0"/>
    <dynamics damping="0.2"/>
  </joint>
  <!-- ****************************************************** Left Wheel Link **********************************************************  -->
  <link name="left_wheel">
    <collision>
      <origin rpy="1.5707963267948966 0 0" xyz="0 0 0"/>
      <geometry>
        <mesh filename="package://robot_gazebo/meshes/diffbot/wheel.dae" scale="1 1 1"/>
        <!-- <cylinder length="${wheel_width}" radius="${wheel_radius}"/> -->
      </geometry>
    </collision>
    <visual>
      <origin rpy="1.5707963267948966 0 0" xyz="0 0 0"/>
      <geometry>
        <mesh filename="package://robot_gazebo/meshes/diffbot/wheel.dae" scale="1 1 1"/>
        <!-- <cylinder length="${wheel_width}" radius="${wheel_radius}"/> -->
      </geometry>
      <material name="black"/>
    </visual>
    <inertial>
      <origin rpy="1.5707963267948966 0 0" xyz="0 0 0"/>
      <mass value="5.0"/>
      <inertia ixx="0.10104166666666667" ixy="0.0" ixz="0.0" iyy="0.0026666666666666666" iyz="0.0" izz="0.0026666666666666666"/>
    </inertial>
  </link>
  <!-- ****************************************************** Front caster joint *******************************************************  -->
  <joint name="front_caster_joint" type="fixed">
    <parent link="base_link"/>
    <child link="front_caster"/>
    <origin rpy="0 0 0" xyz="0.13775 0 -0.05"/>
  </joint>
  <!-- ****************************************************** Front caster Link ********************************************************  -->
  <link name="front_caster">
    <collision>
      <origin rpy="0 0 0" xyz="0 0 0"/>
      <geometry>
        <sphere radius="0.055"/>
      </geometry>
    </collision>
    <visual>
      <origin rpy="0 0 0" xyz="0 0 0"/>
      <geometry>
        <sphere radius="0.055"/>
      </geometry>
      <material name="white"/>
    </visual>
    <inertial>
      <origin rpy="0 0 0" xyz="0 0 0"/>
      <mass value="0.1"/>
      <inertia ixx="0.00012100000000000001" ixy="0.0" ixz="0.0" iyy="0.00012100000000000001" iyz="0.0" izz="0.00012100000000000001"/>
    </inertial>
  </link>
  <!-- ****************************************************** Rear Caster Joint ********************************************************  -->
  <joint name="rear_caster_joint" type="fixed">
    <parent link="base_link"/>
    <child link="rear_caster"/>
    <origin rpy="0 0 0" xyz="-0.13775 0 -0.05"/>
  </joint>
  <!-- ****************************************************** Rear Caster Link *********************************************************  -->
  <link name="rear_caster">
    <collision>
      <origin rpy="0 0 0" xyz="0 0 0"/>
      <geometry>
        <sphere radius="0.055"/>
      </geometry>
    </collision>
    <visual>
      <origin rpy="0 0 0" xyz="0 0 0"/>
      <geometry>
        <sphere radius="0.055"/>
      </geometry>
      <material name="white"/>
    </visual>
    <inertial>
      <origin rpy="0 0 0" xyz="0 0 0"/>
      <mass value="0.1"/>
      <inertia ixx="0.00012100000000000001" ixy="0.0" ixz="0.0" iyy="0.00012100000000000001" iyz="0.0" izz="0.00012100000000000001"/>
    </inertial>
  </link>
  <!-- ****************************************************** Hokuyo Link **************************************************************  -->
  <link name="hokuyo">
    <inertial>
      <mass value="1e-05"/>
      <origin rpy=" 0 0 0" xyz="0 0 0"/>
      <inertia ixx="1e-6" ixy="0" ixz="0" iyy="1e-6" iyz="0" izz="1e-6"/>
    </inertial>
    <visual name="hokuyo_visual">
      <origin rpy="0 0 0" xyz="0 0 0"/>
      <geometry>
        <mesh filename="package://robot_gazebo/meshes/diffbot/hokuyo.dae"/>
        <!--  <box size="${hokuyo_length} ${hokuyo_width} ${hokuyo_height}"/> -->
      </geometry>
      <!-- <material name="red"/> -->
    </visual>
    <collision name="hokuyo_colision">
      <origin rpy="0 0 0" xyz="0 0 0"/>
      <geometry>
        <mesh filename="package://robot_gazebo/meshes/diffbot/hokuyo.dae"/>
        <!--  <box size="${hokuyo_length} ${hokuyo_width} ${hokuyo_height}"/> -->
      </geometry>
    </collision>
  </link>
  <!-- ****************************************************** Hokuyo Joint *************************************************************  -->
  <joint name="hokuyo_joint" type="fixed">
    <origin rpy="0 0 0" xyz="0.11 0 0.0853"/>
    <child link="hokuyo"/>
    <parent link="base_link"/>
    <axis rpy="0 0 0" xyz="0 1 0"/>
  </joint>
  <!-- ****************************************************** END **********************************************************************  -->
</robot>
