<?xml version="1.0" ?>
<!-- =================================================================================== -->
<!-- |    This document was autogenerated by xacro from src/robot_gazebo/xacro/diffbot.xacro | -->
<!-- |    EDITING THIS FILE BY HAND IS NOT RECOMMENDED                                 | -->
<!-- =================================================================================== -->
<robot name="diffbot">
  <!-- ****************************************************** diffbot Robot ************************************************************  -->
  <!-- Muthanna Alwahash                                                                                                                  -->
  <!-- March 2022                                                                                                                         -->
  <!-- *********************************************************************************************************************************  -->
  <!-- ****************************************************** Parameters ***************************************************************  -->
  <!-- Space btw top of beam and the each joint     -->
  <!-- x offset from base center -->
  <!-- ****************************************************** Includes *****************************************************************  -->
  <material name="red">
    <color rgba="1.0 0.0 0.0 1.0"/>
  </material>
  <material name="green">
    <color rgba="0.0 1.0 0.0 1.0"/>
  </material>
  <material name="blue">
    <color rgba="0.0 0.0 1.0 1.0"/>
  </material>
  <material name="black">
    <color rgba="0.3 0.3 0.3 1.0"/>
  </material>
  <material name="white">
    <color rgba="1.0 1.0 1.0 1.0"/>
  </material>
  <material name="grey">
    <color rgba="0.2 0.2 0.2 1.0"/>
  </material>
  <material name="orange">
    <color rgba="1.0 0.4235294117647059 0.0392156862745098 1.0"/>
  </material>
  <material name="brown">
    <color rgba="0.8705882352941177 0.8117647058823529 0.7647058823529411 1.0"/>
  </material>
  <material name="yellow">
    <color rgba="1.0 1.0 0.0 1.0"/>
  </material>
  <!-- ****************************************************** diffbot Robot ************************************************************  -->
  <!-- Muthanna Alwahash                                                                                                                  -->
  <!-- March 2022                                                                                                                         -->
  <!-- *********************************************************************************************************************************  -->
  <!-- ****************************************************** Base Link ****************************************************************  -->
  <gazebo reference="base">
    <material>Gazebo/Blue</material>
  </gazebo>
  <!-- ****************************************************** Front caster Link ********************************************************  -->
  <gazebo reference="front_caster">
    <material>Gazebo/White</material>
  </gazebo>
  <!-- ******************************************************  Joint States Publisher **************************************************  -->
  <gazebo>
    <plugin filename="libgazebo_ros_joint_state_publisher.so" name="joint_states_pub">
      <ros>
        <namespace>diffbot</namespace>
      </ros>
      <joint_name>right_wheel_joint</joint_name>
      <joint_name>left_wheel_joint</joint_name>
      <update_rate>100.0</update_rate>
    </plugin>
  </gazebo>
  <!-- ******************************************************  Skid Steer Drive Controller *********************************************  -->
  <gazebo>
    <plugin filename="libgazebo_ros_diff_drive.so" name="skid_drive">
      <ros>
        <namespace>diffbot</namespace>
      </ros>
      <num_wheel_pairs>1</num_wheel_pairs>
      <!-- 1st Wheels Set -->
      <right_joint>right_wheel_joint</right_joint>
      <left_joint>left_wheel_joint</left_joint>
      <wheel_separation>0.27</wheel_separation>
      <wheel_diameter>0.16</wheel_diameter>
      <max_wheel_torque>20</max_wheel_torque>
      <max_wheel_acceleration>1.0</max_wheel_acceleration>
      <update_rate>100.0</update_rate>
      <robot_base_frame>footprint</robot_base_frame>
      <odometry_frame>odom</odometry_frame>
      <publish_odom>true</publish_odom>
      <publish_odom_tf>true</publish_odom_tf>
      <publish_wheel_tf>true</publish_wheel_tf>
    </plugin>
  </gazebo>
  <!-- ******************************************************  Camera ******************************************************************  -->
  <gazebo reference="camera">
    <sensor name="camera" type="camera">
      <update_rate>30.0</update_rate>
      <camera name="head">
        <horizontal_fov>1.3962634015954636</horizontal_fov>
        <image>
          <width>1280</width>
          <height>720</height>
          <format>R8G8B8</format>
        </image>
        <clip>
          <near>0.02</near>
          <far>300</far>
        </clip>
        <noise>
          <type>gaussian</type>
          <!-- Noise is sampled independently per pixel on each frame.
          That pixel's noise value is added to each of its color
          channels, which at that point lie in the range [0,1]. -->
          <mean>0.0</mean>
          <stddev>0.007</stddev>
        </noise>
      </camera>
      <plugin filename="libgazebo_ros_camera.so" name="camera_controller">
        <ros>
          <namespace>diffbot</namespace>
        </ros>
        <alwaysOn>true</alwaysOn>
        <updateRate>0.0</updateRate>
        <cameraName>camera</cameraName>
        <imageTopicName>image_raw</imageTopicName>
        <cameraInfoTopicName>camera_info</cameraInfoTopicName>
        <frameName>camera_optical</frameName>
        <!-- setting hackBaseline to anything but 0.0 will cause a misalignment
        between the gazebo sensor image and the frame it is supposed to
        be attached to -->
        <hackBaseline>0.0</hackBaseline>
        <distortionK1>0.0</distortionK1>
        <distortionK2>0.0</distortionK2>
        <distortionK3>0.0</distortionK3>
        <distortionT1>0.0</distortionT1>
        <distortionT2>0.0</distortionT2>
        <CxPrime>0</CxPrime>
        <Cx>0.0</Cx>
        <Cy>0.0</Cy>
        <focalLength>0.0</focalLength>
      </plugin>
    </sensor>
    <material>Gazebo/Green</material>
  </gazebo>
  <!-- ****************************************************** hokuyo  ******************************************************************  -->
  <gazebo reference="hokuyo">
    <sensor name="head_hokuyo_sensor" type="ray">
      <plugin filename="libgazebo_ros_ray_sensor.so" name="hokuyo">
        <ros>
          <namespace>diffbot</namespace>
        </ros>
        <output_type>sensor_msgs/LaserScan</output_type>
      </plugin>
      <update_rate>30</update_rate>
      <pose>0 0 0 0 0 0</pose>
      <visualize>false</visualize>
      <ray>
        <scan>
          <horizontal>
            <samples>720</samples>
            <resolution>1</resolution>
            <min_angle>-3.141592653589793</min_angle>
            <max_angle> 3.141592653589793</max_angle>
          </horizontal>
        </scan>
        <range>
          <min>0.10</min>
          <max>30.0</max>
          <resolution>0.01</resolution>
        </range>
        <!-- Noise parameters based on published spec for Hokuyo laser achieving "+-30mm" accuracy at range < 10m.  A mean of 0.0m and stddev   -->
        <!-- of 0.01m will put 99.7% of samples within 0.03m of the true reading.                                                               -->
        <noise>
          <type>gaussian</type>
          <mean>0.0</mean>
          <stddev>0.01</stddev>
        </noise>
      </ray>
    </sensor>
    <!-- <material>Gazebo/Red</material> -->
  </gazebo>
  <!-- ****************************************************** END **********************************************************************  -->
  <!-- Gazebo                                     -->
  <!-- ****************************************************** Footprint ****************************************************************  -->
  <link name="footprint"/>
  <!-- ****************************************************** Base Joint ***************************************************************  -->
  <joint name="footprint_joint" type="fixed">
    <parent link="footprint"/>
    <child link="base"/>
    <origin rpy="0.0 0.0 0.0" xyz="0.0 0.0 0.10500000000000001"/>
  </joint>
  <!-- ****************************************************** Base Link ****************************************************************  -->
  <link name="base">
    <collision>
      <origin rpy="0 0 0" xyz="0 0 0"/>
      <geometry>
        <mesh filename="package://robot_gazebo/meshes/diffbot/base.stl" scale="1 1 1"/>
        <!--  <box size="${base_length} ${base_width} ${base_height}"/> -->
      </geometry>
    </collision>
    <visual>
      <origin rpy="0 0 0" xyz="0 0 0"/>
      <geometry>
        <mesh filename="package://robot_gazebo/meshes/diffbot/base.stl" scale="1 1 1"/>
        <!--  <box size="${base_length} ${base_width} ${base_height}"/> -->
      </geometry>
      <material name="blue"/>
    </visual>
    <inertial>
      <origin rpy="0 0 0" xyz="0 0 0"/>
      <mass value="0.6"/>
      <inertia ixx="0.0085" ixy="0.0" ixz="0.0" iyy="0.0025000000000000005" iyz="0.0" izz="0.010000000000000002"/>
    </inertial>
  </link>
  <!-- ****************************************************** Right Wheel Joint ********************************************************  -->
  <joint name="right_wheel_joint" type="continuous">
    <parent link="base"/>
    <child link="right_wheel"/>
    <origin rpy="0 0 0" xyz="-0.12 0.135 -0.025"/>
    <limit effort="30" lower="-3.141592653589793" upper="3.141592653589793" velocity="5.0"/>
    <axis xyz="0 1 0"/>
    <dynamics damping="0.2"/>
  </joint>
  <!-- ****************************************************** Right Wheel Link ********************************************************  -->
  <link name="right_wheel">
    <collision>
      <origin rpy="1.5707963267948966 0 0" xyz="0 0 0"/>
      <geometry>
        <mesh filename="package://robot_gazebo/meshes/diffbot/wheel.dae" scale="1 1 1"/>
        <!-- <cylinder length="${wheel_width}" radius="${wheel_radius}"/> -->
      </geometry>
    </collision>
    <visual>
      <origin rpy="1.5707963267948966 0 0" xyz="0 0 0"/>
      <geometry>
        <mesh filename="package://robot_gazebo/meshes/diffbot/wheel.dae" scale="1 1 1"/>
        <!-- <cylinder length="${wheel_width}" radius="${wheel_radius}"/> -->
      </geometry>
      <material name="black"/>
    </visual>
    <inertial>
      <origin rpy="1.5707963267948966 0 0" xyz="0 0 0"/>
      <mass value="5.0"/>
      <inertia ixx="0.10104166666666667" ixy="0.0" ixz="0.0" iyy="0.0026666666666666666" iyz="0.0" izz="0.0026666666666666666"/>
    </inertial>
  </link>
  <!-- ****************************************************** Left Wheel Joint *********************************************************  -->
  <joint name="left_wheel_joint" type="continuous">
    <parent link="base"/>
    <child link="left_wheel"/>
    <origin rpy="0 0 0" xyz="-0.12 -0.135 -0.025"/>
    <limit effort="30" lower="-3.141592653589793" upper="3.141592653589793" velocity="5.0"/>
    <axis xyz="0 1 0"/>
    <dynamics damping="0.2"/>
  </joint>
  <!-- ****************************************************** Left Wheel Link **********************************************************  -->
  <link name="left_wheel">
    <collision>
      <origin rpy="1.5707963267948966 0 0" xyz="0 0 0"/>
      <geometry>
        <mesh filename="package://robot_gazebo/meshes/diffbot/wheel.dae" scale="1 1 1"/>
        <!-- <cylinder length="${wheel_width}" radius="${wheel_radius}"/> -->
      </geometry>
    </collision>
    <visual>
      <origin rpy="1.5707963267948966 0 0" xyz="0 0 0"/>
      <geometry>
        <mesh filename="package://robot_gazebo/meshes/diffbot/wheel.dae" scale="1 1 1"/>
        <!-- <cylinder length="${wheel_width}" radius="${wheel_radius}"/> -->
      </geometry>
      <material name="black"/>
    </visual>
    <inertial>
      <origin rpy="1.5707963267948966 0 0" xyz="0 0 0"/>
      <mass value="5.0"/>
      <inertia ixx="0.10104166666666667" ixy="0.0" ixz="0.0" iyy="0.0026666666666666666" iyz="0.0" izz="0.0026666666666666666"/>
    </inertial>
  </link>
  <!-- ****************************************************** Front caster joint *******************************************************  -->
  <joint name="front_caster_joint" type="fixed">
    <parent link="base"/>
    <child link="front_caster"/>
    <origin rpy="0 0 0" xyz="0.14500000000000002 0 -0.05"/>
  </joint>
  <!-- ****************************************************** Front caster Link ********************************************************  -->
  <link name="front_caster">
    <collision>
      <origin rpy="0 0 0" xyz="0 0 0"/>
      <geometry>
        <sphere radius="0.055"/>
      </geometry>
    </collision>
    <visual>
      <origin rpy="0 0 0" xyz="0 0 0"/>
      <geometry>
        <sphere radius="0.055"/>
      </geometry>
      <material name="white"/>
    </visual>
    <inertial>
      <origin rpy="0 0 0" xyz="0 0 0"/>
      <mass value="0.1"/>
      <inertia ixx="0.00012100000000000001" ixy="0.0" ixz="0.0" iyy="0.00012100000000000001" iyz="0.0" izz="0.00012100000000000001"/>
    </inertial>
  </link>
  <!-- ****************************************************** Camera Link **************************************************************  -->
  <link name="camera">
    <inertial>
      <mass value="0.1"/>
      <origin rpy=" 0 0 0" xyz="0 0 0"/>
      <inertia ixx="1e-6" ixy="0" ixz="0" iyy="1e-6" iyz="0" izz="1e-6"/>
    </inertial>
    <visual name="camera_visual">
      <origin rpy="0 0 0" xyz="0 0 0"/>
      <geometry>
        <box size="0.05 0.05 0.05"/>
      </geometry>
      <material name="green"/>
    </visual>
    <collision name="camera_colision">
      <origin rpy="0 0 0" xyz="0 0 0"/>
      <geometry>
        <box size="0.05 0.05 0.05"/>
      </geometry>
    </collision>
  </link>
  <!-- ****************************************************** Camera Joint *************************************************************  -->
  <joint name="camera_joint" type="fixed">
    <origin rpy="0 0 0" xyz="0.2 0 0"/>
    <child link="camera"/>
    <parent link="base"/>
    <axis rpy="0 0 0" xyz="0 1 0"/>
  </joint>
  <!-- ****************************************************** Hokuyo Link **************************************************************  -->
  <link name="hokuyo">
    <inertial>
      <mass value="1e-05"/>
      <origin rpy=" 0 0 0" xyz="0 0 0"/>
      <inertia ixx="1e-6" ixy="0" ixz="0" iyy="1e-6" iyz="0" izz="1e-6"/>
    </inertial>
    <visual name="hokuyo_visual">
      <origin rpy="0 0 0" xyz="0 0 0"/>
      <geometry>
        <mesh filename="package://robot_gazebo/meshes/diffbot/hokuyo.dae"/>
        <!--  <box size="${hokuyo_length} ${hokuyo_width} ${hokuyo_height}"/> -->
      </geometry>
      <!-- <material name="red"/> -->
    </visual>
    <collision name="hokuyo_colision">
      <origin rpy="0 0 0" xyz="0 0 0"/>
      <geometry>
        <mesh filename="package://robot_gazebo/meshes/diffbot/hokuyo.dae"/>
        <!--  <box size="${hokuyo_length} ${hokuyo_width} ${hokuyo_height}"/> -->
      </geometry>
    </collision>
  </link>
  <!-- ****************************************************** Hokuyo Joint *************************************************************  -->
  <joint name="hokuyo_joint" type="fixed">
    <origin rpy="0 0 0" xyz="0.11 0 0.0853"/>
    <child link="hokuyo"/>
    <parent link="base"/>
    <axis rpy="0 0 0" xyz="0 1 0"/>
  </joint>
  <!-- ****************************************************** END **********************************************************************  -->
</robot>
