<?xml version="1.0" ?>
<!-- =================================================================================== -->
<!-- |    This document was autogenerated by xacro from ../xacro/golem.xacro           | -->
<!-- |    EDITING THIS FILE BY HAND IS NOT RECOMMENDED                                 | -->
<!-- =================================================================================== -->
<robot name="Golem">
  <!-- ****************************************************** Golem Robot **************************************************************  -->
  <!-- Muthanna Alwahash                                                                                                                  -->
  <!-- March 2022                                                                                                                         -->
  <!-- *********************************************************************************************************************************  -->
  <!-- ****************************************************** Parameters ***************************************************************  -->
  <!-- ****************************************************** Colors *******************************************************************  -->
  <material name="red">
    <color rgba="1.0 0.0 0.0 1.0"/>
  </material>
  <material name="green">
    <color rgba="0.0 1.0 0.0 1.0"/>
  </material>
  <material name="blue">
    <color rgba="0.0 0.0 1.0 1.0"/>
  </material>
  <material name="black">
    <color rgba="0.3 0.3 0.3 1.0"/>
  </material>
  <material name="white">
    <color rgba="1.0 1.0 1.0 1.0"/>
  </material>
  <!-- ****************************************************** Base Link ****************************************************************  -->
  <link name="base_link"/>
  <!-- ****************************************************** Base Joint ***************************************************************  -->
  <joint name="base_joint" type="fixed">
    <parent link="base_link"/>
    <child link="body_link"/>
    <origin rpy="0.0 0.0 0.0" xyz="0.0 0.0 0.064"/>
  </joint>
  <!-- ****************************************************** Body Link ****************************************************************  -->
  <link name="body_link">
    <visual>
      <origin rpy="0.0 0.0 0.0" xyz="0.0 0.0 0.0"/>
      <geometry>
        <mesh filename="package://robot_gazebo/meshes/golem/body.stl" scale="0.001 0.001 0.001"/>
      </geometry>
      <material name="blue"/>
      <gazebo reference="body_link">
        <material>Gazebo/Blue</material>
      </gazebo>
    </visual>
    <collision>
      <origin rpy="0.0 0.0 0.0" xyz="0.0 0.0 0.0"/>
      <geometry>
        <mesh filename="package://robot_gazebo/meshes/golem/body.stl" scale="0.001 0.001 0.001"/>
      </geometry>
      <material name="blue"/>
    </collision>
    <inertial>
      <origin rpy="0.0 0.0 0.0" xyz="0.0 0.0 0.0"/>
      <mass value="0.00001"/>
      <inertia ixx="1.0" ixy="0.0" ixz="0.0" iyy="1.0" iyz="0.0" izz="1.0"/>
    </inertial>
  </link>
  <!-- ****************************************************** Camera RGB Joint *********************************************************  -->
  <joint name="camera_rgb_joint" type="fixed">
    <parent link="body_link"/>
    <child link="camera_rgb_optical_frame"/>
    <origin rpy="1.5707963267948966 3.141592653589793 1.5707963267948966" xyz="0.150 0.0255 0.034"/>
  </joint>
  <!-- ****************************************************** Camera RGB Optical Frame Link ********************************************  -->
  <link name="camera_rgb_optical_frame">
    <inertial>
      <origin rpy="0.0 0.0 0.0" xyz="0.0 0.0 0.0"/>
      <mass value="0.00001"/>
      <inertia ixx="1.0" ixy="0.0" ixz="0.0" iyy="1.0" iyz="0.0" izz="1.0"/>
    </inertial>
  </link>
  <!-- ****************************************************** Camera Depth Joint *******************************************************  -->
  <joint name="camera_depth_joint" type="fixed">
    <parent link="body_link"/>
    <child link="camera_depth_optical_frame"/>
    <origin rpy="1.5707963267948966 3.141592653589793 1.5707963267948966" xyz="0.150 -0.0225 0.034"/>
  </joint>
  <!-- ****************************************************** Camera Depth Optical Frame Link ****************************************** -->
  <link name="camera_depth_optical_frame">
    <inertial>
      <origin rpy="0.0 0.0 0.0" xyz="0.0 0.0 0.0"/>
      <mass value="0.00001"/>
      <inertia ixx="1.0" ixy="0.0" ixz="0.0" iyy="1.0" iyz="0.0" izz="1.0"/>
    </inertial>
  </link>
  <!-- ****************************************************** IMU Joint ****************************************************************  -->
  <joint name="imu_joint" type="fixed">
    <parent link="body_link"/>
    <child link="imu_link"/>
    <origin rpy="0.0 0.0 0.0" xyz="0.0 0.0 0.034"/>
  </joint>
  <!-- ****************************************************** IMU Link *****************************************************************  -->
  <link name="imu_link">
    <inertial>
      <origin rpy="0.0 0.0 0.0" xyz="0.0 0.0 0.0"/>
      <mass value="0.00001"/>
      <inertia ixx="1.0" ixy="0.0" ixz="0.0" iyy="1.0" iyz="0.0" izz="1.0"/>
    </inertial>
  </link>
  <!-- ****************************************************** Pan Joint ****************************************************************  -->
  <joint name="pan_joint" type="revolute">
    <parent link="body_link"/>
    <child link="pan_link"/>
    <origin rpy="0.0 0.0 0.0" xyz="0.1 0.0 0.034"/>
    <axis xyz="0.0 0.0 1.0"/>
    <limit effort="6.0" lower="-3.14" upper="3.14" velocity="0.524"/>
  </joint>
  <!-- ****************************************************** Pan Link *****************************************************************  -->
  <link name="pan_link">
    <inertial>
      <origin rpy="0.0 0.0 0.0" xyz="0.0 0.0 0.0"/>
      <mass value="0.00001"/>
      <inertia ixx="1.0" ixy="0.0" ixz="0.0" iyy="1.0" iyz="0.0" izz="1.0"/>
    </inertial>
  </link>
  <!-- ****************************************************** Leg Macro ****************************************************************  -->
  <!-- ****************************************************** Build Robot Model ********************************************************  -->
  <!-- ****************************************************** Leg Center Joint *********************************************************  -->
  <joint name="leg_center_joint_RR" type="fixed">
    <origin rpy="0.0 0.0 0.0" xyz="-0.1778 -0.0825 0.0"/>
    <parent link="body_link"/>
    <child link="leg_center_RR"/>
  </joint>
  <!-- ****************************************************** Leg Center Link **********************************************************  -->
  <link name="leg_center_RR">
    <inertial>
      <origin rpy="0.0 0.0 0.0" xyz="0.0 0.0 0.0"/>
      <mass value="0.00001"/>
      <inertia ixx="1.0" ixy="0.0" ixz="0.0" iyy="1.0" iyz="0.0" izz="1.0"/>
    </inertial>
  </link>
  <!-- ****************************************************** Coxa Joint ***************************************************************  -->
  <joint name="coxa_joint_RR" type="revolute">
    <origin rpy="0.0 0.0 -2.356194490192345" xyz="0.0 0.0 0.0"/>
    <parent link="leg_center_RR"/>
    <child link="coxa_RR"/>
    <axis xyz="0.0 0.0 1.0"/>
    <limit effort="6.0" lower="-3.14" upper="3.14" velocity="0.524"/>
  </joint>
  <!-- ****************************************************** Coxa Transmission ********************************************************  -->
  <transmission name="coxa_transmission_RR">
    <type>transmission_interface/SimpleTransmission</type>
    <joint name="coxa_joint_RR">
      <hardwareInterface>EffortJointInterface</hardwareInterface>
    </joint>
    <actuator name="coxa_motor_RR">
      <hardwareInterface>EffortJointInterface</hardwareInterface>
      <mechanicalReduction>1</mechanicalReduction>
    </actuator>
  </transmission>
  <!-- ****************************************************** Coxa Link ****************************************************************  -->
  <link name="coxa_RR">
    <visual>
      <origin rpy="0.0 0.0 0.0" xyz="0.0 0.0 0.0"/>
      <geometry>
        <mesh filename="package://robot_gazebo/meshes/golem/coxa.stl" scale="0.001 0.001 0.001"/>
      </geometry>
      <material name="green"/>
    </visual>
    <collision>
      <origin rpy="0.0 0.0 0.0" xyz="0.0 0.0 0.0"/>
      <geometry>
        <mesh filename="package://robot_gazebo/meshes/golem/coxa.stl" scale="0.001 0.001 0.001"/>
      </geometry>
      <material name="green"/>
    </collision>
    <inertial>
      <origin rpy="0.0 0.0 0.0" xyz="0.0 0.0 0.0"/>
      <mass value="0.00001"/>
      <inertia ixx="1.0" ixy="0.0" ixz="0.0" iyy="1.0" iyz="0.0" izz="1.0"/>
    </inertial>
  </link>
  <!-- ****************************************************** Femur Joint **************************************************************  -->
  <joint name="femur_joint_RR" type="revolute">
    <origin rpy="-1.5707963267948966 1.5707963267948966 0.0" xyz="0.05893 0.0 0.0"/>
    <parent link="coxa_RR"/>
    <child link="femur_RR"/>
    <axis xyz="0.0 0.0 1"/>
    <limit effort="6.0" lower="-3.14" upper="3.14" velocity="0.524"/>
  </joint>
  <!-- ****************************************************** Femur Transmission *******************************************************  -->
  <transmission name="femur_transmission_RR">
    <type>transmission_interface/SimpleTransmission</type>
    <joint name="femur_joint_RR">
      <hardwareInterface>EffortJointInterface</hardwareInterface>
    </joint>
    <actuator name="femur_motor_RR">
      <hardwareInterface>EffortJointInterface</hardwareInterface>
      <mechanicalReduction>1</mechanicalReduction>
    </actuator>
  </transmission>
  <!-- ****************************************************** Femur Link ***************************************************************  -->
  <link name="femur_RR">
    <visual>
      <origin rpy="0.0 0.0 0.0" xyz="0.0 0.0 0.0"/>
      <geometry>
        <mesh filename="package://robot_gazebo/meshes/golem/femur.stl" scale="0.001 0.001 0.001"/>
      </geometry>
      <material name="red"/>
    </visual>
    <collision>
      <origin rpy="0.0 0.0 0.0" xyz="0.0 0.0 0.0"/>
      <geometry>
        <mesh filename="package://robot_gazebo/meshes/golem/femur.stl" scale="0.001 0.001 0.001"/>
      </geometry>
      <material name="read"/>
    </collision>
    <inertial>
      <origin rpy="0.0 0.0 0.0" xyz="0.0 0.0 0.0"/>
      <mass value="0.00001"/>
      <inertia ixx="1.0" ixy="0.0" ixz="0.0" iyy="1.0" iyz="0.0" izz="1.0"/>
    </inertial>
  </link>
  <!-- ****************************************************** Tibia Joint **************************************************************  -->
  <joint name="tibia_joint_RR" type="revolute">
    <origin rpy="3.141592653589793 0.0 0.0" xyz="0.0 -0.10798 0.0"/>
    <parent link="femur_RR"/>
    <child link="tibia_RR"/>
    <axis xyz="0.0 0.0 1"/>
    <limit effort="6.0" lower="-3.14" upper="3.14" velocity="0.524"/>
  </joint>
  <!-- ****************************************************** Tibia Transmission *******************************************************  -->
  <transmission name="tibia_transmission_RR">
    <type>transmission_interface/SimpleTransmission</type>
    <joint name="tibia_joint_RR">
      <hardwareInterface>EffortJointInterface</hardwareInterface>
    </joint>
    <actuator name="tibia_motor_RR">
      <hardwareInterface>EffortJointInterface</hardwareInterface>
      <mechanicalReduction>1</mechanicalReduction>
    </actuator>
  </transmission>
  <!-- ****************************************************** Tibia Link ***************************************************************  -->
  <link name="tibia_RR">
    <visual>
      <origin rpy="0.0 0.0 0.0" xyz="0.0 0.0 0.0"/>
      <geometry>
        <mesh filename="package://robot_gazebo/meshes/golem/tibia.stl" scale="0.001 0.001 0.001"/>
      </geometry>
      <material name="green"/>
    </visual>
    <collision>
      <origin rpy="0.0 0.0 0.0" xyz="0.0 0.0 0.0"/>
      <geometry>
        <mesh filename="package://robot_gazebo/meshes/golem/tibia.stl" scale="0.001 0.001 0.001"/>
      </geometry>
      <material name="green"/>
    </collision>
    <inertial>
      <origin rpy="0.0 0.0 0.0" xyz="0.0 0.0 0.0"/>
      <mass value="0.00001"/>
      <inertia ixx="1.0" ixy="0.0" ixz="0.0" iyy="1.0" iyz="0.0" izz="1.0"/>
    </inertial>
  </link>
  <!-- ****************************************************** Tarsus Joint *************************************************************  -->
  <joint name="tarsus_joint_RR" type="revolute">
    <origin rpy="0.0 0.0 0.0" xyz="0.08774 0.0 0.0"/>
    <parent link="tibia_RR"/>
    <child link="tarsus_RR"/>
    <axis xyz="0.0 0.0 1"/>
    <limit effort="6.0" lower="-3.14" upper="3.14" velocity="0.524"/>
  </joint>
  <!-- ****************************************************** Tarsus Transmission ******************************************************  -->
  <transmission name="tarsus_transmission_RR">
    <type>transmission_interface/SimpleTransmission</type>
    <joint name="tarsus_joint_RR">
      <hardwareInterface>EffortJointInterface</hardwareInterface>
    </joint>
    <actuator name="tarsus_motor_RR">
      <hardwareInterface>EffortJointInterface</hardwareInterface>
      <mechanicalReduction>1</mechanicalReduction>
    </actuator>
  </transmission>
  <!-- ****************************************************** Tarsus Link **************************************************************  -->
  <link name="tarsus_RR">
    <visual>
      <origin rpy="0.0 0.0 0.0" xyz="0.0 0.0 0.0"/>
      <geometry>
        <mesh filename="package://robot_gazebo/meshes/golem/tarsus.stl" scale="0.001 0.001 0.001"/>
      </geometry>
      <material name="red"/>
    </visual>
    <collision>
      <origin rpy="0.0 0.0 0.0" xyz="0.0 0.0 0.0"/>
      <geometry>
        <mesh filename="package://robot_gazebo/meshes/golem/tarsus.stl" scale="0.001 0.001 0.001"/>
      </geometry>
      <material name="red"/>
    </collision>
    <inertial>
      <origin rpy="0.0 0.0 0.0" xyz="0.0 0.0 0.0"/>
      <mass value="0.00001"/>
      <inertia ixx="1.0" ixy="0.0" ixz="0.0" iyy="1.0" iyz="0.0" izz="1.0"/>
    </inertial>
  </link>
  <!-- ****************************************************** Foot Joint ***************************************************************  -->
  <joint name="foot_joint_RR" type="fixed">
    <origin rpy="0.0 0.0 0.0" xyz="0.12065 0.0 0.0"/>
    <parent link="tarsus_RR"/>
    <child link="foot_RR"/>
  </joint>
  <!-- ****************************************************** Foot Link ****************************************************************  -->
  <link name="foot_RR">
    <inertial>
      <origin rpy="0.0 0.0 0.0" xyz="0.0 0.0 0.0"/>
      <mass value="0.00001"/>
      <inertia ixx="1.0" ixy="0.0" ixz="0.0" iyy="1.0" iyz="0.0" izz="1.0"/>
    </inertial>
  </link>
  <!-- ******************************************************  End of Macro ************************************************************  -->
  <!-- ****************************************************** Leg Center Joint *********************************************************  -->
  <joint name="leg_center_joint_RM" type="fixed">
    <origin rpy="0.0 0.0 0.0" xyz="0.0 -0.13335 0.0"/>
    <parent link="body_link"/>
    <child link="leg_center_RM"/>
  </joint>
  <!-- ****************************************************** Leg Center Link **********************************************************  -->
  <link name="leg_center_RM">
    <inertial>
      <origin rpy="0.0 0.0 0.0" xyz="0.0 0.0 0.0"/>
      <mass value="0.00001"/>
      <inertia ixx="1.0" ixy="0.0" ixz="0.0" iyy="1.0" iyz="0.0" izz="1.0"/>
    </inertial>
  </link>
  <!-- ****************************************************** Coxa Joint ***************************************************************  -->
  <joint name="coxa_joint_RM" type="revolute">
    <origin rpy="0.0 0.0 -1.5707963267948966" xyz="0.0 0.0 0.0"/>
    <parent link="leg_center_RM"/>
    <child link="coxa_RM"/>
    <axis xyz="0.0 0.0 1.0"/>
    <limit effort="6.0" lower="-3.14" upper="3.14" velocity="0.524"/>
  </joint>
  <!-- ****************************************************** Coxa Transmission ********************************************************  -->
  <transmission name="coxa_transmission_RM">
    <type>transmission_interface/SimpleTransmission</type>
    <joint name="coxa_joint_RM">
      <hardwareInterface>EffortJointInterface</hardwareInterface>
    </joint>
    <actuator name="coxa_motor_RM">
      <hardwareInterface>EffortJointInterface</hardwareInterface>
      <mechanicalReduction>1</mechanicalReduction>
    </actuator>
  </transmission>
  <!-- ****************************************************** Coxa Link ****************************************************************  -->
  <link name="coxa_RM">
    <visual>
      <origin rpy="0.0 0.0 0.0" xyz="0.0 0.0 0.0"/>
      <geometry>
        <mesh filename="package://robot_gazebo/meshes/golem/coxa.stl" scale="0.001 0.001 0.001"/>
      </geometry>
      <material name="green"/>
    </visual>
    <collision>
      <origin rpy="0.0 0.0 0.0" xyz="0.0 0.0 0.0"/>
      <geometry>
        <mesh filename="package://robot_gazebo/meshes/golem/coxa.stl" scale="0.001 0.001 0.001"/>
      </geometry>
      <material name="green"/>
    </collision>
    <inertial>
      <origin rpy="0.0 0.0 0.0" xyz="0.0 0.0 0.0"/>
      <mass value="0.00001"/>
      <inertia ixx="1.0" ixy="0.0" ixz="0.0" iyy="1.0" iyz="0.0" izz="1.0"/>
    </inertial>
  </link>
  <!-- ****************************************************** Femur Joint **************************************************************  -->
  <joint name="femur_joint_RM" type="revolute">
    <origin rpy="-1.5707963267948966 1.5707963267948966 0.0" xyz="0.05893 0.0 0.0"/>
    <parent link="coxa_RM"/>
    <child link="femur_RM"/>
    <axis xyz="0.0 0.0 1"/>
    <limit effort="6.0" lower="-3.14" upper="3.14" velocity="0.524"/>
  </joint>
  <!-- ****************************************************** Femur Transmission *******************************************************  -->
  <transmission name="femur_transmission_RM">
    <type>transmission_interface/SimpleTransmission</type>
    <joint name="femur_joint_RM">
      <hardwareInterface>EffortJointInterface</hardwareInterface>
    </joint>
    <actuator name="femur_motor_RM">
      <hardwareInterface>EffortJointInterface</hardwareInterface>
      <mechanicalReduction>1</mechanicalReduction>
    </actuator>
  </transmission>
  <!-- ****************************************************** Femur Link ***************************************************************  -->
  <link name="femur_RM">
    <visual>
      <origin rpy="0.0 0.0 0.0" xyz="0.0 0.0 0.0"/>
      <geometry>
        <mesh filename="package://robot_gazebo/meshes/golem/femur.stl" scale="0.001 0.001 0.001"/>
      </geometry>
      <material name="red"/>
    </visual>
    <collision>
      <origin rpy="0.0 0.0 0.0" xyz="0.0 0.0 0.0"/>
      <geometry>
        <mesh filename="package://robot_gazebo/meshes/golem/femur.stl" scale="0.001 0.001 0.001"/>
      </geometry>
      <material name="read"/>
    </collision>
    <inertial>
      <origin rpy="0.0 0.0 0.0" xyz="0.0 0.0 0.0"/>
      <mass value="0.00001"/>
      <inertia ixx="1.0" ixy="0.0" ixz="0.0" iyy="1.0" iyz="0.0" izz="1.0"/>
    </inertial>
  </link>
  <!-- ****************************************************** Tibia Joint **************************************************************  -->
  <joint name="tibia_joint_RM" type="revolute">
    <origin rpy="3.141592653589793 0.0 0.0" xyz="0.0 -0.10798 0.0"/>
    <parent link="femur_RM"/>
    <child link="tibia_RM"/>
    <axis xyz="0.0 0.0 1"/>
    <limit effort="6.0" lower="-3.14" upper="3.14" velocity="0.524"/>
  </joint>
  <!-- ****************************************************** Tibia Transmission *******************************************************  -->
  <transmission name="tibia_transmission_RM">
    <type>transmission_interface/SimpleTransmission</type>
    <joint name="tibia_joint_RM">
      <hardwareInterface>EffortJointInterface</hardwareInterface>
    </joint>
    <actuator name="tibia_motor_RM">
      <hardwareInterface>EffortJointInterface</hardwareInterface>
      <mechanicalReduction>1</mechanicalReduction>
    </actuator>
  </transmission>
  <!-- ****************************************************** Tibia Link ***************************************************************  -->
  <link name="tibia_RM">
    <visual>
      <origin rpy="0.0 0.0 0.0" xyz="0.0 0.0 0.0"/>
      <geometry>
        <mesh filename="package://robot_gazebo/meshes/golem/tibia.stl" scale="0.001 0.001 0.001"/>
      </geometry>
      <material name="green"/>
    </visual>
    <collision>
      <origin rpy="0.0 0.0 0.0" xyz="0.0 0.0 0.0"/>
      <geometry>
        <mesh filename="package://robot_gazebo/meshes/golem/tibia.stl" scale="0.001 0.001 0.001"/>
      </geometry>
      <material name="green"/>
    </collision>
    <inertial>
      <origin rpy="0.0 0.0 0.0" xyz="0.0 0.0 0.0"/>
      <mass value="0.00001"/>
      <inertia ixx="1.0" ixy="0.0" ixz="0.0" iyy="1.0" iyz="0.0" izz="1.0"/>
    </inertial>
  </link>
  <!-- ****************************************************** Tarsus Joint *************************************************************  -->
  <joint name="tarsus_joint_RM" type="revolute">
    <origin rpy="0.0 0.0 0.0" xyz="0.08774 0.0 0.0"/>
    <parent link="tibia_RM"/>
    <child link="tarsus_RM"/>
    <axis xyz="0.0 0.0 1"/>
    <limit effort="6.0" lower="-3.14" upper="3.14" velocity="0.524"/>
  </joint>
  <!-- ****************************************************** Tarsus Transmission ******************************************************  -->
  <transmission name="tarsus_transmission_RM">
    <type>transmission_interface/SimpleTransmission</type>
    <joint name="tarsus_joint_RM">
      <hardwareInterface>EffortJointInterface</hardwareInterface>
    </joint>
    <actuator name="tarsus_motor_RM">
      <hardwareInterface>EffortJointInterface</hardwareInterface>
      <mechanicalReduction>1</mechanicalReduction>
    </actuator>
  </transmission>
  <!-- ****************************************************** Tarsus Link **************************************************************  -->
  <link name="tarsus_RM">
    <visual>
      <origin rpy="0.0 0.0 0.0" xyz="0.0 0.0 0.0"/>
      <geometry>
        <mesh filename="package://robot_gazebo/meshes/golem/tarsus.stl" scale="0.001 0.001 0.001"/>
      </geometry>
      <material name="red"/>
    </visual>
    <collision>
      <origin rpy="0.0 0.0 0.0" xyz="0.0 0.0 0.0"/>
      <geometry>
        <mesh filename="package://robot_gazebo/meshes/golem/tarsus.stl" scale="0.001 0.001 0.001"/>
      </geometry>
      <material name="red"/>
    </collision>
    <inertial>
      <origin rpy="0.0 0.0 0.0" xyz="0.0 0.0 0.0"/>
      <mass value="0.00001"/>
      <inertia ixx="1.0" ixy="0.0" ixz="0.0" iyy="1.0" iyz="0.0" izz="1.0"/>
    </inertial>
  </link>
  <!-- ****************************************************** Foot Joint ***************************************************************  -->
  <joint name="foot_joint_RM" type="fixed">
    <origin rpy="0.0 0.0 0.0" xyz="0.12065 0.0 0.0"/>
    <parent link="tarsus_RM"/>
    <child link="foot_RM"/>
  </joint>
  <!-- ****************************************************** Foot Link ****************************************************************  -->
  <link name="foot_RM">
    <inertial>
      <origin rpy="0.0 0.0 0.0" xyz="0.0 0.0 0.0"/>
      <mass value="0.00001"/>
      <inertia ixx="1.0" ixy="0.0" ixz="0.0" iyy="1.0" iyz="0.0" izz="1.0"/>
    </inertial>
  </link>
  <!-- ******************************************************  End of Macro ************************************************************  -->
  <!-- ****************************************************** Leg Center Joint *********************************************************  -->
  <joint name="leg_center_joint_RF" type="fixed">
    <origin rpy="0.0 0.0 0.0" xyz="0.1778 -0.0825 0.0"/>
    <parent link="body_link"/>
    <child link="leg_center_RF"/>
  </joint>
  <!-- ****************************************************** Leg Center Link **********************************************************  -->
  <link name="leg_center_RF">
    <inertial>
      <origin rpy="0.0 0.0 0.0" xyz="0.0 0.0 0.0"/>
      <mass value="0.00001"/>
      <inertia ixx="1.0" ixy="0.0" ixz="0.0" iyy="1.0" iyz="0.0" izz="1.0"/>
    </inertial>
  </link>
  <!-- ****************************************************** Coxa Joint ***************************************************************  -->
  <joint name="coxa_joint_RF" type="revolute">
    <origin rpy="0.0 0.0 -0.7853981633974483" xyz="0.0 0.0 0.0"/>
    <parent link="leg_center_RF"/>
    <child link="coxa_RF"/>
    <axis xyz="0.0 0.0 1.0"/>
    <limit effort="6.0" lower="-3.14" upper="3.14" velocity="0.524"/>
  </joint>
  <!-- ****************************************************** Coxa Transmission ********************************************************  -->
  <transmission name="coxa_transmission_RF">
    <type>transmission_interface/SimpleTransmission</type>
    <joint name="coxa_joint_RF">
      <hardwareInterface>EffortJointInterface</hardwareInterface>
    </joint>
    <actuator name="coxa_motor_RF">
      <hardwareInterface>EffortJointInterface</hardwareInterface>
      <mechanicalReduction>1</mechanicalReduction>
    </actuator>
  </transmission>
  <!-- ****************************************************** Coxa Link ****************************************************************  -->
  <link name="coxa_RF">
    <visual>
      <origin rpy="0.0 0.0 0.0" xyz="0.0 0.0 0.0"/>
      <geometry>
        <mesh filename="package://robot_gazebo/meshes/golem/coxa.stl" scale="0.001 0.001 0.001"/>
      </geometry>
      <material name="green"/>
    </visual>
    <collision>
      <origin rpy="0.0 0.0 0.0" xyz="0.0 0.0 0.0"/>
      <geometry>
        <mesh filename="package://robot_gazebo/meshes/golem/coxa.stl" scale="0.001 0.001 0.001"/>
      </geometry>
      <material name="green"/>
    </collision>
    <inertial>
      <origin rpy="0.0 0.0 0.0" xyz="0.0 0.0 0.0"/>
      <mass value="0.00001"/>
      <inertia ixx="1.0" ixy="0.0" ixz="0.0" iyy="1.0" iyz="0.0" izz="1.0"/>
    </inertial>
  </link>
  <!-- ****************************************************** Femur Joint **************************************************************  -->
  <joint name="femur_joint_RF" type="revolute">
    <origin rpy="-1.5707963267948966 1.5707963267948966 0.0" xyz="0.05893 0.0 0.0"/>
    <parent link="coxa_RF"/>
    <child link="femur_RF"/>
    <axis xyz="0.0 0.0 1"/>
    <limit effort="6.0" lower="-3.14" upper="3.14" velocity="0.524"/>
  </joint>
  <!-- ****************************************************** Femur Transmission *******************************************************  -->
  <transmission name="femur_transmission_RF">
    <type>transmission_interface/SimpleTransmission</type>
    <joint name="femur_joint_RF">
      <hardwareInterface>EffortJointInterface</hardwareInterface>
    </joint>
    <actuator name="femur_motor_RF">
      <hardwareInterface>EffortJointInterface</hardwareInterface>
      <mechanicalReduction>1</mechanicalReduction>
    </actuator>
  </transmission>
  <!-- ****************************************************** Femur Link ***************************************************************  -->
  <link name="femur_RF">
    <visual>
      <origin rpy="0.0 0.0 0.0" xyz="0.0 0.0 0.0"/>
      <geometry>
        <mesh filename="package://robot_gazebo/meshes/golem/femur.stl" scale="0.001 0.001 0.001"/>
      </geometry>
      <material name="red"/>
    </visual>
    <collision>
      <origin rpy="0.0 0.0 0.0" xyz="0.0 0.0 0.0"/>
      <geometry>
        <mesh filename="package://robot_gazebo/meshes/golem/femur.stl" scale="0.001 0.001 0.001"/>
      </geometry>
      <material name="read"/>
    </collision>
    <inertial>
      <origin rpy="0.0 0.0 0.0" xyz="0.0 0.0 0.0"/>
      <mass value="0.00001"/>
      <inertia ixx="1.0" ixy="0.0" ixz="0.0" iyy="1.0" iyz="0.0" izz="1.0"/>
    </inertial>
  </link>
  <!-- ****************************************************** Tibia Joint **************************************************************  -->
  <joint name="tibia_joint_RF" type="revolute">
    <origin rpy="3.141592653589793 0.0 0.0" xyz="0.0 -0.10798 0.0"/>
    <parent link="femur_RF"/>
    <child link="tibia_RF"/>
    <axis xyz="0.0 0.0 1"/>
    <limit effort="6.0" lower="-3.14" upper="3.14" velocity="0.524"/>
  </joint>
  <!-- ****************************************************** Tibia Transmission *******************************************************  -->
  <transmission name="tibia_transmission_RF">
    <type>transmission_interface/SimpleTransmission</type>
    <joint name="tibia_joint_RF">
      <hardwareInterface>EffortJointInterface</hardwareInterface>
    </joint>
    <actuator name="tibia_motor_RF">
      <hardwareInterface>EffortJointInterface</hardwareInterface>
      <mechanicalReduction>1</mechanicalReduction>
    </actuator>
  </transmission>
  <!-- ****************************************************** Tibia Link ***************************************************************  -->
  <link name="tibia_RF">
    <visual>
      <origin rpy="0.0 0.0 0.0" xyz="0.0 0.0 0.0"/>
      <geometry>
        <mesh filename="package://robot_gazebo/meshes/golem/tibia.stl" scale="0.001 0.001 0.001"/>
      </geometry>
      <material name="green"/>
    </visual>
    <collision>
      <origin rpy="0.0 0.0 0.0" xyz="0.0 0.0 0.0"/>
      <geometry>
        <mesh filename="package://robot_gazebo/meshes/golem/tibia.stl" scale="0.001 0.001 0.001"/>
      </geometry>
      <material name="green"/>
    </collision>
    <inertial>
      <origin rpy="0.0 0.0 0.0" xyz="0.0 0.0 0.0"/>
      <mass value="0.00001"/>
      <inertia ixx="1.0" ixy="0.0" ixz="0.0" iyy="1.0" iyz="0.0" izz="1.0"/>
    </inertial>
  </link>
  <!-- ****************************************************** Tarsus Joint *************************************************************  -->
  <joint name="tarsus_joint_RF" type="revolute">
    <origin rpy="0.0 0.0 0.0" xyz="0.08774 0.0 0.0"/>
    <parent link="tibia_RF"/>
    <child link="tarsus_RF"/>
    <axis xyz="0.0 0.0 1"/>
    <limit effort="6.0" lower="-3.14" upper="3.14" velocity="0.524"/>
  </joint>
  <!-- ****************************************************** Tarsus Transmission ******************************************************  -->
  <transmission name="tarsus_transmission_RF">
    <type>transmission_interface/SimpleTransmission</type>
    <joint name="tarsus_joint_RF">
      <hardwareInterface>EffortJointInterface</hardwareInterface>
    </joint>
    <actuator name="tarsus_motor_RF">
      <hardwareInterface>EffortJointInterface</hardwareInterface>
      <mechanicalReduction>1</mechanicalReduction>
    </actuator>
  </transmission>
  <!-- ****************************************************** Tarsus Link **************************************************************  -->
  <link name="tarsus_RF">
    <visual>
      <origin rpy="0.0 0.0 0.0" xyz="0.0 0.0 0.0"/>
      <geometry>
        <mesh filename="package://robot_gazebo/meshes/golem/tarsus.stl" scale="0.001 0.001 0.001"/>
      </geometry>
      <material name="red"/>
    </visual>
    <collision>
      <origin rpy="0.0 0.0 0.0" xyz="0.0 0.0 0.0"/>
      <geometry>
        <mesh filename="package://robot_gazebo/meshes/golem/tarsus.stl" scale="0.001 0.001 0.001"/>
      </geometry>
      <material name="red"/>
    </collision>
    <inertial>
      <origin rpy="0.0 0.0 0.0" xyz="0.0 0.0 0.0"/>
      <mass value="0.00001"/>
      <inertia ixx="1.0" ixy="0.0" ixz="0.0" iyy="1.0" iyz="0.0" izz="1.0"/>
    </inertial>
  </link>
  <!-- ****************************************************** Foot Joint ***************************************************************  -->
  <joint name="foot_joint_RF" type="fixed">
    <origin rpy="0.0 0.0 0.0" xyz="0.12065 0.0 0.0"/>
    <parent link="tarsus_RF"/>
    <child link="foot_RF"/>
  </joint>
  <!-- ****************************************************** Foot Link ****************************************************************  -->
  <link name="foot_RF">
    <inertial>
      <origin rpy="0.0 0.0 0.0" xyz="0.0 0.0 0.0"/>
      <mass value="0.00001"/>
      <inertia ixx="1.0" ixy="0.0" ixz="0.0" iyy="1.0" iyz="0.0" izz="1.0"/>
    </inertial>
  </link>
  <!-- ******************************************************  End of Macro ************************************************************  -->
  <!-- ****************************************************** Leg Center Joint *********************************************************  -->
  <joint name="leg_center_joint_LR" type="fixed">
    <origin rpy="0.0 0.0 0.0" xyz="-0.1778 0.0825 0.0"/>
    <parent link="body_link"/>
    <child link="leg_center_LR"/>
  </joint>
  <!-- ****************************************************** Leg Center Link **********************************************************  -->
  <link name="leg_center_LR">
    <inertial>
      <origin rpy="0.0 0.0 0.0" xyz="0.0 0.0 0.0"/>
      <mass value="0.00001"/>
      <inertia ixx="1.0" ixy="0.0" ixz="0.0" iyy="1.0" iyz="0.0" izz="1.0"/>
    </inertial>
  </link>
  <!-- ****************************************************** Coxa Joint ***************************************************************  -->
  <joint name="coxa_joint_LR" type="revolute">
    <origin rpy="0.0 0.0 2.356194490192345" xyz="0.0 0.0 0.0"/>
    <parent link="leg_center_LR"/>
    <child link="coxa_LR"/>
    <axis xyz="0.0 0.0 1.0"/>
    <limit effort="6.0" lower="-3.14" upper="3.14" velocity="0.524"/>
  </joint>
  <!-- ****************************************************** Coxa Transmission ********************************************************  -->
  <transmission name="coxa_transmission_LR">
    <type>transmission_interface/SimpleTransmission</type>
    <joint name="coxa_joint_LR">
      <hardwareInterface>EffortJointInterface</hardwareInterface>
    </joint>
    <actuator name="coxa_motor_LR">
      <hardwareInterface>EffortJointInterface</hardwareInterface>
      <mechanicalReduction>1</mechanicalReduction>
    </actuator>
  </transmission>
  <!-- ****************************************************** Coxa Link ****************************************************************  -->
  <link name="coxa_LR">
    <visual>
      <origin rpy="0.0 0.0 0.0" xyz="0.0 0.0 0.0"/>
      <geometry>
        <mesh filename="package://robot_gazebo/meshes/golem/coxa.stl" scale="0.001 0.001 0.001"/>
      </geometry>
      <material name="green"/>
    </visual>
    <collision>
      <origin rpy="0.0 0.0 0.0" xyz="0.0 0.0 0.0"/>
      <geometry>
        <mesh filename="package://robot_gazebo/meshes/golem/coxa.stl" scale="0.001 0.001 0.001"/>
      </geometry>
      <material name="green"/>
    </collision>
    <inertial>
      <origin rpy="0.0 0.0 0.0" xyz="0.0 0.0 0.0"/>
      <mass value="0.00001"/>
      <inertia ixx="1.0" ixy="0.0" ixz="0.0" iyy="1.0" iyz="0.0" izz="1.0"/>
    </inertial>
  </link>
  <!-- ****************************************************** Femur Joint **************************************************************  -->
  <joint name="femur_joint_LR" type="revolute">
    <origin rpy="-1.5707963267948966 1.5707963267948966 0.0" xyz="0.05893 0.0 0.0"/>
    <parent link="coxa_LR"/>
    <child link="femur_LR"/>
    <axis xyz="0.0 0.0 -1"/>
    <limit effort="6.0" lower="-3.14" upper="3.14" velocity="0.524"/>
  </joint>
  <!-- ****************************************************** Femur Transmission *******************************************************  -->
  <transmission name="femur_transmission_LR">
    <type>transmission_interface/SimpleTransmission</type>
    <joint name="femur_joint_LR">
      <hardwareInterface>EffortJointInterface</hardwareInterface>
    </joint>
    <actuator name="femur_motor_LR">
      <hardwareInterface>EffortJointInterface</hardwareInterface>
      <mechanicalReduction>1</mechanicalReduction>
    </actuator>
  </transmission>
  <!-- ****************************************************** Femur Link ***************************************************************  -->
  <link name="femur_LR">
    <visual>
      <origin rpy="0.0 0.0 0.0" xyz="0.0 0.0 0.0"/>
      <geometry>
        <mesh filename="package://robot_gazebo/meshes/golem/femur.stl" scale="0.001 0.001 0.001"/>
      </geometry>
      <material name="red"/>
    </visual>
    <collision>
      <origin rpy="0.0 0.0 0.0" xyz="0.0 0.0 0.0"/>
      <geometry>
        <mesh filename="package://robot_gazebo/meshes/golem/femur.stl" scale="0.001 0.001 0.001"/>
      </geometry>
      <material name="read"/>
    </collision>
    <inertial>
      <origin rpy="0.0 0.0 0.0" xyz="0.0 0.0 0.0"/>
      <mass value="0.00001"/>
      <inertia ixx="1.0" ixy="0.0" ixz="0.0" iyy="1.0" iyz="0.0" izz="1.0"/>
    </inertial>
  </link>
  <!-- ****************************************************** Tibia Joint **************************************************************  -->
  <joint name="tibia_joint_LR" type="revolute">
    <origin rpy="3.141592653589793 0.0 0.0" xyz="0.0 -0.10798 0.0"/>
    <parent link="femur_LR"/>
    <child link="tibia_LR"/>
    <axis xyz="0.0 0.0 -1"/>
    <limit effort="6.0" lower="-3.14" upper="3.14" velocity="0.524"/>
  </joint>
  <!-- ****************************************************** Tibia Transmission *******************************************************  -->
  <transmission name="tibia_transmission_LR">
    <type>transmission_interface/SimpleTransmission</type>
    <joint name="tibia_joint_LR">
      <hardwareInterface>EffortJointInterface</hardwareInterface>
    </joint>
    <actuator name="tibia_motor_LR">
      <hardwareInterface>EffortJointInterface</hardwareInterface>
      <mechanicalReduction>1</mechanicalReduction>
    </actuator>
  </transmission>
  <!-- ****************************************************** Tibia Link ***************************************************************  -->
  <link name="tibia_LR">
    <visual>
      <origin rpy="0.0 0.0 0.0" xyz="0.0 0.0 0.0"/>
      <geometry>
        <mesh filename="package://robot_gazebo/meshes/golem/tibia.stl" scale="0.001 0.001 0.001"/>
      </geometry>
      <material name="green"/>
    </visual>
    <collision>
      <origin rpy="0.0 0.0 0.0" xyz="0.0 0.0 0.0"/>
      <geometry>
        <mesh filename="package://robot_gazebo/meshes/golem/tibia.stl" scale="0.001 0.001 0.001"/>
      </geometry>
      <material name="green"/>
    </collision>
    <inertial>
      <origin rpy="0.0 0.0 0.0" xyz="0.0 0.0 0.0"/>
      <mass value="0.00001"/>
      <inertia ixx="1.0" ixy="0.0" ixz="0.0" iyy="1.0" iyz="0.0" izz="1.0"/>
    </inertial>
  </link>
  <!-- ****************************************************** Tarsus Joint *************************************************************  -->
  <joint name="tarsus_joint_LR" type="revolute">
    <origin rpy="0.0 0.0 0.0" xyz="0.08774 0.0 0.0"/>
    <parent link="tibia_LR"/>
    <child link="tarsus_LR"/>
    <axis xyz="0.0 0.0 -1"/>
    <limit effort="6.0" lower="-3.14" upper="3.14" velocity="0.524"/>
  </joint>
  <!-- ****************************************************** Tarsus Transmission ******************************************************  -->
  <transmission name="tarsus_transmission_LR">
    <type>transmission_interface/SimpleTransmission</type>
    <joint name="tarsus_joint_LR">
      <hardwareInterface>EffortJointInterface</hardwareInterface>
    </joint>
    <actuator name="tarsus_motor_LR">
      <hardwareInterface>EffortJointInterface</hardwareInterface>
      <mechanicalReduction>1</mechanicalReduction>
    </actuator>
  </transmission>
  <!-- ****************************************************** Tarsus Link **************************************************************  -->
  <link name="tarsus_LR">
    <visual>
      <origin rpy="0.0 0.0 0.0" xyz="0.0 0.0 0.0"/>
      <geometry>
        <mesh filename="package://robot_gazebo/meshes/golem/tarsus.stl" scale="0.001 0.001 0.001"/>
      </geometry>
      <material name="red"/>
    </visual>
    <collision>
      <origin rpy="0.0 0.0 0.0" xyz="0.0 0.0 0.0"/>
      <geometry>
        <mesh filename="package://robot_gazebo/meshes/golem/tarsus.stl" scale="0.001 0.001 0.001"/>
      </geometry>
      <material name="red"/>
    </collision>
    <inertial>
      <origin rpy="0.0 0.0 0.0" xyz="0.0 0.0 0.0"/>
      <mass value="0.00001"/>
      <inertia ixx="1.0" ixy="0.0" ixz="0.0" iyy="1.0" iyz="0.0" izz="1.0"/>
    </inertial>
  </link>
  <!-- ****************************************************** Foot Joint ***************************************************************  -->
  <joint name="foot_joint_LR" type="fixed">
    <origin rpy="0.0 0.0 0.0" xyz="0.12065 0.0 0.0"/>
    <parent link="tarsus_LR"/>
    <child link="foot_LR"/>
  </joint>
  <!-- ****************************************************** Foot Link ****************************************************************  -->
  <link name="foot_LR">
    <inertial>
      <origin rpy="0.0 0.0 0.0" xyz="0.0 0.0 0.0"/>
      <mass value="0.00001"/>
      <inertia ixx="1.0" ixy="0.0" ixz="0.0" iyy="1.0" iyz="0.0" izz="1.0"/>
    </inertial>
  </link>
  <!-- ******************************************************  End of Macro ************************************************************  -->
  <!-- ****************************************************** Leg Center Joint *********************************************************  -->
  <joint name="leg_center_joint_LM" type="fixed">
    <origin rpy="0.0 0.0 0.0" xyz="0.0 0.13335 0.0"/>
    <parent link="body_link"/>
    <child link="leg_center_LM"/>
  </joint>
  <!-- ****************************************************** Leg Center Link **********************************************************  -->
  <link name="leg_center_LM">
    <inertial>
      <origin rpy="0.0 0.0 0.0" xyz="0.0 0.0 0.0"/>
      <mass value="0.00001"/>
      <inertia ixx="1.0" ixy="0.0" ixz="0.0" iyy="1.0" iyz="0.0" izz="1.0"/>
    </inertial>
  </link>
  <!-- ****************************************************** Coxa Joint ***************************************************************  -->
  <joint name="coxa_joint_LM" type="revolute">
    <origin rpy="0.0 0.0 1.5707963267948966" xyz="0.0 0.0 0.0"/>
    <parent link="leg_center_LM"/>
    <child link="coxa_LM"/>
    <axis xyz="0.0 0.0 1.0"/>
    <limit effort="6.0" lower="-3.14" upper="3.14" velocity="0.524"/>
  </joint>
  <!-- ****************************************************** Coxa Transmission ********************************************************  -->
  <transmission name="coxa_transmission_LM">
    <type>transmission_interface/SimpleTransmission</type>
    <joint name="coxa_joint_LM">
      <hardwareInterface>EffortJointInterface</hardwareInterface>
    </joint>
    <actuator name="coxa_motor_LM">
      <hardwareInterface>EffortJointInterface</hardwareInterface>
      <mechanicalReduction>1</mechanicalReduction>
    </actuator>
  </transmission>
  <!-- ****************************************************** Coxa Link ****************************************************************  -->
  <link name="coxa_LM">
    <visual>
      <origin rpy="0.0 0.0 0.0" xyz="0.0 0.0 0.0"/>
      <geometry>
        <mesh filename="package://robot_gazebo/meshes/golem/coxa.stl" scale="0.001 0.001 0.001"/>
      </geometry>
      <material name="green"/>
    </visual>
    <collision>
      <origin rpy="0.0 0.0 0.0" xyz="0.0 0.0 0.0"/>
      <geometry>
        <mesh filename="package://robot_gazebo/meshes/golem/coxa.stl" scale="0.001 0.001 0.001"/>
      </geometry>
      <material name="green"/>
    </collision>
    <inertial>
      <origin rpy="0.0 0.0 0.0" xyz="0.0 0.0 0.0"/>
      <mass value="0.00001"/>
      <inertia ixx="1.0" ixy="0.0" ixz="0.0" iyy="1.0" iyz="0.0" izz="1.0"/>
    </inertial>
  </link>
  <!-- ****************************************************** Femur Joint **************************************************************  -->
  <joint name="femur_joint_LM" type="revolute">
    <origin rpy="-1.5707963267948966 1.5707963267948966 0.0" xyz="0.05893 0.0 0.0"/>
    <parent link="coxa_LM"/>
    <child link="femur_LM"/>
    <axis xyz="0.0 0.0 -1"/>
    <limit effort="6.0" lower="-3.14" upper="3.14" velocity="0.524"/>
  </joint>
  <!-- ****************************************************** Femur Transmission *******************************************************  -->
  <transmission name="femur_transmission_LM">
    <type>transmission_interface/SimpleTransmission</type>
    <joint name="femur_joint_LM">
      <hardwareInterface>EffortJointInterface</hardwareInterface>
    </joint>
    <actuator name="femur_motor_LM">
      <hardwareInterface>EffortJointInterface</hardwareInterface>
      <mechanicalReduction>1</mechanicalReduction>
    </actuator>
  </transmission>
  <!-- ****************************************************** Femur Link ***************************************************************  -->
  <link name="femur_LM">
    <visual>
      <origin rpy="0.0 0.0 0.0" xyz="0.0 0.0 0.0"/>
      <geometry>
        <mesh filename="package://robot_gazebo/meshes/golem/femur.stl" scale="0.001 0.001 0.001"/>
      </geometry>
      <material name="red"/>
    </visual>
    <collision>
      <origin rpy="0.0 0.0 0.0" xyz="0.0 0.0 0.0"/>
      <geometry>
        <mesh filename="package://robot_gazebo/meshes/golem/femur.stl" scale="0.001 0.001 0.001"/>
      </geometry>
      <material name="read"/>
    </collision>
    <inertial>
      <origin rpy="0.0 0.0 0.0" xyz="0.0 0.0 0.0"/>
      <mass value="0.00001"/>
      <inertia ixx="1.0" ixy="0.0" ixz="0.0" iyy="1.0" iyz="0.0" izz="1.0"/>
    </inertial>
  </link>
  <!-- ****************************************************** Tibia Joint **************************************************************  -->
  <joint name="tibia_joint_LM" type="revolute">
    <origin rpy="3.141592653589793 0.0 0.0" xyz="0.0 -0.10798 0.0"/>
    <parent link="femur_LM"/>
    <child link="tibia_LM"/>
    <axis xyz="0.0 0.0 -1"/>
    <limit effort="6.0" lower="-3.14" upper="3.14" velocity="0.524"/>
  </joint>
  <!-- ****************************************************** Tibia Transmission *******************************************************  -->
  <transmission name="tibia_transmission_LM">
    <type>transmission_interface/SimpleTransmission</type>
    <joint name="tibia_joint_LM">
      <hardwareInterface>EffortJointInterface</hardwareInterface>
    </joint>
    <actuator name="tibia_motor_LM">
      <hardwareInterface>EffortJointInterface</hardwareInterface>
      <mechanicalReduction>1</mechanicalReduction>
    </actuator>
  </transmission>
  <!-- ****************************************************** Tibia Link ***************************************************************  -->
  <link name="tibia_LM">
    <visual>
      <origin rpy="0.0 0.0 0.0" xyz="0.0 0.0 0.0"/>
      <geometry>
        <mesh filename="package://robot_gazebo/meshes/golem/tibia.stl" scale="0.001 0.001 0.001"/>
      </geometry>
      <material name="green"/>
    </visual>
    <collision>
      <origin rpy="0.0 0.0 0.0" xyz="0.0 0.0 0.0"/>
      <geometry>
        <mesh filename="package://robot_gazebo/meshes/golem/tibia.stl" scale="0.001 0.001 0.001"/>
      </geometry>
      <material name="green"/>
    </collision>
    <inertial>
      <origin rpy="0.0 0.0 0.0" xyz="0.0 0.0 0.0"/>
      <mass value="0.00001"/>
      <inertia ixx="1.0" ixy="0.0" ixz="0.0" iyy="1.0" iyz="0.0" izz="1.0"/>
    </inertial>
  </link>
  <!-- ****************************************************** Tarsus Joint *************************************************************  -->
  <joint name="tarsus_joint_LM" type="revolute">
    <origin rpy="0.0 0.0 0.0" xyz="0.08774 0.0 0.0"/>
    <parent link="tibia_LM"/>
    <child link="tarsus_LM"/>
    <axis xyz="0.0 0.0 -1"/>
    <limit effort="6.0" lower="-3.14" upper="3.14" velocity="0.524"/>
  </joint>
  <!-- ****************************************************** Tarsus Transmission ******************************************************  -->
  <transmission name="tarsus_transmission_LM">
    <type>transmission_interface/SimpleTransmission</type>
    <joint name="tarsus_joint_LM">
      <hardwareInterface>EffortJointInterface</hardwareInterface>
    </joint>
    <actuator name="tarsus_motor_LM">
      <hardwareInterface>EffortJointInterface</hardwareInterface>
      <mechanicalReduction>1</mechanicalReduction>
    </actuator>
  </transmission>
  <!-- ****************************************************** Tarsus Link **************************************************************  -->
  <link name="tarsus_LM">
    <visual>
      <origin rpy="0.0 0.0 0.0" xyz="0.0 0.0 0.0"/>
      <geometry>
        <mesh filename="package://robot_gazebo/meshes/golem/tarsus.stl" scale="0.001 0.001 0.001"/>
      </geometry>
      <material name="red"/>
    </visual>
    <collision>
      <origin rpy="0.0 0.0 0.0" xyz="0.0 0.0 0.0"/>
      <geometry>
        <mesh filename="package://robot_gazebo/meshes/golem/tarsus.stl" scale="0.001 0.001 0.001"/>
      </geometry>
      <material name="red"/>
    </collision>
    <inertial>
      <origin rpy="0.0 0.0 0.0" xyz="0.0 0.0 0.0"/>
      <mass value="0.00001"/>
      <inertia ixx="1.0" ixy="0.0" ixz="0.0" iyy="1.0" iyz="0.0" izz="1.0"/>
    </inertial>
  </link>
  <!-- ****************************************************** Foot Joint ***************************************************************  -->
  <joint name="foot_joint_LM" type="fixed">
    <origin rpy="0.0 0.0 0.0" xyz="0.12065 0.0 0.0"/>
    <parent link="tarsus_LM"/>
    <child link="foot_LM"/>
  </joint>
  <!-- ****************************************************** Foot Link ****************************************************************  -->
  <link name="foot_LM">
    <inertial>
      <origin rpy="0.0 0.0 0.0" xyz="0.0 0.0 0.0"/>
      <mass value="0.00001"/>
      <inertia ixx="1.0" ixy="0.0" ixz="0.0" iyy="1.0" iyz="0.0" izz="1.0"/>
    </inertial>
  </link>
  <!-- ******************************************************  End of Macro ************************************************************  -->
  <!-- ****************************************************** Leg Center Joint *********************************************************  -->
  <joint name="leg_center_joint_LF" type="fixed">
    <origin rpy="0.0 0.0 0.0" xyz="0.1778 0.0825 0.0"/>
    <parent link="body_link"/>
    <child link="leg_center_LF"/>
  </joint>
  <!-- ****************************************************** Leg Center Link **********************************************************  -->
  <link name="leg_center_LF">
    <inertial>
      <origin rpy="0.0 0.0 0.0" xyz="0.0 0.0 0.0"/>
      <mass value="0.00001"/>
      <inertia ixx="1.0" ixy="0.0" ixz="0.0" iyy="1.0" iyz="0.0" izz="1.0"/>
    </inertial>
  </link>
  <!-- ****************************************************** Coxa Joint ***************************************************************  -->
  <joint name="coxa_joint_LF" type="revolute">
    <origin rpy="0.0 0.0 0.7853981633974483" xyz="0.0 0.0 0.0"/>
    <parent link="leg_center_LF"/>
    <child link="coxa_LF"/>
    <axis xyz="0.0 0.0 1.0"/>
    <limit effort="6.0" lower="-3.14" upper="3.14" velocity="0.524"/>
  </joint>
  <!-- ****************************************************** Coxa Transmission ********************************************************  -->
  <transmission name="coxa_transmission_LF">
    <type>transmission_interface/SimpleTransmission</type>
    <joint name="coxa_joint_LF">
      <hardwareInterface>EffortJointInterface</hardwareInterface>
    </joint>
    <actuator name="coxa_motor_LF">
      <hardwareInterface>EffortJointInterface</hardwareInterface>
      <mechanicalReduction>1</mechanicalReduction>
    </actuator>
  </transmission>
  <!-- ****************************************************** Coxa Link ****************************************************************  -->
  <link name="coxa_LF">
    <visual>
      <origin rpy="0.0 0.0 0.0" xyz="0.0 0.0 0.0"/>
      <geometry>
        <mesh filename="package://robot_gazebo/meshes/golem/coxa.stl" scale="0.001 0.001 0.001"/>
      </geometry>
      <material name="green"/>
    </visual>
    <collision>
      <origin rpy="0.0 0.0 0.0" xyz="0.0 0.0 0.0"/>
      <geometry>
        <mesh filename="package://robot_gazebo/meshes/golem/coxa.stl" scale="0.001 0.001 0.001"/>
      </geometry>
      <material name="green"/>
    </collision>
    <inertial>
      <origin rpy="0.0 0.0 0.0" xyz="0.0 0.0 0.0"/>
      <mass value="0.00001"/>
      <inertia ixx="1.0" ixy="0.0" ixz="0.0" iyy="1.0" iyz="0.0" izz="1.0"/>
    </inertial>
  </link>
  <!-- ****************************************************** Femur Joint **************************************************************  -->
  <joint name="femur_joint_LF" type="revolute">
    <origin rpy="-1.5707963267948966 1.5707963267948966 0.0" xyz="0.05893 0.0 0.0"/>
    <parent link="coxa_LF"/>
    <child link="femur_LF"/>
    <axis xyz="0.0 0.0 -1"/>
    <limit effort="6.0" lower="-3.14" upper="3.14" velocity="0.524"/>
  </joint>
  <!-- ****************************************************** Femur Transmission *******************************************************  -->
  <transmission name="femur_transmission_LF">
    <type>transmission_interface/SimpleTransmission</type>
    <joint name="femur_joint_LF">
      <hardwareInterface>EffortJointInterface</hardwareInterface>
    </joint>
    <actuator name="femur_motor_LF">
      <hardwareInterface>EffortJointInterface</hardwareInterface>
      <mechanicalReduction>1</mechanicalReduction>
    </actuator>
  </transmission>
  <!-- ****************************************************** Femur Link ***************************************************************  -->
  <link name="femur_LF">
    <visual>
      <origin rpy="0.0 0.0 0.0" xyz="0.0 0.0 0.0"/>
      <geometry>
        <mesh filename="package://robot_gazebo/meshes/golem/femur.stl" scale="0.001 0.001 0.001"/>
      </geometry>
      <material name="red"/>
    </visual>
    <collision>
      <origin rpy="0.0 0.0 0.0" xyz="0.0 0.0 0.0"/>
      <geometry>
        <mesh filename="package://robot_gazebo/meshes/golem/femur.stl" scale="0.001 0.001 0.001"/>
      </geometry>
      <material name="read"/>
    </collision>
    <inertial>
      <origin rpy="0.0 0.0 0.0" xyz="0.0 0.0 0.0"/>
      <mass value="0.00001"/>
      <inertia ixx="1.0" ixy="0.0" ixz="0.0" iyy="1.0" iyz="0.0" izz="1.0"/>
    </inertial>
  </link>
  <!-- ****************************************************** Tibia Joint **************************************************************  -->
  <joint name="tibia_joint_LF" type="revolute">
    <origin rpy="3.141592653589793 0.0 0.0" xyz="0.0 -0.10798 0.0"/>
    <parent link="femur_LF"/>
    <child link="tibia_LF"/>
    <axis xyz="0.0 0.0 -1"/>
    <limit effort="6.0" lower="-3.14" upper="3.14" velocity="0.524"/>
  </joint>
  <!-- ****************************************************** Tibia Transmission *******************************************************  -->
  <transmission name="tibia_transmission_LF">
    <type>transmission_interface/SimpleTransmission</type>
    <joint name="tibia_joint_LF">
      <hardwareInterface>EffortJointInterface</hardwareInterface>
    </joint>
    <actuator name="tibia_motor_LF">
      <hardwareInterface>EffortJointInterface</hardwareInterface>
      <mechanicalReduction>1</mechanicalReduction>
    </actuator>
  </transmission>
  <!-- ****************************************************** Tibia Link ***************************************************************  -->
  <link name="tibia_LF">
    <visual>
      <origin rpy="0.0 0.0 0.0" xyz="0.0 0.0 0.0"/>
      <geometry>
        <mesh filename="package://robot_gazebo/meshes/golem/tibia.stl" scale="0.001 0.001 0.001"/>
      </geometry>
      <material name="green"/>
    </visual>
    <collision>
      <origin rpy="0.0 0.0 0.0" xyz="0.0 0.0 0.0"/>
      <geometry>
        <mesh filename="package://robot_gazebo/meshes/golem/tibia.stl" scale="0.001 0.001 0.001"/>
      </geometry>
      <material name="green"/>
    </collision>
    <inertial>
      <origin rpy="0.0 0.0 0.0" xyz="0.0 0.0 0.0"/>
      <mass value="0.00001"/>
      <inertia ixx="1.0" ixy="0.0" ixz="0.0" iyy="1.0" iyz="0.0" izz="1.0"/>
    </inertial>
  </link>
  <!-- ****************************************************** Tarsus Joint *************************************************************  -->
  <joint name="tarsus_joint_LF" type="revolute">
    <origin rpy="0.0 0.0 0.0" xyz="0.08774 0.0 0.0"/>
    <parent link="tibia_LF"/>
    <child link="tarsus_LF"/>
    <axis xyz="0.0 0.0 -1"/>
    <limit effort="6.0" lower="-3.14" upper="3.14" velocity="0.524"/>
  </joint>
  <!-- ****************************************************** Tarsus Transmission ******************************************************  -->
  <transmission name="tarsus_transmission_LF">
    <type>transmission_interface/SimpleTransmission</type>
    <joint name="tarsus_joint_LF">
      <hardwareInterface>EffortJointInterface</hardwareInterface>
    </joint>
    <actuator name="tarsus_motor_LF">
      <hardwareInterface>EffortJointInterface</hardwareInterface>
      <mechanicalReduction>1</mechanicalReduction>
    </actuator>
  </transmission>
  <!-- ****************************************************** Tarsus Link **************************************************************  -->
  <link name="tarsus_LF">
    <visual>
      <origin rpy="0.0 0.0 0.0" xyz="0.0 0.0 0.0"/>
      <geometry>
        <mesh filename="package://robot_gazebo/meshes/golem/tarsus.stl" scale="0.001 0.001 0.001"/>
      </geometry>
      <material name="red"/>
    </visual>
    <collision>
      <origin rpy="0.0 0.0 0.0" xyz="0.0 0.0 0.0"/>
      <geometry>
        <mesh filename="package://robot_gazebo/meshes/golem/tarsus.stl" scale="0.001 0.001 0.001"/>
      </geometry>
      <material name="red"/>
    </collision>
    <inertial>
      <origin rpy="0.0 0.0 0.0" xyz="0.0 0.0 0.0"/>
      <mass value="0.00001"/>
      <inertia ixx="1.0" ixy="0.0" ixz="0.0" iyy="1.0" iyz="0.0" izz="1.0"/>
    </inertial>
  </link>
  <!-- ****************************************************** Foot Joint ***************************************************************  -->
  <joint name="foot_joint_LF" type="fixed">
    <origin rpy="0.0 0.0 0.0" xyz="0.12065 0.0 0.0"/>
    <parent link="tarsus_LF"/>
    <child link="foot_LF"/>
  </joint>
  <!-- ****************************************************** Foot Link ****************************************************************  -->
  <link name="foot_LF">
    <inertial>
      <origin rpy="0.0 0.0 0.0" xyz="0.0 0.0 0.0"/>
      <mass value="0.00001"/>
      <inertia ixx="1.0" ixy="0.0" ixz="0.0" iyy="1.0" iyz="0.0" izz="1.0"/>
    </inertial>
  </link>
  <!-- ******************************************************  End of Macro ************************************************************  -->
  <!-- ******************************************************  End *********************************************************************  -->
</robot>
