<?xml version="1.0" ?>
<!-- =================================================================================== -->
<!-- |    This document was autogenerated by xacro from src/bots/xacro/lbr_iiwa_14_r820.xacro | -->
<!-- |    EDITING THIS FILE BY HAND IS NOT RECOMMENDED                                 | -->
<!-- =================================================================================== -->
<robot name="lbr_iiwa_14_r820">
  <!-- ****************************************************** Properties**************************************************************** -->
  <!-- ****************************************************** Includes *****************************************************************  -->
  <!-- colours based on RAL values given in "FAQ - Colours of robot and robot
       controller", version "KUKA.Tifs | 2010-01-21 |YM| DefaultColorsRobotAndController.doc",
       downloaded 2015-07-18 from
       http://www.kuka.be/main/cservice/faqs/hardware/DefaultColorsRobotAndController.pdf

       all RAL colours converted using http://www.visual-graphics.de/en/customer-care/ral-colours
  -->
  <!-- ****************************************************** Macro ******************************************************************** -->
  <!-- ****************************************************** World Link *************************************************************** -->
  <link name="world"/>
  <gazebo reference="world">
    <static>true</static>
  </gazebo>
  <!-- ****************************************************** Generates a urdf from macro ********************************************** -->
  <!-- ****************************************************** LINKS ******************************************************************** -->
  <!-- ****************************************************** base link **************************************************************** -->
  <gazebo reference="base_link">
    <material>Gazebo/Gray</material>
  </gazebo>
  <!-- ****************************************************** link 1 (A1) ************************************************************** -->
  <gazebo reference="link_1">
    <material>Gazebo/Orange</material>
  </gazebo>
  <!-- ****************************************************** link 2 (A2) ************************************************************** -->
  <gazebo reference="link_2">
    <material>Gazebo/Orange</material>
  </gazebo>
  <!-- ****************************************************** link 3 (A3) ************************************************************** -->
  <gazebo reference="link_3">
    <material>Gazebo/Orange</material>
  </gazebo>
  <!-- ****************************************************** link 4 (A4) ************************************************************** -->
  <gazebo reference="link_4">
    <material>Gazebo/Orange</material>
  </gazebo>
  <!-- ****************************************************** link 5 (A5) ************************************************************** -->
  <gazebo reference="link_5">
    <material>Gazebo/Orange</material>
  </gazebo>
  <!-- ****************************************************** link 6 (A6) ************************************************************** -->
  <gazebo reference="link_6">
    <material>Gazebo/Orange</material>
  </gazebo>
  <!-- ****************************************************** link 7 (A7) ************************************************************** -->
  <gazebo reference="link_7">
    <material>Gazebo/Gray</material>
  </gazebo>
  <!-- ****************************************************** End Macro **************************************************************** -->
  <!-- ****************************************************** End ********************************************************************** -->
  <!-- Gazebo                                     -->
  <!-- ****************************************************** Macro ******************************************************************** -->
  <!-- ****************************************************** Generates a urdf from macro ********************************************** -->
  <!-- ****************************************************** LINKS ******************************************************************** -->
  <!-- ****************************************************** base link **************************************************************** -->
  <link name="base_link">
    <inertial>
      <origin rpy="0 0 0" xyz="0 0 0"/>
      <mass value="2"/>
      <inertia ixx="0.01" ixy="0" ixz="0" iyy="0.01" iyz="0" izz="0.01"/>
    </inertial>
    <visual>
      <origin rpy="0 0 0" xyz="0 0 0"/>
      <geometry>
        <mesh filename="package://bots/meshes/lbr_iiwa_14_r820/visual/base_link.dae"/>
      </geometry>
    </visual>
    <collision>
      <origin rpy="0 0 0" xyz="0 0 0"/>
      <geometry>
        <mesh filename="package://bots/meshes/lbr_iiwa_14_r820/collision/base_link.stl"/>
      </geometry>
    </collision>
  </link>
  <!-- ****************************************************** link 1 (A1) ************************************************************** -->
  <link name="link_1">
    <inertial>
      <origin rpy="0 0 0" xyz="0 0 0"/>
      <mass value="2"/>
      <inertia ixx="0.01" ixy="0" ixz="0" iyy="0.01" iyz="0" izz="0.01"/>
    </inertial>
    <visual>
      <origin rpy="0 0 0" xyz="0 0 0"/>
      <geometry>
        <mesh filename="package://bots/meshes/lbr_iiwa_14_r820/visual/link_1.dae"/>
      </geometry>
    </visual>
    <collision>
      <origin rpy="0 0 0" xyz="0 0 0"/>
      <geometry>
        <mesh filename="package://bots/meshes/lbr_iiwa_14_r820/collision/link_1.stl"/>
      </geometry>
    </collision>
  </link>
  <!-- ****************************************************** link 2 (A2) *********************************************************** -->
  <link name="link_2">
    <inertial>
      <origin rpy="0 0 0" xyz="0 0 0"/>
      <mass value="2"/>
      <inertia ixx="0.01" ixy="0" ixz="0" iyy="0.01" iyz="0" izz="0.01"/>
    </inertial>
    <visual>
      <origin rpy="0 0 0" xyz="0 0 0"/>
      <geometry>
        <mesh filename="package://bots/meshes/lbr_iiwa_14_r820/visual/link_2.dae"/>
      </geometry>
    </visual>
    <collision>
      <origin rpy="0 0 0" xyz="0 0 0"/>
      <geometry>
        <mesh filename="package://bots/meshes/lbr_iiwa_14_r820/collision/link_2.stl"/>
      </geometry>
    </collision>
  </link>
  <!-- ****************************************************** link 3 (A3) *********************************************************** -->
  <link name="link_3">
    <inertial>
      <origin rpy="0 0 0" xyz="0 0 0"/>
      <mass value="2"/>
      <inertia ixx="0.01" ixy="0" ixz="0" iyy="0.01" iyz="0" izz="0.01"/>
    </inertial>
    <visual>
      <origin rpy="0 0 0" xyz="0 0 0"/>
      <geometry>
        <mesh filename="package://bots/meshes/lbr_iiwa_14_r820/visual/link_3.dae"/>
      </geometry>
    </visual>
    <collision>
      <origin rpy="0 0 0" xyz="0 0 0"/>
      <geometry>
        <mesh filename="package://bots/meshes/lbr_iiwa_14_r820/collision/link_3.stl"/>
      </geometry>
    </collision>
  </link>
  <!-- ****************************************************** link 4 (A4) *********************************************************** -->
  <link name="link_4">
    <inertial>
      <origin rpy="0 0 0" xyz="0 0 0"/>
      <mass value="2"/>
      <inertia ixx="0.01" ixy="0" ixz="0" iyy="0.01" iyz="0" izz="0.01"/>
    </inertial>
    <visual>
      <origin rpy="0 0 0" xyz="0 0 0"/>
      <geometry>
        <mesh filename="package://bots/meshes/lbr_iiwa_14_r820/visual/link_4.dae"/>
      </geometry>
    </visual>
    <collision>
      <origin rpy="0 0 0" xyz="0 0 0"/>
      <geometry>
        <mesh filename="package://bots/meshes/lbr_iiwa_14_r820/collision/link_4.stl"/>
      </geometry>
    </collision>
  </link>
  <!-- ****************************************************** link 5 (A5) *********************************************************** -->
  <link name="link_5">
    <inertial>
      <origin rpy="0 0 0" xyz="0 0 0"/>
      <mass value="2"/>
      <inertia ixx="0.01" ixy="0" ixz="0" iyy="0.01" iyz="0" izz="0.01"/>
    </inertial>
    <visual>
      <origin rpy="0 0 0" xyz="0 0 0"/>
      <geometry>
        <mesh filename="package://bots/meshes/lbr_iiwa_14_r820/visual/link_5.dae"/>
      </geometry>
    </visual>
    <collision>
      <origin rpy="0 0 0" xyz="0 0 0"/>
      <geometry>
        <mesh filename="package://bots/meshes/lbr_iiwa_14_r820/collision/link_5.stl"/>
      </geometry>
    </collision>
  </link>
  <!-- ****************************************************** link 6 (A6) *********************************************************** -->
  <link name="link_6">
    <inertial>
      <origin rpy="0 0 0" xyz="0 0 0"/>
      <mass value="2"/>
      <inertia ixx="0.01" ixy="0" ixz="0" iyy="0.01" iyz="0" izz="0.01"/>
    </inertial>
    <visual>
      <origin rpy="0 0 0" xyz="0 0 0"/>
      <geometry>
        <mesh filename="package://bots/meshes/lbr_iiwa_14_r820/visual/link_6.dae"/>
      </geometry>
    </visual>
    <collision>
      <origin rpy="0 0 0" xyz="0 0 0"/>
      <geometry>
        <mesh filename="package://bots/meshes/lbr_iiwa_14_r820/collision/link_6.stl"/>
      </geometry>
    </collision>
  </link>
  <!-- ****************************************************** link 7 (A7) *********************************************************** -->
  <link name="link_7">
    <inertial>
      <origin rpy="0 0 0" xyz="0 0 0"/>
      <mass value="2"/>
      <inertia ixx="0.01" ixy="0" ixz="0" iyy="0.01" iyz="0" izz="0.01"/>
    </inertial>
    <visual>
      <origin rpy="0 0 0" xyz="0 0 0"/>
      <geometry>
        <mesh filename="package://bots/meshes/lbr_iiwa_14_r820/visual/link_7.dae"/>
      </geometry>
    </visual>
    <collision>
      <origin rpy="0 0 0" xyz="0 0 0"/>
      <geometry>
        <mesh filename="package://bots/meshes/lbr_iiwa_14_r820/collision/link_7.stl"/>
      </geometry>
    </collision>
  </link>
  <!-- ****************************************************** tool 0 ******************************************************************* -->
  <!-- ******************* Following REP199, this frame shall be use to attach EEF or other equipment ********************************** -->
  <link name="tool0"/>
  <!-- ****************************************************** END LINKS **************************************************************** -->
  <!-- ****************************************************** JOINTS ******************************************************************* -->
  <!-- ****************************************************** Base Joint *************************************************************** -->
  <joint name="base_joint" type="fixed">
    <origin rpy="0 0 0" xyz="0 0 0"/>
    <parent link="world"/>
    <child link="base_link"/>
  </joint>
  <!-- ****************************************************** joint 1 (A1) ************************************************************* -->
  <joint name="joint_a1" type="revolute">
    <origin rpy="0 0 0" xyz="0 0 0"/>
    <parent link="base_link"/>
    <child link="link_1"/>
    <axis xyz="0 0 1"/>
    <limit effort="0" lower="-2.9668" upper="2.9668" velocity="1.4834"/>
  </joint>
  <!-- ****************************************************** joint 2 (A2) **************************************************************** -->
  <joint name="joint_a2" type="revolute">
    <origin rpy="0 0 0" xyz="-0.00043624 0 0.36"/>
    <parent link="link_1"/>
    <child link="link_2"/>
    <axis xyz="0 1 0"/>
    <limit effort="0" lower="-2.0942" upper="2.0942" velocity="1.4834"/>
  </joint>
  <!-- ****************************************************** joint 3 (A3) **************************************************************** -->
  <joint name="joint_a3" type="revolute">
    <origin rpy="0 0 0" xyz="0 0 0"/>
    <parent link="link_2"/>
    <child link="link_3"/>
    <axis xyz="0 0 1"/>
    <limit effort="0" lower="-2.9668" upper="2.9668" velocity="1.7452"/>
  </joint>
  <!-- ****************************************************** joint 4 (A4) **************************************************************** -->
  <joint name="joint_a4" type="revolute">
    <origin rpy="0 0 0" xyz="0.00043624 0 0.42"/>
    <parent link="link_3"/>
    <child link="link_4"/>
    <axis xyz="0 -1 0"/>
    <limit effort="0" lower="-2.0942" upper="2.0942" velocity="1.3089"/>
  </joint>
  <!-- ****************************************************** joint 5 (A5) **************************************************************** -->
  <joint name="joint_a5" type="revolute">
    <origin rpy="0 0 0" xyz="0 0 0"/>
    <parent link="link_4"/>
    <child link="link_5"/>
    <axis xyz="0 0 1"/>
    <limit effort="0" lower="-2.9668" upper="2.9668" velocity="2.2688"/>
  </joint>
  <!-- ****************************************************** joint 6 (A6) **************************************************************** -->
  <joint name="joint_a6" type="revolute">
    <origin rpy="0 0 0" xyz="0 0 0.4"/>
    <parent link="link_5"/>
    <child link="link_6"/>
    <axis xyz="0 1 0"/>
    <limit effort="0" lower="-2.0942" upper="2.0942" velocity="2.356"/>
  </joint>
  <!-- ****************************************************** joint 7 (A7) **************************************************************** -->
  <joint name="joint_a7" type="revolute">
    <origin rpy="0 0 0" xyz="0 0 0"/>
    <parent link="link_6"/>
    <child link="link_7"/>
    <axis xyz="0 0 1"/>
    <limit effort="0" lower="-3.0541" upper="3.0541" velocity="2.356"/>
  </joint>
  <!-- ***************** This frame corresponds to the $TOOL coordinate system in KUKA KRC controllers ********************************* -->
  <joint name="joint_a7-tool0" type="fixed">
    <origin rpy="0 0 0" xyz="0 0 0.126"/>
    <parent link="link_7"/>
    <child link="tool0"/>
    <axis xyz="0 0 0"/>
  </joint>
  <!-- ****************************************************** END JOINTS *********************************************************** -->
  <!-- ****************************************************** ROS base_link to KUKA $ROBROOT coordinate system transform *********** -->
  <link name="base"/>
  <joint name="base_link-base" type="fixed">
    <origin rpy="0 0 0" xyz="0 0 0"/>
    <parent link="base_link"/>
    <child link="base"/>
  </joint>
  <!-- ****************************************************** End Macro **************************************************************** -->
  <!-- ****************************************************** End ********************************************************************** -->
</robot>
