<?xml version="1.0" ?>
<!-- =================================================================================== -->
<!-- |    This document was autogenerated by xacro from ../xacro/pxm3.xacro            | -->
<!-- |    EDITING THIS FILE BY HAND IS NOT RECOMMENDED                                 | -->
<!-- =================================================================================== -->
<robot name="pxm3">
  <!-- ****************************************************** Phantom X MKIII Robot ****************************************************  -->
  <!-- Muthanna Alwahash                                                                                                                  -->
  <!-- March 2022                                                                                                                         -->
  <!-- *********************************************************************************************************************************  -->
  <!-- ****************************************************** Parameters ***************************************************************  -->
  <!-- ****************************************************** Colors *******************************************************************  -->
  <material name="red">
    <color rgba="1.0 0.0 0.0 1.0"/>
  </material>
  <material name="green">
    <color rgba="0.0 1.0 0.0 1.0"/>
  </material>
  <material name="blue">
    <color rgba="0.0 0.0 1.0 1.0"/>
  </material>
  <material name="black">
    <color rgba="0.3 0.3 0.3 1.0"/>
  </material>
  <material name="white">
    <color rgba="1.0 1.0 1.0 1.0"/>
  </material>
  <!-- ****************************************************** Main Macro ***************************************************************  -->
  <!-- ****************************************************** Legs Macro ***************************************************************  -->
  <!-- ****************************************************** Base footprint ***********************************************************  -->
  <link name="base_footprint"/>
  <!-- ****************************************************** Main Macro ***************************************************************  -->
  <!-- ****************************************************** Attachment Joint *********************************************************  -->
  <joint name="j_base_base_footprint" type="fixed">
    <parent link="base_footprint"/>
    <child link="base_link"/>
    <origin rpy="0 0 0" xyz="0 0 0"/>
  </joint>
  <!-- ****************************************************** base_link Link *************************************************************  -->
  <link name="base_link">
    <inertial>
      <origin xyz="0 0 0"/>
      <mass value="0.97559947"/>
      <inertia ixx="3.1081800" ixy="-0.25460189" ixz="2.0318174" iyy="6.3787776" iyz="0.16417863" izz="5.3316425"/>
    </inertial>
    <visual>
      <!--origin xyz="-0.0235 0 -0.03525" rpy="0 0 0" /-->
      <origin rpy="0 0 0" xyz="0 0 0"/>
      <geometry>
        <!--box size="0.102 0.109 0.106" /-->
        <mesh filename="package://robot_gazebo/meshes/pxm3/body.STL" scale="1 1 1"/>
      </geometry>
      <material name="blue"/>
    </visual>
    <collision>
      <origin rpy="0 0 0" xyz="0 0 0"/>
      <geometry>
        <mesh filename="package://robot_gazebo/meshes/pxm3/body_coll.STL" scale="1 1 1"/>
      </geometry>
    </collision>
  </link>
  <!-- ****************************************************** Create Legs using Legs Macro **********************************************  -->
  <!-- ****************************************************** C1 Link ******************************************************************  -->
  <link name="c1_RF">
    <inertial>
      <origin rpy="0 0 0" xyz="0 -0.02633 0"/>
      <mass value="0.024357719"/>
      <inertia ixx="0.0051411124" ixy="-0.00057530255" ixz="-0.000024729049" iyy="0.0081915737" iyz="-0.000019223094" izz="0.0011379812"/>
    </inertial>
    <visual>
      <origin rpy="0 0 0" xyz="0 -0.0252 0"/>
      <geometry>
        <!--box size="0.045 0.022 0.0325" /-->
        <mesh filename="package://robot_gazebo/meshes/pxm3/connect.STL" scale="1 1 1"/>
      </geometry>
      <material name="red"/>
    </visual>
    <collision>
      <origin rpy="0 0 0" xyz="0 -0.02633 0"/>
      <geometry>
        <mesh filename="package://robot_gazebo/meshes/pxm3/connect_coll.STL" scale="1 1 1"/>
      </geometry>
    </collision>
  </link>
  <!-- ****************************************************** C2 Link ******************************************************************  -->
  <link name="c2_RF">
    <inertial>
      <origin rpy="0 0 0" xyz="0 -0.02633 0"/>
      <mass value="0.024357719"/>
      <inertia ixx="0.0051411124" ixy="-0.00057530255" ixz="-0.000024729049" iyy="0.0081915737" iyz="-0.000019223094" izz="0.0011379812"/>
    </inertial>
    <visual>
      <origin rpy="0 0 0" xyz="0 -0.0252 0"/>
      <geometry>
        <!--box size="0.045 0.022 0.0325" /-->
        <mesh filename="package://robot_gazebo/meshes/pxm3/connect.STL" scale="1 1 1"/>
      </geometry>
      <material name="green"/>
    </visual>
    <collision>
      <origin rpy="0 0 0" xyz="0 -0.02633 0"/>
      <geometry>
        <mesh filename="package://robot_gazebo/meshes/pxm3/connect_coll.STL" scale="1 1 1"/>
      </geometry>
    </collision>
  </link>
  <!-- ****************************************************** Thigh Link ***************************************************************  -->
  <link name="thigh_RF">
    <inertial>
      <origin rpy="0 0 0" xyz="0 0 0"/>
      <mass value="0.024357719"/>
      <inertia ixx="0.0051411124" ixy="-0.00057530255" ixz="-0.000024729049" iyy="0.0081915737" iyz="-0.000019223094" izz="0.0011379812"/>
    </inertial>
    <visual>
      <origin rpy="0 0 0" xyz="0 0 0"/>
      <geometry>
        <!--box size="0.045 0.022 0.0325" /-->
        <mesh filename="package://robot_gazebo/meshes/pxm3/thigh_l.STL" scale="1 1 1"/>
      </geometry>
      <material name="red"/>
    </visual>
    <collision>
      <origin rpy="0 0 0" xyz="0 0 0"/>
      <geometry>
        <mesh filename="package://robot_gazebo/meshes/pxm3/thigh_l_coll.STL" scale="1 1 1"/>
      </geometry>
    </collision>
  </link>
  <!-- ****************************************************** Tibia Link ***************************************************************  -->
  <link name="tibia_RF">
    <inertial>
      <origin rpy="0 0 0" xyz="0 0 0"/>
      <mass value="0.024357719"/>
      <inertia ixx="0.0051411124" ixy="-0.00057530255" ixz="-0.000024729049" iyy="0.0081915737" iyz="-0.000019223094" izz="0.0011379812"/>
    </inertial>
    <visual>
      <origin rpy="0 0 0" xyz="0 0 0"/>
      <geometry>
        <!--box size="0.045 0.022 0.0325" /-->
        <mesh filename="package://robot_gazebo/meshes/pxm3/tibia_l.STL" scale="1 1 1"/>
      </geometry>
      <material name="green"/>
    </visual>
    <collision>
      <origin rpy="0 0 0" xyz="0 0 0"/>
      <geometry>
        <mesh filename="package://robot_gazebo/meshes/pxm3/tibia_l_coll.STL" scale="1 1 1"/>
      </geometry>
    </collision>
  </link>
  <!-- ****************************************************** C1 Joint *****************************************************************  -->
  <joint name="j_c1_RF" type="revolute">
    <parent link="base_link"/>
    <child link="c1_RF"/>
    <origin rpy="0 4.7123 0.7853981633974483" xyz="0.1248    -0.06164  0.001116"/>
    <axis xyz="1 0 0"/>
    <limit effort="2.8" lower="-2.6179939" upper="2.6179939" velocity="5.6548668"/>
  </joint>
  <!-- ****************************************************** C2 Joint *****************************************************************  -->
  <joint name="j_c2_RF" type="fixed">
    <parent link="c1_RF"/>
    <child link="c2_RF"/>
    <origin rpy="0 1.5704 3.14159" xyz="0 -0.054 0"/>
  </joint>
  <!-- ****************************************************** Thigh Joint **************************************************************  -->
  <joint name="j_thigh_RF" type="revolute">
    <parent link="c2_RF"/>
    <child link="thigh_RF"/>
    <origin rpy=" 0 3.14159 3.14159" xyz="0 0 0"/>
    <axis xyz="1 0 0"/>
    <limit effort="2.8" lower="-2.6179939" upper="2.6179939" velocity="5.6548668"/>
  </joint>
  <!-- ****************************************************** Tibia Joint **************************************************************  -->
  <joint name="j_tibia_RF" type="revolute">
    <parent link="thigh_RF"/>
    <child link="tibia_RF"/>
    <origin rpy="-1.5707 0 3.14159" xyz="0 -0.0645 -0.0145"/>
    <axis xyz="1 0 0"/>
    <limit effort="2.8" lower="-2.6179939" upper="2.6179939" velocity="5.6548668"/>
  </joint>
  <!-- ****************************************************** C1 Transmission **********************************************************  -->
  <transmission name="t_c1_RF">
    <type>transmission_interface/SimpleTransmission</type>
    <joint name="j_c1_RF">
      <hardwareInterface>EffortJointInterface</hardwareInterface>
    </joint>
    <actuator name="m_c1_RF">
      <hardwareInterface>EffortJointInterface</hardwareInterface>
      <mechanicalReduction>1</mechanicalReduction>
    </actuator>
  </transmission>
  <!-- ****************************************************** Thigh Transmission *******************************************************  -->
  <transmission name="t_thigh_RF">
    <type>transmission_interface/SimpleTransmission</type>
    <joint name="j_thigh_RF">
      <hardwareInterface>EffortJointInterface</hardwareInterface>
    </joint>
    <actuator name="m_thigh_RF">
      <hardwareInterface>EffortJointInterface</hardwareInterface>
      <mechanicalReduction>1</mechanicalReduction>
    </actuator>
  </transmission>
  <!-- ****************************************************** Tibia Transmission *******************************************************  -->
  <transmission name="t_tibia_RF">
    <type>transmission_interface/SimpleTransmission</type>
    <joint name="j_tibia_RF">
      <hardwareInterface>EffortJointInterface</hardwareInterface>
    </joint>
    <actuator name="m_tibia_RF">
      <hardwareInterface>EffortJointInterface</hardwareInterface>
      <mechanicalReduction>1</mechanicalReduction>
    </actuator>
  </transmission>
  <!-- ****************************************************** end of Macro *************************************************************  -->
  <!-- ****************************************************** C1 Link ******************************************************************  -->
  <link name="c1_RM">
    <inertial>
      <origin rpy="0 0 0" xyz="0 -0.02633 0"/>
      <mass value="0.024357719"/>
      <inertia ixx="0.0051411124" ixy="-0.00057530255" ixz="-0.000024729049" iyy="0.0081915737" iyz="-0.000019223094" izz="0.0011379812"/>
    </inertial>
    <visual>
      <origin rpy="0 0 0" xyz="0 -0.0252 0"/>
      <geometry>
        <!--box size="0.045 0.022 0.0325" /-->
        <mesh filename="package://robot_gazebo/meshes/pxm3/connect.STL" scale="1 1 1"/>
      </geometry>
      <material name="red"/>
    </visual>
    <collision>
      <origin rpy="0 0 0" xyz="0 -0.02633 0"/>
      <geometry>
        <mesh filename="package://robot_gazebo/meshes/pxm3/connect_coll.STL" scale="1 1 1"/>
      </geometry>
    </collision>
  </link>
  <!-- ****************************************************** C2 Link ******************************************************************  -->
  <link name="c2_RM">
    <inertial>
      <origin rpy="0 0 0" xyz="0 -0.02633 0"/>
      <mass value="0.024357719"/>
      <inertia ixx="0.0051411124" ixy="-0.00057530255" ixz="-0.000024729049" iyy="0.0081915737" iyz="-0.000019223094" izz="0.0011379812"/>
    </inertial>
    <visual>
      <origin rpy="0 0 0" xyz="0 -0.0252 0"/>
      <geometry>
        <!--box size="0.045 0.022 0.0325" /-->
        <mesh filename="package://robot_gazebo/meshes/pxm3/connect.STL" scale="1 1 1"/>
      </geometry>
      <material name="green"/>
    </visual>
    <collision>
      <origin rpy="0 0 0" xyz="0 -0.02633 0"/>
      <geometry>
        <mesh filename="package://robot_gazebo/meshes/pxm3/connect_coll.STL" scale="1 1 1"/>
      </geometry>
    </collision>
  </link>
  <!-- ****************************************************** Thigh Link ***************************************************************  -->
  <link name="thigh_RM">
    <inertial>
      <origin rpy="0 0 0" xyz="0 0 0"/>
      <mass value="0.024357719"/>
      <inertia ixx="0.0051411124" ixy="-0.00057530255" ixz="-0.000024729049" iyy="0.0081915737" iyz="-0.000019223094" izz="0.0011379812"/>
    </inertial>
    <visual>
      <origin rpy="0 0 0" xyz="0 0 0"/>
      <geometry>
        <!--box size="0.045 0.022 0.0325" /-->
        <mesh filename="package://robot_gazebo/meshes/pxm3/thigh_l.STL" scale="1 1 1"/>
      </geometry>
      <material name="red"/>
    </visual>
    <collision>
      <origin rpy="0 0 0" xyz="0 0 0"/>
      <geometry>
        <mesh filename="package://robot_gazebo/meshes/pxm3/thigh_l_coll.STL" scale="1 1 1"/>
      </geometry>
    </collision>
  </link>
  <!-- ****************************************************** Tibia Link ***************************************************************  -->
  <link name="tibia_RM">
    <inertial>
      <origin rpy="0 0 0" xyz="0 0 0"/>
      <mass value="0.024357719"/>
      <inertia ixx="0.0051411124" ixy="-0.00057530255" ixz="-0.000024729049" iyy="0.0081915737" iyz="-0.000019223094" izz="0.0011379812"/>
    </inertial>
    <visual>
      <origin rpy="0 0 0" xyz="0 0 0"/>
      <geometry>
        <!--box size="0.045 0.022 0.0325" /-->
        <mesh filename="package://robot_gazebo/meshes/pxm3/tibia_l.STL" scale="1 1 1"/>
      </geometry>
      <material name="green"/>
    </visual>
    <collision>
      <origin rpy="0 0 0" xyz="0 0 0"/>
      <geometry>
        <mesh filename="package://robot_gazebo/meshes/pxm3/tibia_l_coll.STL" scale="1 1 1"/>
      </geometry>
    </collision>
  </link>
  <!-- ****************************************************** C1 Joint *****************************************************************  -->
  <joint name="j_c1_RM" type="revolute">
    <parent link="base_link"/>
    <child link="c1_RM"/>
    <origin rpy="0 4.7123 0" xyz="0         -0.1034   0.001116"/>
    <axis xyz="1 0 0"/>
    <limit effort="2.8" lower="-2.6179939" upper="2.6179939" velocity="5.6548668"/>
  </joint>
  <!-- ****************************************************** C2 Joint *****************************************************************  -->
  <joint name="j_c2_RM" type="fixed">
    <parent link="c1_RM"/>
    <child link="c2_RM"/>
    <origin rpy="0 1.5704 3.14159" xyz="0 -0.054 0"/>
  </joint>
  <!-- ****************************************************** Thigh Joint **************************************************************  -->
  <joint name="j_thigh_RM" type="revolute">
    <parent link="c2_RM"/>
    <child link="thigh_RM"/>
    <origin rpy=" 0 3.14159 3.14159" xyz="0 0 0"/>
    <axis xyz="1 0 0"/>
    <limit effort="2.8" lower="-2.6179939" upper="2.6179939" velocity="5.6548668"/>
  </joint>
  <!-- ****************************************************** Tibia Joint **************************************************************  -->
  <joint name="j_tibia_RM" type="revolute">
    <parent link="thigh_RM"/>
    <child link="tibia_RM"/>
    <origin rpy="-1.5707 0 3.14159" xyz="0 -0.0645 -0.0145"/>
    <axis xyz="1 0 0"/>
    <limit effort="2.8" lower="-2.6179939" upper="2.6179939" velocity="5.6548668"/>
  </joint>
  <!-- ****************************************************** C1 Transmission **********************************************************  -->
  <transmission name="t_c1_RM">
    <type>transmission_interface/SimpleTransmission</type>
    <joint name="j_c1_RM">
      <hardwareInterface>EffortJointInterface</hardwareInterface>
    </joint>
    <actuator name="m_c1_RM">
      <hardwareInterface>EffortJointInterface</hardwareInterface>
      <mechanicalReduction>1</mechanicalReduction>
    </actuator>
  </transmission>
  <!-- ****************************************************** Thigh Transmission *******************************************************  -->
  <transmission name="t_thigh_RM">
    <type>transmission_interface/SimpleTransmission</type>
    <joint name="j_thigh_RM">
      <hardwareInterface>EffortJointInterface</hardwareInterface>
    </joint>
    <actuator name="m_thigh_RM">
      <hardwareInterface>EffortJointInterface</hardwareInterface>
      <mechanicalReduction>1</mechanicalReduction>
    </actuator>
  </transmission>
  <!-- ****************************************************** Tibia Transmission *******************************************************  -->
  <transmission name="t_tibia_RM">
    <type>transmission_interface/SimpleTransmission</type>
    <joint name="j_tibia_RM">
      <hardwareInterface>EffortJointInterface</hardwareInterface>
    </joint>
    <actuator name="m_tibia_RM">
      <hardwareInterface>EffortJointInterface</hardwareInterface>
      <mechanicalReduction>1</mechanicalReduction>
    </actuator>
  </transmission>
  <!-- ****************************************************** end of Macro *************************************************************  -->
  <!-- ****************************************************** C1 Link ******************************************************************  -->
  <link name="c1_RR">
    <inertial>
      <origin rpy="0 0 0" xyz="0 -0.02633 0"/>
      <mass value="0.024357719"/>
      <inertia ixx="0.0051411124" ixy="-0.00057530255" ixz="-0.000024729049" iyy="0.0081915737" iyz="-0.000019223094" izz="0.0011379812"/>
    </inertial>
    <visual>
      <origin rpy="0 0 0" xyz="0 -0.0252 0"/>
      <geometry>
        <!--box size="0.045 0.022 0.0325" /-->
        <mesh filename="package://robot_gazebo/meshes/pxm3/connect.STL" scale="1 1 1"/>
      </geometry>
      <material name="red"/>
    </visual>
    <collision>
      <origin rpy="0 0 0" xyz="0 -0.02633 0"/>
      <geometry>
        <mesh filename="package://robot_gazebo/meshes/pxm3/connect_coll.STL" scale="1 1 1"/>
      </geometry>
    </collision>
  </link>
  <!-- ****************************************************** C2 Link ******************************************************************  -->
  <link name="c2_RR">
    <inertial>
      <origin rpy="0 0 0" xyz="0 -0.02633 0"/>
      <mass value="0.024357719"/>
      <inertia ixx="0.0051411124" ixy="-0.00057530255" ixz="-0.000024729049" iyy="0.0081915737" iyz="-0.000019223094" izz="0.0011379812"/>
    </inertial>
    <visual>
      <origin rpy="0 0 0" xyz="0 -0.0252 0"/>
      <geometry>
        <!--box size="0.045 0.022 0.0325" /-->
        <mesh filename="package://robot_gazebo/meshes/pxm3/connect.STL" scale="1 1 1"/>
      </geometry>
      <material name="green"/>
    </visual>
    <collision>
      <origin rpy="0 0 0" xyz="0 -0.02633 0"/>
      <geometry>
        <mesh filename="package://robot_gazebo/meshes/pxm3/connect_coll.STL" scale="1 1 1"/>
      </geometry>
    </collision>
  </link>
  <!-- ****************************************************** Thigh Link ***************************************************************  -->
  <link name="thigh_RR">
    <inertial>
      <origin rpy="0 0 0" xyz="0 0 0"/>
      <mass value="0.024357719"/>
      <inertia ixx="0.0051411124" ixy="-0.00057530255" ixz="-0.000024729049" iyy="0.0081915737" iyz="-0.000019223094" izz="0.0011379812"/>
    </inertial>
    <visual>
      <origin rpy="0 0 0" xyz="0 0 0"/>
      <geometry>
        <!--box size="0.045 0.022 0.0325" /-->
        <mesh filename="package://robot_gazebo/meshes/pxm3/thigh_l.STL" scale="1 1 1"/>
      </geometry>
      <material name="red"/>
    </visual>
    <collision>
      <origin rpy="0 0 0" xyz="0 0 0"/>
      <geometry>
        <mesh filename="package://robot_gazebo/meshes/pxm3/thigh_l_coll.STL" scale="1 1 1"/>
      </geometry>
    </collision>
  </link>
  <!-- ****************************************************** Tibia Link ***************************************************************  -->
  <link name="tibia_RR">
    <inertial>
      <origin rpy="0 0 0" xyz="0 0 0"/>
      <mass value="0.024357719"/>
      <inertia ixx="0.0051411124" ixy="-0.00057530255" ixz="-0.000024729049" iyy="0.0081915737" iyz="-0.000019223094" izz="0.0011379812"/>
    </inertial>
    <visual>
      <origin rpy="0 0 0" xyz="0 0 0"/>
      <geometry>
        <!--box size="0.045 0.022 0.0325" /-->
        <mesh filename="package://robot_gazebo/meshes/pxm3/tibia_l.STL" scale="1 1 1"/>
      </geometry>
      <material name="green"/>
    </visual>
    <collision>
      <origin rpy="0 0 0" xyz="0 0 0"/>
      <geometry>
        <mesh filename="package://robot_gazebo/meshes/pxm3/tibia_l_coll.STL" scale="1 1 1"/>
      </geometry>
    </collision>
  </link>
  <!-- ****************************************************** C1 Joint *****************************************************************  -->
  <joint name="j_c1_RR" type="revolute">
    <parent link="base_link"/>
    <child link="c1_RR"/>
    <origin rpy="0 4.7123 -0.7853981633974483" xyz="-0.1248   -0.06164  0.001116"/>
    <axis xyz="1 0 0"/>
    <limit effort="2.8" lower="-2.6179939" upper="2.6179939" velocity="5.6548668"/>
  </joint>
  <!-- ****************************************************** C2 Joint *****************************************************************  -->
  <joint name="j_c2_RR" type="fixed">
    <parent link="c1_RR"/>
    <child link="c2_RR"/>
    <origin rpy="0 1.5704 3.14159" xyz="0 -0.054 0"/>
  </joint>
  <!-- ****************************************************** Thigh Joint **************************************************************  -->
  <joint name="j_thigh_RR" type="revolute">
    <parent link="c2_RR"/>
    <child link="thigh_RR"/>
    <origin rpy=" 0 3.14159 3.14159" xyz="0 0 0"/>
    <axis xyz="1 0 0"/>
    <limit effort="2.8" lower="-2.6179939" upper="2.6179939" velocity="5.6548668"/>
  </joint>
  <!-- ****************************************************** Tibia Joint **************************************************************  -->
  <joint name="j_tibia_RR" type="revolute">
    <parent link="thigh_RR"/>
    <child link="tibia_RR"/>
    <origin rpy="-1.5707 0 3.14159" xyz="0 -0.0645 -0.0145"/>
    <axis xyz="1 0 0"/>
    <limit effort="2.8" lower="-2.6179939" upper="2.6179939" velocity="5.6548668"/>
  </joint>
  <!-- ****************************************************** C1 Transmission **********************************************************  -->
  <transmission name="t_c1_RR">
    <type>transmission_interface/SimpleTransmission</type>
    <joint name="j_c1_RR">
      <hardwareInterface>EffortJointInterface</hardwareInterface>
    </joint>
    <actuator name="m_c1_RR">
      <hardwareInterface>EffortJointInterface</hardwareInterface>
      <mechanicalReduction>1</mechanicalReduction>
    </actuator>
  </transmission>
  <!-- ****************************************************** Thigh Transmission *******************************************************  -->
  <transmission name="t_thigh_RR">
    <type>transmission_interface/SimpleTransmission</type>
    <joint name="j_thigh_RR">
      <hardwareInterface>EffortJointInterface</hardwareInterface>
    </joint>
    <actuator name="m_thigh_RR">
      <hardwareInterface>EffortJointInterface</hardwareInterface>
      <mechanicalReduction>1</mechanicalReduction>
    </actuator>
  </transmission>
  <!-- ****************************************************** Tibia Transmission *******************************************************  -->
  <transmission name="t_tibia_RR">
    <type>transmission_interface/SimpleTransmission</type>
    <joint name="j_tibia_RR">
      <hardwareInterface>EffortJointInterface</hardwareInterface>
    </joint>
    <actuator name="m_tibia_RR">
      <hardwareInterface>EffortJointInterface</hardwareInterface>
      <mechanicalReduction>1</mechanicalReduction>
    </actuator>
  </transmission>
  <!-- ****************************************************** end of Macro *************************************************************  -->
  <!-- ****************************************************** C1 Link ******************************************************************  -->
  <link name="c1_LF">
    <inertial>
      <origin rpy="0 0 0" xyz="0 -0.02633 0"/>
      <mass value="0.024357719"/>
      <inertia ixx="0.0051411124" ixy="-0.00057530255" ixz="-0.000024729049" iyy="0.0081915737" iyz="-0.000019223094" izz="0.0011379812"/>
    </inertial>
    <visual>
      <origin rpy="0 0 0" xyz="0 -0.0252 0"/>
      <geometry>
        <!--box size="0.045 0.022 0.0325" /-->
        <mesh filename="package://robot_gazebo/meshes/pxm3/connect.STL" scale="1 1 1"/>
      </geometry>
      <material name="red"/>
    </visual>
    <collision>
      <origin rpy="0 0 0" xyz="0 -0.02633 0"/>
      <geometry>
        <mesh filename="package://robot_gazebo/meshes/pxm3/connect_coll.STL" scale="1 1 1"/>
      </geometry>
    </collision>
  </link>
  <!-- ****************************************************** C2 Link ******************************************************************  -->
  <link name="c2_LF">
    <inertial>
      <origin rpy="0 0 0" xyz="0 -0.02633 0"/>
      <mass value="0.024357719"/>
      <inertia ixx="0.0051411124" ixy="-0.00057530255" ixz="-0.000024729049" iyy="0.0081915737" iyz="-0.000019223094" izz="0.0011379812"/>
    </inertial>
    <visual>
      <origin rpy="0 0 0" xyz="0 -0.0252 0"/>
      <geometry>
        <!--box size="0.045 0.022 0.0325" /-->
        <mesh filename="package://robot_gazebo/meshes/pxm3/connect.STL" scale="1 1 1"/>
      </geometry>
      <material name="green"/>
    </visual>
    <collision>
      <origin rpy="0 0 0" xyz="0 -0.02633 0"/>
      <geometry>
        <mesh filename="package://robot_gazebo/meshes/pxm3/connect_coll.STL" scale="1 1 1"/>
      </geometry>
    </collision>
  </link>
  <!-- ****************************************************** Thigh Link ***************************************************************  -->
  <link name="thigh_LF">
    <inertial>
      <origin rpy="0 0 0" xyz="0 0 0"/>
      <mass value="0.024357719"/>
      <inertia ixx="0.0051411124" ixy="-0.00057530255" ixz="-0.000024729049" iyy="0.0081915737" iyz="-0.000019223094" izz="0.0011379812"/>
    </inertial>
    <visual>
      <origin rpy="0 0 0" xyz="0 0 0"/>
      <geometry>
        <!--box size="0.045 0.022 0.0325" /-->
        <mesh filename="package://robot_gazebo/meshes/pxm3/thigh_l.STL" scale="1 1 1"/>
      </geometry>
      <material name="red"/>
    </visual>
    <collision>
      <origin rpy="0 0 0" xyz="0 0 0"/>
      <geometry>
        <mesh filename="package://robot_gazebo/meshes/pxm3/thigh_l_coll.STL" scale="1 1 1"/>
      </geometry>
    </collision>
  </link>
  <!-- ****************************************************** Tibia Link ***************************************************************  -->
  <link name="tibia_LF">
    <inertial>
      <origin rpy="0 0 0" xyz="0 0 0"/>
      <mass value="0.024357719"/>
      <inertia ixx="0.0051411124" ixy="-0.00057530255" ixz="-0.000024729049" iyy="0.0081915737" iyz="-0.000019223094" izz="0.0011379812"/>
    </inertial>
    <visual>
      <origin rpy="0 0 0" xyz="0 0 0"/>
      <geometry>
        <!--box size="0.045 0.022 0.0325" /-->
        <mesh filename="package://robot_gazebo/meshes/pxm3/tibia_l.STL" scale="1 1 1"/>
      </geometry>
      <material name="green"/>
    </visual>
    <collision>
      <origin rpy="0 0 0" xyz="0 0 0"/>
      <geometry>
        <mesh filename="package://robot_gazebo/meshes/pxm3/tibia_l_coll.STL" scale="1 1 1"/>
      </geometry>
    </collision>
  </link>
  <!-- ****************************************************** C1 Joint *****************************************************************  -->
  <joint name="j_c1_LF" type="revolute">
    <parent link="base_link"/>
    <child link="c1_LF"/>
    <origin rpy="0 4.7123 2.356194490192345" xyz="0.1248    0.06164   0.001116"/>
    <axis xyz="1 0 0"/>
    <limit effort="2.8" lower="-2.6179939" upper="2.6179939" velocity="5.6548668"/>
  </joint>
  <!-- ****************************************************** C2 Joint *****************************************************************  -->
  <joint name="j_c2_LF" type="fixed">
    <parent link="c1_LF"/>
    <child link="c2_LF"/>
    <origin rpy="0 1.5704 3.14159" xyz="0 -0.054 0"/>
  </joint>
  <!-- ****************************************************** Thigh Joint **************************************************************  -->
  <joint name="j_thigh_LF" type="revolute">
    <parent link="c2_LF"/>
    <child link="thigh_LF"/>
    <origin rpy=" 0 3.14159 3.14159" xyz="0 0 0"/>
    <axis xyz="1 0 0"/>
    <limit effort="2.8" lower="-2.6179939" upper="2.6179939" velocity="5.6548668"/>
  </joint>
  <!-- ****************************************************** Tibia Joint **************************************************************  -->
  <joint name="j_tibia_LF" type="revolute">
    <parent link="thigh_LF"/>
    <child link="tibia_LF"/>
    <origin rpy="-1.5707 0 3.14159" xyz="0 -0.0645 -0.0145"/>
    <axis xyz="1 0 0"/>
    <limit effort="2.8" lower="-2.6179939" upper="2.6179939" velocity="5.6548668"/>
  </joint>
  <!-- ****************************************************** C1 Transmission **********************************************************  -->
  <transmission name="t_c1_LF">
    <type>transmission_interface/SimpleTransmission</type>
    <joint name="j_c1_LF">
      <hardwareInterface>EffortJointInterface</hardwareInterface>
    </joint>
    <actuator name="m_c1_LF">
      <hardwareInterface>EffortJointInterface</hardwareInterface>
      <mechanicalReduction>1</mechanicalReduction>
    </actuator>
  </transmission>
  <!-- ****************************************************** Thigh Transmission *******************************************************  -->
  <transmission name="t_thigh_LF">
    <type>transmission_interface/SimpleTransmission</type>
    <joint name="j_thigh_LF">
      <hardwareInterface>EffortJointInterface</hardwareInterface>
    </joint>
    <actuator name="m_thigh_LF">
      <hardwareInterface>EffortJointInterface</hardwareInterface>
      <mechanicalReduction>1</mechanicalReduction>
    </actuator>
  </transmission>
  <!-- ****************************************************** Tibia Transmission *******************************************************  -->
  <transmission name="t_tibia_LF">
    <type>transmission_interface/SimpleTransmission</type>
    <joint name="j_tibia_LF">
      <hardwareInterface>EffortJointInterface</hardwareInterface>
    </joint>
    <actuator name="m_tibia_LF">
      <hardwareInterface>EffortJointInterface</hardwareInterface>
      <mechanicalReduction>1</mechanicalReduction>
    </actuator>
  </transmission>
  <!-- ****************************************************** end of Macro *************************************************************  -->
  <!-- ****************************************************** C1 Link ******************************************************************  -->
  <link name="c1_LM">
    <inertial>
      <origin rpy="0 0 0" xyz="0 -0.02633 0"/>
      <mass value="0.024357719"/>
      <inertia ixx="0.0051411124" ixy="-0.00057530255" ixz="-0.000024729049" iyy="0.0081915737" iyz="-0.000019223094" izz="0.0011379812"/>
    </inertial>
    <visual>
      <origin rpy="0 0 0" xyz="0 -0.0252 0"/>
      <geometry>
        <!--box size="0.045 0.022 0.0325" /-->
        <mesh filename="package://robot_gazebo/meshes/pxm3/connect.STL" scale="1 1 1"/>
      </geometry>
      <material name="red"/>
    </visual>
    <collision>
      <origin rpy="0 0 0" xyz="0 -0.02633 0"/>
      <geometry>
        <mesh filename="package://robot_gazebo/meshes/pxm3/connect_coll.STL" scale="1 1 1"/>
      </geometry>
    </collision>
  </link>
  <!-- ****************************************************** C2 Link ******************************************************************  -->
  <link name="c2_LM">
    <inertial>
      <origin rpy="0 0 0" xyz="0 -0.02633 0"/>
      <mass value="0.024357719"/>
      <inertia ixx="0.0051411124" ixy="-0.00057530255" ixz="-0.000024729049" iyy="0.0081915737" iyz="-0.000019223094" izz="0.0011379812"/>
    </inertial>
    <visual>
      <origin rpy="0 0 0" xyz="0 -0.0252 0"/>
      <geometry>
        <!--box size="0.045 0.022 0.0325" /-->
        <mesh filename="package://robot_gazebo/meshes/pxm3/connect.STL" scale="1 1 1"/>
      </geometry>
      <material name="green"/>
    </visual>
    <collision>
      <origin rpy="0 0 0" xyz="0 -0.02633 0"/>
      <geometry>
        <mesh filename="package://robot_gazebo/meshes/pxm3/connect_coll.STL" scale="1 1 1"/>
      </geometry>
    </collision>
  </link>
  <!-- ****************************************************** Thigh Link ***************************************************************  -->
  <link name="thigh_LM">
    <inertial>
      <origin rpy="0 0 0" xyz="0 0 0"/>
      <mass value="0.024357719"/>
      <inertia ixx="0.0051411124" ixy="-0.00057530255" ixz="-0.000024729049" iyy="0.0081915737" iyz="-0.000019223094" izz="0.0011379812"/>
    </inertial>
    <visual>
      <origin rpy="0 0 0" xyz="0 0 0"/>
      <geometry>
        <!--box size="0.045 0.022 0.0325" /-->
        <mesh filename="package://robot_gazebo/meshes/pxm3/thigh_l.STL" scale="1 1 1"/>
      </geometry>
      <material name="red"/>
    </visual>
    <collision>
      <origin rpy="0 0 0" xyz="0 0 0"/>
      <geometry>
        <mesh filename="package://robot_gazebo/meshes/pxm3/thigh_l_coll.STL" scale="1 1 1"/>
      </geometry>
    </collision>
  </link>
  <!-- ****************************************************** Tibia Link ***************************************************************  -->
  <link name="tibia_LM">
    <inertial>
      <origin rpy="0 0 0" xyz="0 0 0"/>
      <mass value="0.024357719"/>
      <inertia ixx="0.0051411124" ixy="-0.00057530255" ixz="-0.000024729049" iyy="0.0081915737" iyz="-0.000019223094" izz="0.0011379812"/>
    </inertial>
    <visual>
      <origin rpy="0 0 0" xyz="0 0 0"/>
      <geometry>
        <!--box size="0.045 0.022 0.0325" /-->
        <mesh filename="package://robot_gazebo/meshes/pxm3/tibia_l.STL" scale="1 1 1"/>
      </geometry>
      <material name="green"/>
    </visual>
    <collision>
      <origin rpy="0 0 0" xyz="0 0 0"/>
      <geometry>
        <mesh filename="package://robot_gazebo/meshes/pxm3/tibia_l_coll.STL" scale="1 1 1"/>
      </geometry>
    </collision>
  </link>
  <!-- ****************************************************** C1 Joint *****************************************************************  -->
  <joint name="j_c1_LM" type="revolute">
    <parent link="base_link"/>
    <child link="c1_LM"/>
    <origin rpy="0 4.7123 3.14159" xyz="0         0.1034    0.001116"/>
    <axis xyz="1 0 0"/>
    <limit effort="2.8" lower="-2.6179939" upper="2.6179939" velocity="5.6548668"/>
  </joint>
  <!-- ****************************************************** C2 Joint *****************************************************************  -->
  <joint name="j_c2_LM" type="fixed">
    <parent link="c1_LM"/>
    <child link="c2_LM"/>
    <origin rpy="0 1.5704 3.14159" xyz="0 -0.054 0"/>
  </joint>
  <!-- ****************************************************** Thigh Joint **************************************************************  -->
  <joint name="j_thigh_LM" type="revolute">
    <parent link="c2_LM"/>
    <child link="thigh_LM"/>
    <origin rpy=" 0 3.14159 3.14159" xyz="0 0 0"/>
    <axis xyz="1 0 0"/>
    <limit effort="2.8" lower="-2.6179939" upper="2.6179939" velocity="5.6548668"/>
  </joint>
  <!-- ****************************************************** Tibia Joint **************************************************************  -->
  <joint name="j_tibia_LM" type="revolute">
    <parent link="thigh_LM"/>
    <child link="tibia_LM"/>
    <origin rpy="-1.5707 0 3.14159" xyz="0 -0.0645 -0.0145"/>
    <axis xyz="1 0 0"/>
    <limit effort="2.8" lower="-2.6179939" upper="2.6179939" velocity="5.6548668"/>
  </joint>
  <!-- ****************************************************** C1 Transmission **********************************************************  -->
  <transmission name="t_c1_LM">
    <type>transmission_interface/SimpleTransmission</type>
    <joint name="j_c1_LM">
      <hardwareInterface>EffortJointInterface</hardwareInterface>
    </joint>
    <actuator name="m_c1_LM">
      <hardwareInterface>EffortJointInterface</hardwareInterface>
      <mechanicalReduction>1</mechanicalReduction>
    </actuator>
  </transmission>
  <!-- ****************************************************** Thigh Transmission *******************************************************  -->
  <transmission name="t_thigh_LM">
    <type>transmission_interface/SimpleTransmission</type>
    <joint name="j_thigh_LM">
      <hardwareInterface>EffortJointInterface</hardwareInterface>
    </joint>
    <actuator name="m_thigh_LM">
      <hardwareInterface>EffortJointInterface</hardwareInterface>
      <mechanicalReduction>1</mechanicalReduction>
    </actuator>
  </transmission>
  <!-- ****************************************************** Tibia Transmission *******************************************************  -->
  <transmission name="t_tibia_LM">
    <type>transmission_interface/SimpleTransmission</type>
    <joint name="j_tibia_LM">
      <hardwareInterface>EffortJointInterface</hardwareInterface>
    </joint>
    <actuator name="m_tibia_LM">
      <hardwareInterface>EffortJointInterface</hardwareInterface>
      <mechanicalReduction>1</mechanicalReduction>
    </actuator>
  </transmission>
  <!-- ****************************************************** end of Macro *************************************************************  -->
  <!-- ****************************************************** C1 Link ******************************************************************  -->
  <link name="c1_LR">
    <inertial>
      <origin rpy="0 0 0" xyz="0 -0.02633 0"/>
      <mass value="0.024357719"/>
      <inertia ixx="0.0051411124" ixy="-0.00057530255" ixz="-0.000024729049" iyy="0.0081915737" iyz="-0.000019223094" izz="0.0011379812"/>
    </inertial>
    <visual>
      <origin rpy="0 0 0" xyz="0 -0.0252 0"/>
      <geometry>
        <!--box size="0.045 0.022 0.0325" /-->
        <mesh filename="package://robot_gazebo/meshes/pxm3/connect.STL" scale="1 1 1"/>
      </geometry>
      <material name="red"/>
    </visual>
    <collision>
      <origin rpy="0 0 0" xyz="0 -0.02633 0"/>
      <geometry>
        <mesh filename="package://robot_gazebo/meshes/pxm3/connect_coll.STL" scale="1 1 1"/>
      </geometry>
    </collision>
  </link>
  <!-- ****************************************************** C2 Link ******************************************************************  -->
  <link name="c2_LR">
    <inertial>
      <origin rpy="0 0 0" xyz="0 -0.02633 0"/>
      <mass value="0.024357719"/>
      <inertia ixx="0.0051411124" ixy="-0.00057530255" ixz="-0.000024729049" iyy="0.0081915737" iyz="-0.000019223094" izz="0.0011379812"/>
    </inertial>
    <visual>
      <origin rpy="0 0 0" xyz="0 -0.0252 0"/>
      <geometry>
        <!--box size="0.045 0.022 0.0325" /-->
        <mesh filename="package://robot_gazebo/meshes/pxm3/connect.STL" scale="1 1 1"/>
      </geometry>
      <material name="green"/>
    </visual>
    <collision>
      <origin rpy="0 0 0" xyz="0 -0.02633 0"/>
      <geometry>
        <mesh filename="package://robot_gazebo/meshes/pxm3/connect_coll.STL" scale="1 1 1"/>
      </geometry>
    </collision>
  </link>
  <!-- ****************************************************** Thigh Link ***************************************************************  -->
  <link name="thigh_LR">
    <inertial>
      <origin rpy="0 0 0" xyz="0 0 0"/>
      <mass value="0.024357719"/>
      <inertia ixx="0.0051411124" ixy="-0.00057530255" ixz="-0.000024729049" iyy="0.0081915737" iyz="-0.000019223094" izz="0.0011379812"/>
    </inertial>
    <visual>
      <origin rpy="0 0 0" xyz="0 0 0"/>
      <geometry>
        <!--box size="0.045 0.022 0.0325" /-->
        <mesh filename="package://robot_gazebo/meshes/pxm3/thigh_l.STL" scale="1 1 1"/>
      </geometry>
      <material name="red"/>
    </visual>
    <collision>
      <origin rpy="0 0 0" xyz="0 0 0"/>
      <geometry>
        <mesh filename="package://robot_gazebo/meshes/pxm3/thigh_l_coll.STL" scale="1 1 1"/>
      </geometry>
    </collision>
  </link>
  <!-- ****************************************************** Tibia Link ***************************************************************  -->
  <link name="tibia_LR">
    <inertial>
      <origin rpy="0 0 0" xyz="0 0 0"/>
      <mass value="0.024357719"/>
      <inertia ixx="0.0051411124" ixy="-0.00057530255" ixz="-0.000024729049" iyy="0.0081915737" iyz="-0.000019223094" izz="0.0011379812"/>
    </inertial>
    <visual>
      <origin rpy="0 0 0" xyz="0 0 0"/>
      <geometry>
        <!--box size="0.045 0.022 0.0325" /-->
        <mesh filename="package://robot_gazebo/meshes/pxm3/tibia_l.STL" scale="1 1 1"/>
      </geometry>
      <material name="green"/>
    </visual>
    <collision>
      <origin rpy="0 0 0" xyz="0 0 0"/>
      <geometry>
        <mesh filename="package://robot_gazebo/meshes/pxm3/tibia_l_coll.STL" scale="1 1 1"/>
      </geometry>
    </collision>
  </link>
  <!-- ****************************************************** C1 Joint *****************************************************************  -->
  <joint name="j_c1_LR" type="revolute">
    <parent link="base_link"/>
    <child link="c1_LR"/>
    <origin rpy="0 4.7123 3.9269908169872414" xyz="-0.1248   0.06164   0.001116"/>
    <axis xyz="1 0 0"/>
    <limit effort="2.8" lower="-2.6179939" upper="2.6179939" velocity="5.6548668"/>
  </joint>
  <!-- ****************************************************** C2 Joint *****************************************************************  -->
  <joint name="j_c2_LR" type="fixed">
    <parent link="c1_LR"/>
    <child link="c2_LR"/>
    <origin rpy="0 1.5704 3.14159" xyz="0 -0.054 0"/>
  </joint>
  <!-- ****************************************************** Thigh Joint **************************************************************  -->
  <joint name="j_thigh_LR" type="revolute">
    <parent link="c2_LR"/>
    <child link="thigh_LR"/>
    <origin rpy=" 0 3.14159 3.14159" xyz="0 0 0"/>
    <axis xyz="1 0 0"/>
    <limit effort="2.8" lower="-2.6179939" upper="2.6179939" velocity="5.6548668"/>
  </joint>
  <!-- ****************************************************** Tibia Joint **************************************************************  -->
  <joint name="j_tibia_LR" type="revolute">
    <parent link="thigh_LR"/>
    <child link="tibia_LR"/>
    <origin rpy="-1.5707 0 3.14159" xyz="0 -0.0645 -0.0145"/>
    <axis xyz="1 0 0"/>
    <limit effort="2.8" lower="-2.6179939" upper="2.6179939" velocity="5.6548668"/>
  </joint>
  <!-- ****************************************************** C1 Transmission **********************************************************  -->
  <transmission name="t_c1_LR">
    <type>transmission_interface/SimpleTransmission</type>
    <joint name="j_c1_LR">
      <hardwareInterface>EffortJointInterface</hardwareInterface>
    </joint>
    <actuator name="m_c1_LR">
      <hardwareInterface>EffortJointInterface</hardwareInterface>
      <mechanicalReduction>1</mechanicalReduction>
    </actuator>
  </transmission>
  <!-- ****************************************************** Thigh Transmission *******************************************************  -->
  <transmission name="t_thigh_LR">
    <type>transmission_interface/SimpleTransmission</type>
    <joint name="j_thigh_LR">
      <hardwareInterface>EffortJointInterface</hardwareInterface>
    </joint>
    <actuator name="m_thigh_LR">
      <hardwareInterface>EffortJointInterface</hardwareInterface>
      <mechanicalReduction>1</mechanicalReduction>
    </actuator>
  </transmission>
  <!-- ****************************************************** Tibia Transmission *******************************************************  -->
  <transmission name="t_tibia_LR">
    <type>transmission_interface/SimpleTransmission</type>
    <joint name="j_tibia_LR">
      <hardwareInterface>EffortJointInterface</hardwareInterface>
    </joint>
    <actuator name="m_tibia_LR">
      <hardwareInterface>EffortJointInterface</hardwareInterface>
      <mechanicalReduction>1</mechanicalReduction>
    </actuator>
  </transmission>
  <!-- ****************************************************** end of Macro *************************************************************  -->
  <!-- Left Rear    -->
  <!-- ****************************************************** End of Main Macro ********************************************************  -->
  <!-- *********************************************************************************************************************************  -->
</robot>
