<?xml version="1.0" ?>
<!-- =================================================================================== -->
<!-- |    This document was autogenerated by xacro from src/robot_gazebo/xacro/razbot.xacro | -->
<!-- |    EDITING THIS FILE BY HAND IS NOT RECOMMENDED                                 | -->
<!-- =================================================================================== -->
<robot name="razbot">
  <!-- ****************************************************** Razbot Robot *************************************************************  -->
  <!-- Muthanna Alwahash                                                                                                                  -->
  <!-- March 2022                                                                                                                         -->
  <!-- Originally developed by Shubhankar Das a.k.a Razbotics                                                                             -->
  <!-- *********************************************************************************************************************************  -->
  <!-- ****************************************************** Parameters ***************************************************************  -->
  <!-- ****************************************************** Import RVIZ Materials*****************************************************  -->
  <material name="red">
    <color rgba="1.0 0.0 0.0 1.0"/>
  </material>
  <material name="green">
    <color rgba="0.0 1.0 0.0 1.0"/>
  </material>
  <material name="blue">
    <color rgba="0.0 0.0 1.0 1.0"/>
  </material>
  <material name="black">
    <color rgba="0.3 0.3 0.3 1.0"/>
  </material>
  <material name="white">
    <color rgba="1.0 1.0 1.0 1.0"/>
  </material>
  <material name="grey">
    <color rgba="0.2 0.2 0.2 1.0"/>
  </material>
  <material name="orange">
    <color rgba="1.0 0.4235294117647059 0.0392156862745098 1.0"/>
  </material>
  <material name="brown">
    <color rgba="0.8705882352941177 0.8117647058823529 0.7647058823529411 1.0"/>
  </material>
  <material name="yellow">
    <color rgba="1.0 1.0 0.0 1.0"/>
  </material>
  <!-- ****************************************************** Base Footprint ***********************************************************  -->
  <link name="base_footprint"/>
  <!-- ****************************************************** Base Joint ***************************************************************  -->
  <joint name="base_joint" type="fixed">
    <parent link="base_footprint"/>
    <child link="base_link"/>
    <origin rpy="0 0 0" xyz="0 0 0"/>
  </joint>
  <!-- ****************************************************** Base Link ****************************************************************  -->
  <link name="base_link">
    <visual>
      <origin rpy="0 0 0" xyz="0 0 0"/>
      <geometry>
        <mesh filename="package://robot_gazebo/meshes/razbot/body.stl" scale="0.001 0.001 0.001"/>
      </geometry>
      <material name="blue"/>
    </visual>
    <collision>
      <origin rpy="0 0 0" xyz="0 0 0"/>
      <geometry>
        <mesh filename="package://robot_gazebo/meshes/razbot/body.stl" scale="0.001 0.001 0.001"/>
      </geometry>
      <material name="blue"/>
    </collision>
    <inertial>
      <origin rpy="0 0 0" xyz="0 0 0"/>
      <mass value="0.00001"/>
      <inertia ixx="1.0" ixy="0.0" ixz="0.0" iyy="1.0" iyz="0.0" izz="1.0"/>
    </inertial>
  </link>
  <gazebo reference="base_link">
    <material>Gazebo/Blue</material>
  </gazebo>
  <!-- ****************************************************** IMU Joint ****************************************************************  -->
  <joint name="imu_joint" type="fixed">
    <parent link="base_link"/>
    <child link="imu_link"/>
    <origin rpy="0 0 0" xyz="0 0 0"/>
  </joint>
  <!-- ****************************************************** IMU Link *****************************************************************  -->
  <link name="imu_link">
    <inertial>
      <origin rpy="0 0 0" xyz="0 0 0"/>
      <mass value="0.00001"/>
      <inertia ixx="1.0" ixy="0.0" ixz="0.0" iyy="1.0" iyz="0.0" izz="1.0"/>
    </inertial>
  </link>
  <!-- ****************************************************** Leg Macro ****************************************************************  -->
  <!-- ****************************************************** Build Robot **************************************************************  -->
  <!-- ****************************************************** Leg Center Joint *********************************************************  -->
  <joint name="leg_center_joint_RR" type="fixed">
    <origin rpy="0 0 0" xyz="-0.147 -0.08475 0.0"/>
    <parent link="base_link"/>
    <child link="leg_center_RR"/>
  </joint>
  <!-- ****************************************************** Leg Center Link **********************************************************  -->
  <link name="leg_center_RR">
    <inertial>
      <origin rpy="0 0 0" xyz="0 0 0"/>
      <mass value="0.00001"/>
      <inertia ixx="1.0" ixy="0.0" ixz="0.0" iyy="1.0" iyz="0.0" izz="1.0"/>
    </inertial>
  </link>
  <!-- ****************************************************** Coxa Joint **************************************************************  -->
  <joint name="coxa_joint_RR" type="revolute">
    <origin rpy="0.0 0.0 -2.6179938779914944" xyz="0 0 0"/>
    <parent link="leg_center_RR"/>
    <child link="coxa_RR"/>
    <axis xyz="0.0 0.0 1.0"/>
    <limit effort="6.0" lower="-3.141592653589793" upper="3.141592653589793" velocity="5.235987755982989"/>
  </joint>
  <!-- ****************************************************** Coxa Link *****************************************************************  -->
  <link name="coxa_RR">
    <visual>
      <origin rpy="0 0 0" xyz="0 0 0"/>
      <geometry>
        <mesh filename="package://robot_gazebo/meshes/razbot/coxa.stl" scale="0.001 0.001 0.001"/>
      </geometry>
      <material name="green"/>
    </visual>
    <collision>
      <origin rpy="0 0 0" xyz="0 0 0"/>
      <geometry>
        <mesh filename="package://robot_gazebo/meshes/razbot/coxa.stl" scale="0.001 0.001 0.001"/>
      </geometry>
      <material name="green"/>
    </collision>
    <inertial>
      <origin rpy="0 0 0" xyz="0 0 0"/>
      <mass value="0.00001"/>
      <inertia ixx="1.0" ixy="0.0" ixz="0.0" iyy="1.0" iyz="0.0" izz="1.0"/>
    </inertial>
  </link>
  <gazebo reference="coxa_RR">
    <material>Gazebo/Red</material>
  </gazebo>
  <!-- ****************************************************** Coxa Transmission ********************************************************  -->
  <transmission name="coxa_transmission_RR">
    <type>transmission_interface/SimpleTransmission</type>
    <joint name="coxa_joint_RR">
      <hardwareInterface>EffortJointInterface</hardwareInterface>
    </joint>
    <actuator name="coxa_motor_RR">
      <hardwareInterface>EffortJointInterface</hardwareInterface>
      <mechanicalReduction>1</mechanicalReduction>
    </actuator>
  </transmission>
  <!-- ****************************************************** Femur Joint **************************************************************  -->
  <joint name="femur_joint_RR" type="revolute">
    <origin rpy="-1.5707963267948966 1.5707963267948966 0.0" xyz="0.052 0.0 0.0"/>
    <parent link="coxa_RR"/>
    <child link="femur_RR"/>
    <axis xyz="0.0 0.0 -1"/>
    <limit effort="6.0" lower="-3.141592653589793" upper="3.141592653589793" velocity="5.235987755982989"/>
  </joint>
  <!-- ****************************************************** Femur Link ***************************************************************  -->
  <link name="femur_RR">
    <visual>
      <origin rpy="0 0 0" xyz="0 0 0"/>
      <geometry>
        <mesh filename="package://robot_gazebo/meshes/razbot/femur.stl" scale="0.001 0.001 0.001"/>
      </geometry>
      <material name="red"/>
    </visual>
    <collision>
      <origin rpy="0 0 0" xyz="0 0 0"/>
      <geometry>
        <mesh filename="package://robot_gazebo/meshes/razbot/femur.stl" scale="0.001 0.001 0.001"/>
      </geometry>
      <material name="red"/>
    </collision>
    <inertial>
      <origin rpy="0 0 0" xyz="0 0 0"/>
      <mass value="0.00001"/>
      <inertia ixx="1.0" ixy="0.0" ixz="0.0" iyy="1.0" iyz="0.0" izz="1.0"/>
    </inertial>
  </link>
  <gazebo reference="femur_RR">
    <material>Gazebo/Green</material>
  </gazebo>
  <!-- ****************************************************** Femur Transmission *******************************************************  -->
  <transmission name="femur_transmission_RR">
    <type>transmission_interface/SimpleTransmission</type>
    <joint name="femur_joint_RR">
      <hardwareInterface>EffortJointInterface</hardwareInterface>
    </joint>
    <actuator name="femur_motor_RR">
      <hardwareInterface>EffortJointInterface</hardwareInterface>
      <mechanicalReduction>1</mechanicalReduction>
    </actuator>
  </transmission>
  <!-- ****************************************************** Tibia Joint *************************************************************  -->
  <joint name="tibia_joint_RR" type="revolute">
    <origin rpy="3.141592653589793 0 0" xyz="0.0 -0.065 0.0"/>
    <parent link="femur_RR"/>
    <child link="tibia_RR"/>
    <axis xyz="0.0 0.0 1"/>
    <limit effort="6.0" lower="-3.141592653589793" upper="3.141592653589793" velocity="5.235987755982989"/>
  </joint>
  <!-- ****************************************************** Tibia Link **************************************************************  -->
  <link name="tibia_RR">
    <visual>
      <origin rpy="0 0 0" xyz="0 0 0"/>
      <geometry>
        <mesh filename="package://robot_gazebo/meshes/razbot/tibia.stl" scale="0.001 0.001 0.001"/>
      </geometry>
      <material name="green"/>
    </visual>
    <collision>
      <origin rpy="0 0 0" xyz="0 0.0 0.0"/>
      <geometry>
        <mesh filename="package://robot_gazebo/meshes/razbot/tibia.stl" scale="0.001 0.001 0.001"/>
      </geometry>
      <material name="green"/>
    </collision>
    <inertial>
      <origin rpy="0 0 0" xyz="0 0.0 0.0"/>
      <mass value="0.00001"/>
      <inertia ixx="1.0" ixy="0.0" ixz="0.0" iyy="1.0" iyz="0.0" izz="1.0"/>
    </inertial>
  </link>
  <gazebo reference="tibia_RR">
    <material>Gazebo/Red</material>
  </gazebo>
  <!-- ****************************************************** Tibia Transmission *****************************************************  -->
  <transmission name="tibia_transmission_RR">
    <type>transmission_interface/SimpleTransmission</type>
    <joint name="tibia_joint_RR">
      <hardwareInterface>EffortJointInterface</hardwareInterface>
    </joint>
    <actuator name="tibia_motor_RR">
      <hardwareInterface>EffortJointInterface</hardwareInterface>
      <mechanicalReduction>1</mechanicalReduction>
    </actuator>
  </transmission>
  <!-- ****************************************************** end of Macro *************************************************************  -->
  <!-- ****************************************************** Leg Center Joint *********************************************************  -->
  <joint name="leg_center_joint_RM" type="fixed">
    <origin rpy="0 0 0" xyz="0.0 -0.17 0.0"/>
    <parent link="base_link"/>
    <child link="leg_center_RM"/>
  </joint>
  <!-- ****************************************************** Leg Center Link **********************************************************  -->
  <link name="leg_center_RM">
    <inertial>
      <origin rpy="0 0 0" xyz="0 0 0"/>
      <mass value="0.00001"/>
      <inertia ixx="1.0" ixy="0.0" ixz="0.0" iyy="1.0" iyz="0.0" izz="1.0"/>
    </inertial>
  </link>
  <!-- ****************************************************** Coxa Joint **************************************************************  -->
  <joint name="coxa_joint_RM" type="revolute">
    <origin rpy="0.0 0.0 -1.5707963267948966" xyz="0 0 0"/>
    <parent link="leg_center_RM"/>
    <child link="coxa_RM"/>
    <axis xyz="0.0 0.0 1.0"/>
    <limit effort="6.0" lower="-3.141592653589793" upper="3.141592653589793" velocity="5.235987755982989"/>
  </joint>
  <!-- ****************************************************** Coxa Link *****************************************************************  -->
  <link name="coxa_RM">
    <visual>
      <origin rpy="0 0 0" xyz="0 0 0"/>
      <geometry>
        <mesh filename="package://robot_gazebo/meshes/razbot/coxa.stl" scale="0.001 0.001 0.001"/>
      </geometry>
      <material name="green"/>
    </visual>
    <collision>
      <origin rpy="0 0 0" xyz="0 0 0"/>
      <geometry>
        <mesh filename="package://robot_gazebo/meshes/razbot/coxa.stl" scale="0.001 0.001 0.001"/>
      </geometry>
      <material name="green"/>
    </collision>
    <inertial>
      <origin rpy="0 0 0" xyz="0 0 0"/>
      <mass value="0.00001"/>
      <inertia ixx="1.0" ixy="0.0" ixz="0.0" iyy="1.0" iyz="0.0" izz="1.0"/>
    </inertial>
  </link>
  <gazebo reference="coxa_RM">
    <material>Gazebo/Red</material>
  </gazebo>
  <!-- ****************************************************** Coxa Transmission ********************************************************  -->
  <transmission name="coxa_transmission_RM">
    <type>transmission_interface/SimpleTransmission</type>
    <joint name="coxa_joint_RM">
      <hardwareInterface>EffortJointInterface</hardwareInterface>
    </joint>
    <actuator name="coxa_motor_RM">
      <hardwareInterface>EffortJointInterface</hardwareInterface>
      <mechanicalReduction>1</mechanicalReduction>
    </actuator>
  </transmission>
  <!-- ****************************************************** Femur Joint **************************************************************  -->
  <joint name="femur_joint_RM" type="revolute">
    <origin rpy="-1.5707963267948966 1.5707963267948966 0.0" xyz="0.052 0.0 0.0"/>
    <parent link="coxa_RM"/>
    <child link="femur_RM"/>
    <axis xyz="0.0 0.0 -1"/>
    <limit effort="6.0" lower="-3.141592653589793" upper="3.141592653589793" velocity="5.235987755982989"/>
  </joint>
  <!-- ****************************************************** Femur Link ***************************************************************  -->
  <link name="femur_RM">
    <visual>
      <origin rpy="0 0 0" xyz="0 0 0"/>
      <geometry>
        <mesh filename="package://robot_gazebo/meshes/razbot/femur.stl" scale="0.001 0.001 0.001"/>
      </geometry>
      <material name="red"/>
    </visual>
    <collision>
      <origin rpy="0 0 0" xyz="0 0 0"/>
      <geometry>
        <mesh filename="package://robot_gazebo/meshes/razbot/femur.stl" scale="0.001 0.001 0.001"/>
      </geometry>
      <material name="red"/>
    </collision>
    <inertial>
      <origin rpy="0 0 0" xyz="0 0 0"/>
      <mass value="0.00001"/>
      <inertia ixx="1.0" ixy="0.0" ixz="0.0" iyy="1.0" iyz="0.0" izz="1.0"/>
    </inertial>
  </link>
  <gazebo reference="femur_RM">
    <material>Gazebo/Green</material>
  </gazebo>
  <!-- ****************************************************** Femur Transmission *******************************************************  -->
  <transmission name="femur_transmission_RM">
    <type>transmission_interface/SimpleTransmission</type>
    <joint name="femur_joint_RM">
      <hardwareInterface>EffortJointInterface</hardwareInterface>
    </joint>
    <actuator name="femur_motor_RM">
      <hardwareInterface>EffortJointInterface</hardwareInterface>
      <mechanicalReduction>1</mechanicalReduction>
    </actuator>
  </transmission>
  <!-- ****************************************************** Tibia Joint *************************************************************  -->
  <joint name="tibia_joint_RM" type="revolute">
    <origin rpy="3.141592653589793 0 0" xyz="0.0 -0.065 0.0"/>
    <parent link="femur_RM"/>
    <child link="tibia_RM"/>
    <axis xyz="0.0 0.0 1"/>
    <limit effort="6.0" lower="-3.141592653589793" upper="3.141592653589793" velocity="5.235987755982989"/>
  </joint>
  <!-- ****************************************************** Tibia Link **************************************************************  -->
  <link name="tibia_RM">
    <visual>
      <origin rpy="0 0 0" xyz="0 0 0"/>
      <geometry>
        <mesh filename="package://robot_gazebo/meshes/razbot/tibia.stl" scale="0.001 0.001 0.001"/>
      </geometry>
      <material name="green"/>
    </visual>
    <collision>
      <origin rpy="0 0 0" xyz="0 0.0 0.0"/>
      <geometry>
        <mesh filename="package://robot_gazebo/meshes/razbot/tibia.stl" scale="0.001 0.001 0.001"/>
      </geometry>
      <material name="green"/>
    </collision>
    <inertial>
      <origin rpy="0 0 0" xyz="0 0.0 0.0"/>
      <mass value="0.00001"/>
      <inertia ixx="1.0" ixy="0.0" ixz="0.0" iyy="1.0" iyz="0.0" izz="1.0"/>
    </inertial>
  </link>
  <gazebo reference="tibia_RM">
    <material>Gazebo/Red</material>
  </gazebo>
  <!-- ****************************************************** Tibia Transmission *****************************************************  -->
  <transmission name="tibia_transmission_RM">
    <type>transmission_interface/SimpleTransmission</type>
    <joint name="tibia_joint_RM">
      <hardwareInterface>EffortJointInterface</hardwareInterface>
    </joint>
    <actuator name="tibia_motor_RM">
      <hardwareInterface>EffortJointInterface</hardwareInterface>
      <mechanicalReduction>1</mechanicalReduction>
    </actuator>
  </transmission>
  <!-- ****************************************************** end of Macro *************************************************************  -->
  <!-- ****************************************************** Leg Center Joint *********************************************************  -->
  <joint name="leg_center_joint_RF" type="fixed">
    <origin rpy="0 0 0" xyz="0.147 -0.08475 0.0"/>
    <parent link="base_link"/>
    <child link="leg_center_RF"/>
  </joint>
  <!-- ****************************************************** Leg Center Link **********************************************************  -->
  <link name="leg_center_RF">
    <inertial>
      <origin rpy="0 0 0" xyz="0 0 0"/>
      <mass value="0.00001"/>
      <inertia ixx="1.0" ixy="0.0" ixz="0.0" iyy="1.0" iyz="0.0" izz="1.0"/>
    </inertial>
  </link>
  <!-- ****************************************************** Coxa Joint **************************************************************  -->
  <joint name="coxa_joint_RF" type="revolute">
    <origin rpy="0.0 0.0 -0.5235987755982988" xyz="0 0 0"/>
    <parent link="leg_center_RF"/>
    <child link="coxa_RF"/>
    <axis xyz="0.0 0.0 1.0"/>
    <limit effort="6.0" lower="-3.141592653589793" upper="3.141592653589793" velocity="5.235987755982989"/>
  </joint>
  <!-- ****************************************************** Coxa Link *****************************************************************  -->
  <link name="coxa_RF">
    <visual>
      <origin rpy="0 0 0" xyz="0 0 0"/>
      <geometry>
        <mesh filename="package://robot_gazebo/meshes/razbot/coxa.stl" scale="0.001 0.001 0.001"/>
      </geometry>
      <material name="green"/>
    </visual>
    <collision>
      <origin rpy="0 0 0" xyz="0 0 0"/>
      <geometry>
        <mesh filename="package://robot_gazebo/meshes/razbot/coxa.stl" scale="0.001 0.001 0.001"/>
      </geometry>
      <material name="green"/>
    </collision>
    <inertial>
      <origin rpy="0 0 0" xyz="0 0 0"/>
      <mass value="0.00001"/>
      <inertia ixx="1.0" ixy="0.0" ixz="0.0" iyy="1.0" iyz="0.0" izz="1.0"/>
    </inertial>
  </link>
  <gazebo reference="coxa_RF">
    <material>Gazebo/Red</material>
  </gazebo>
  <!-- ****************************************************** Coxa Transmission ********************************************************  -->
  <transmission name="coxa_transmission_RF">
    <type>transmission_interface/SimpleTransmission</type>
    <joint name="coxa_joint_RF">
      <hardwareInterface>EffortJointInterface</hardwareInterface>
    </joint>
    <actuator name="coxa_motor_RF">
      <hardwareInterface>EffortJointInterface</hardwareInterface>
      <mechanicalReduction>1</mechanicalReduction>
    </actuator>
  </transmission>
  <!-- ****************************************************** Femur Joint **************************************************************  -->
  <joint name="femur_joint_RF" type="revolute">
    <origin rpy="-1.5707963267948966 1.5707963267948966 0.0" xyz="0.052 0.0 0.0"/>
    <parent link="coxa_RF"/>
    <child link="femur_RF"/>
    <axis xyz="0.0 0.0 -1"/>
    <limit effort="6.0" lower="-3.141592653589793" upper="3.141592653589793" velocity="5.235987755982989"/>
  </joint>
  <!-- ****************************************************** Femur Link ***************************************************************  -->
  <link name="femur_RF">
    <visual>
      <origin rpy="0 0 0" xyz="0 0 0"/>
      <geometry>
        <mesh filename="package://robot_gazebo/meshes/razbot/femur.stl" scale="0.001 0.001 0.001"/>
      </geometry>
      <material name="red"/>
    </visual>
    <collision>
      <origin rpy="0 0 0" xyz="0 0 0"/>
      <geometry>
        <mesh filename="package://robot_gazebo/meshes/razbot/femur.stl" scale="0.001 0.001 0.001"/>
      </geometry>
      <material name="red"/>
    </collision>
    <inertial>
      <origin rpy="0 0 0" xyz="0 0 0"/>
      <mass value="0.00001"/>
      <inertia ixx="1.0" ixy="0.0" ixz="0.0" iyy="1.0" iyz="0.0" izz="1.0"/>
    </inertial>
  </link>
  <gazebo reference="femur_RF">
    <material>Gazebo/Green</material>
  </gazebo>
  <!-- ****************************************************** Femur Transmission *******************************************************  -->
  <transmission name="femur_transmission_RF">
    <type>transmission_interface/SimpleTransmission</type>
    <joint name="femur_joint_RF">
      <hardwareInterface>EffortJointInterface</hardwareInterface>
    </joint>
    <actuator name="femur_motor_RF">
      <hardwareInterface>EffortJointInterface</hardwareInterface>
      <mechanicalReduction>1</mechanicalReduction>
    </actuator>
  </transmission>
  <!-- ****************************************************** Tibia Joint *************************************************************  -->
  <joint name="tibia_joint_RF" type="revolute">
    <origin rpy="3.141592653589793 0 0" xyz="0.0 -0.065 0.0"/>
    <parent link="femur_RF"/>
    <child link="tibia_RF"/>
    <axis xyz="0.0 0.0 1"/>
    <limit effort="6.0" lower="-3.141592653589793" upper="3.141592653589793" velocity="5.235987755982989"/>
  </joint>
  <!-- ****************************************************** Tibia Link **************************************************************  -->
  <link name="tibia_RF">
    <visual>
      <origin rpy="0 0 0" xyz="0 0 0"/>
      <geometry>
        <mesh filename="package://robot_gazebo/meshes/razbot/tibia.stl" scale="0.001 0.001 0.001"/>
      </geometry>
      <material name="green"/>
    </visual>
    <collision>
      <origin rpy="0 0 0" xyz="0 0.0 0.0"/>
      <geometry>
        <mesh filename="package://robot_gazebo/meshes/razbot/tibia.stl" scale="0.001 0.001 0.001"/>
      </geometry>
      <material name="green"/>
    </collision>
    <inertial>
      <origin rpy="0 0 0" xyz="0 0.0 0.0"/>
      <mass value="0.00001"/>
      <inertia ixx="1.0" ixy="0.0" ixz="0.0" iyy="1.0" iyz="0.0" izz="1.0"/>
    </inertial>
  </link>
  <gazebo reference="tibia_RF">
    <material>Gazebo/Red</material>
  </gazebo>
  <!-- ****************************************************** Tibia Transmission *****************************************************  -->
  <transmission name="tibia_transmission_RF">
    <type>transmission_interface/SimpleTransmission</type>
    <joint name="tibia_joint_RF">
      <hardwareInterface>EffortJointInterface</hardwareInterface>
    </joint>
    <actuator name="tibia_motor_RF">
      <hardwareInterface>EffortJointInterface</hardwareInterface>
      <mechanicalReduction>1</mechanicalReduction>
    </actuator>
  </transmission>
  <!-- ****************************************************** end of Macro *************************************************************  -->
  <!-- ****************************************************** Leg Center Joint *********************************************************  -->
  <joint name="leg_center_joint_LR" type="fixed">
    <origin rpy="0 0 0" xyz="-0.147 0.08475 0.0"/>
    <parent link="base_link"/>
    <child link="leg_center_LR"/>
  </joint>
  <!-- ****************************************************** Leg Center Link **********************************************************  -->
  <link name="leg_center_LR">
    <inertial>
      <origin rpy="0 0 0" xyz="0 0 0"/>
      <mass value="0.00001"/>
      <inertia ixx="1.0" ixy="0.0" ixz="0.0" iyy="1.0" iyz="0.0" izz="1.0"/>
    </inertial>
  </link>
  <!-- ****************************************************** Coxa Joint **************************************************************  -->
  <joint name="coxa_joint_LR" type="revolute">
    <origin rpy="0.0 0.0 2.6179938779914944" xyz="0 0 0"/>
    <parent link="leg_center_LR"/>
    <child link="coxa_LR"/>
    <axis xyz="0.0 0.0 1.0"/>
    <limit effort="6.0" lower="-3.141592653589793" upper="3.141592653589793" velocity="5.235987755982989"/>
  </joint>
  <!-- ****************************************************** Coxa Link *****************************************************************  -->
  <link name="coxa_LR">
    <visual>
      <origin rpy="0 0 0" xyz="0 0 0"/>
      <geometry>
        <mesh filename="package://robot_gazebo/meshes/razbot/coxa.stl" scale="0.001 0.001 0.001"/>
      </geometry>
      <material name="green"/>
    </visual>
    <collision>
      <origin rpy="0 0 0" xyz="0 0 0"/>
      <geometry>
        <mesh filename="package://robot_gazebo/meshes/razbot/coxa.stl" scale="0.001 0.001 0.001"/>
      </geometry>
      <material name="green"/>
    </collision>
    <inertial>
      <origin rpy="0 0 0" xyz="0 0 0"/>
      <mass value="0.00001"/>
      <inertia ixx="1.0" ixy="0.0" ixz="0.0" iyy="1.0" iyz="0.0" izz="1.0"/>
    </inertial>
  </link>
  <gazebo reference="coxa_LR">
    <material>Gazebo/Red</material>
  </gazebo>
  <!-- ****************************************************** Coxa Transmission ********************************************************  -->
  <transmission name="coxa_transmission_LR">
    <type>transmission_interface/SimpleTransmission</type>
    <joint name="coxa_joint_LR">
      <hardwareInterface>EffortJointInterface</hardwareInterface>
    </joint>
    <actuator name="coxa_motor_LR">
      <hardwareInterface>EffortJointInterface</hardwareInterface>
      <mechanicalReduction>1</mechanicalReduction>
    </actuator>
  </transmission>
  <!-- ****************************************************** Femur Joint **************************************************************  -->
  <joint name="femur_joint_LR" type="revolute">
    <origin rpy="-1.5707963267948966 1.5707963267948966 0.0" xyz="0.052 0.0 0.0"/>
    <parent link="coxa_LR"/>
    <child link="femur_LR"/>
    <axis xyz="0.0 0.0 1"/>
    <limit effort="6.0" lower="-3.141592653589793" upper="3.141592653589793" velocity="5.235987755982989"/>
  </joint>
  <!-- ****************************************************** Femur Link ***************************************************************  -->
  <link name="femur_LR">
    <visual>
      <origin rpy="0 0 0" xyz="0 0 0"/>
      <geometry>
        <mesh filename="package://robot_gazebo/meshes/razbot/femur.stl" scale="0.001 0.001 0.001"/>
      </geometry>
      <material name="red"/>
    </visual>
    <collision>
      <origin rpy="0 0 0" xyz="0 0 0"/>
      <geometry>
        <mesh filename="package://robot_gazebo/meshes/razbot/femur.stl" scale="0.001 0.001 0.001"/>
      </geometry>
      <material name="red"/>
    </collision>
    <inertial>
      <origin rpy="0 0 0" xyz="0 0 0"/>
      <mass value="0.00001"/>
      <inertia ixx="1.0" ixy="0.0" ixz="0.0" iyy="1.0" iyz="0.0" izz="1.0"/>
    </inertial>
  </link>
  <gazebo reference="femur_LR">
    <material>Gazebo/Green</material>
  </gazebo>
  <!-- ****************************************************** Femur Transmission *******************************************************  -->
  <transmission name="femur_transmission_LR">
    <type>transmission_interface/SimpleTransmission</type>
    <joint name="femur_joint_LR">
      <hardwareInterface>EffortJointInterface</hardwareInterface>
    </joint>
    <actuator name="femur_motor_LR">
      <hardwareInterface>EffortJointInterface</hardwareInterface>
      <mechanicalReduction>1</mechanicalReduction>
    </actuator>
  </transmission>
  <!-- ****************************************************** Tibia Joint *************************************************************  -->
  <joint name="tibia_joint_LR" type="revolute">
    <origin rpy="3.141592653589793 0 0" xyz="0.0 -0.065 0.0"/>
    <parent link="femur_LR"/>
    <child link="tibia_LR"/>
    <axis xyz="0.0 0.0 -1"/>
    <limit effort="6.0" lower="-3.141592653589793" upper="3.141592653589793" velocity="5.235987755982989"/>
  </joint>
  <!-- ****************************************************** Tibia Link **************************************************************  -->
  <link name="tibia_LR">
    <visual>
      <origin rpy="0 0 0" xyz="0 0 0"/>
      <geometry>
        <mesh filename="package://robot_gazebo/meshes/razbot/tibia.stl" scale="0.001 0.001 0.001"/>
      </geometry>
      <material name="green"/>
    </visual>
    <collision>
      <origin rpy="0 0 0" xyz="0 0.0 0.0"/>
      <geometry>
        <mesh filename="package://robot_gazebo/meshes/razbot/tibia.stl" scale="0.001 0.001 0.001"/>
      </geometry>
      <material name="green"/>
    </collision>
    <inertial>
      <origin rpy="0 0 0" xyz="0 0.0 0.0"/>
      <mass value="0.00001"/>
      <inertia ixx="1.0" ixy="0.0" ixz="0.0" iyy="1.0" iyz="0.0" izz="1.0"/>
    </inertial>
  </link>
  <gazebo reference="tibia_LR">
    <material>Gazebo/Red</material>
  </gazebo>
  <!-- ****************************************************** Tibia Transmission *****************************************************  -->
  <transmission name="tibia_transmission_LR">
    <type>transmission_interface/SimpleTransmission</type>
    <joint name="tibia_joint_LR">
      <hardwareInterface>EffortJointInterface</hardwareInterface>
    </joint>
    <actuator name="tibia_motor_LR">
      <hardwareInterface>EffortJointInterface</hardwareInterface>
      <mechanicalReduction>1</mechanicalReduction>
    </actuator>
  </transmission>
  <!-- ****************************************************** end of Macro *************************************************************  -->
  <!-- ****************************************************** Leg Center Joint *********************************************************  -->
  <joint name="leg_center_joint_LM" type="fixed">
    <origin rpy="0 0 0" xyz="0.0 0.17 0.0"/>
    <parent link="base_link"/>
    <child link="leg_center_LM"/>
  </joint>
  <!-- ****************************************************** Leg Center Link **********************************************************  -->
  <link name="leg_center_LM">
    <inertial>
      <origin rpy="0 0 0" xyz="0 0 0"/>
      <mass value="0.00001"/>
      <inertia ixx="1.0" ixy="0.0" ixz="0.0" iyy="1.0" iyz="0.0" izz="1.0"/>
    </inertial>
  </link>
  <!-- ****************************************************** Coxa Joint **************************************************************  -->
  <joint name="coxa_joint_LM" type="revolute">
    <origin rpy="0.0 0.0 1.5707963267948966" xyz="0 0 0"/>
    <parent link="leg_center_LM"/>
    <child link="coxa_LM"/>
    <axis xyz="0.0 0.0 1.0"/>
    <limit effort="6.0" lower="-3.141592653589793" upper="3.141592653589793" velocity="5.235987755982989"/>
  </joint>
  <!-- ****************************************************** Coxa Link *****************************************************************  -->
  <link name="coxa_LM">
    <visual>
      <origin rpy="0 0 0" xyz="0 0 0"/>
      <geometry>
        <mesh filename="package://robot_gazebo/meshes/razbot/coxa.stl" scale="0.001 0.001 0.001"/>
      </geometry>
      <material name="green"/>
    </visual>
    <collision>
      <origin rpy="0 0 0" xyz="0 0 0"/>
      <geometry>
        <mesh filename="package://robot_gazebo/meshes/razbot/coxa.stl" scale="0.001 0.001 0.001"/>
      </geometry>
      <material name="green"/>
    </collision>
    <inertial>
      <origin rpy="0 0 0" xyz="0 0 0"/>
      <mass value="0.00001"/>
      <inertia ixx="1.0" ixy="0.0" ixz="0.0" iyy="1.0" iyz="0.0" izz="1.0"/>
    </inertial>
  </link>
  <gazebo reference="coxa_LM">
    <material>Gazebo/Red</material>
  </gazebo>
  <!-- ****************************************************** Coxa Transmission ********************************************************  -->
  <transmission name="coxa_transmission_LM">
    <type>transmission_interface/SimpleTransmission</type>
    <joint name="coxa_joint_LM">
      <hardwareInterface>EffortJointInterface</hardwareInterface>
    </joint>
    <actuator name="coxa_motor_LM">
      <hardwareInterface>EffortJointInterface</hardwareInterface>
      <mechanicalReduction>1</mechanicalReduction>
    </actuator>
  </transmission>
  <!-- ****************************************************** Femur Joint **************************************************************  -->
  <joint name="femur_joint_LM" type="revolute">
    <origin rpy="-1.5707963267948966 1.5707963267948966 0.0" xyz="0.052 0.0 0.0"/>
    <parent link="coxa_LM"/>
    <child link="femur_LM"/>
    <axis xyz="0.0 0.0 1"/>
    <limit effort="6.0" lower="-3.141592653589793" upper="3.141592653589793" velocity="5.235987755982989"/>
  </joint>
  <!-- ****************************************************** Femur Link ***************************************************************  -->
  <link name="femur_LM">
    <visual>
      <origin rpy="0 0 0" xyz="0 0 0"/>
      <geometry>
        <mesh filename="package://robot_gazebo/meshes/razbot/femur.stl" scale="0.001 0.001 0.001"/>
      </geometry>
      <material name="red"/>
    </visual>
    <collision>
      <origin rpy="0 0 0" xyz="0 0 0"/>
      <geometry>
        <mesh filename="package://robot_gazebo/meshes/razbot/femur.stl" scale="0.001 0.001 0.001"/>
      </geometry>
      <material name="red"/>
    </collision>
    <inertial>
      <origin rpy="0 0 0" xyz="0 0 0"/>
      <mass value="0.00001"/>
      <inertia ixx="1.0" ixy="0.0" ixz="0.0" iyy="1.0" iyz="0.0" izz="1.0"/>
    </inertial>
  </link>
  <gazebo reference="femur_LM">
    <material>Gazebo/Green</material>
  </gazebo>
  <!-- ****************************************************** Femur Transmission *******************************************************  -->
  <transmission name="femur_transmission_LM">
    <type>transmission_interface/SimpleTransmission</type>
    <joint name="femur_joint_LM">
      <hardwareInterface>EffortJointInterface</hardwareInterface>
    </joint>
    <actuator name="femur_motor_LM">
      <hardwareInterface>EffortJointInterface</hardwareInterface>
      <mechanicalReduction>1</mechanicalReduction>
    </actuator>
  </transmission>
  <!-- ****************************************************** Tibia Joint *************************************************************  -->
  <joint name="tibia_joint_LM" type="revolute">
    <origin rpy="3.141592653589793 0 0" xyz="0.0 -0.065 0.0"/>
    <parent link="femur_LM"/>
    <child link="tibia_LM"/>
    <axis xyz="0.0 0.0 -1"/>
    <limit effort="6.0" lower="-3.141592653589793" upper="3.141592653589793" velocity="5.235987755982989"/>
  </joint>
  <!-- ****************************************************** Tibia Link **************************************************************  -->
  <link name="tibia_LM">
    <visual>
      <origin rpy="0 0 0" xyz="0 0 0"/>
      <geometry>
        <mesh filename="package://robot_gazebo/meshes/razbot/tibia.stl" scale="0.001 0.001 0.001"/>
      </geometry>
      <material name="green"/>
    </visual>
    <collision>
      <origin rpy="0 0 0" xyz="0 0.0 0.0"/>
      <geometry>
        <mesh filename="package://robot_gazebo/meshes/razbot/tibia.stl" scale="0.001 0.001 0.001"/>
      </geometry>
      <material name="green"/>
    </collision>
    <inertial>
      <origin rpy="0 0 0" xyz="0 0.0 0.0"/>
      <mass value="0.00001"/>
      <inertia ixx="1.0" ixy="0.0" ixz="0.0" iyy="1.0" iyz="0.0" izz="1.0"/>
    </inertial>
  </link>
  <gazebo reference="tibia_LM">
    <material>Gazebo/Red</material>
  </gazebo>
  <!-- ****************************************************** Tibia Transmission *****************************************************  -->
  <transmission name="tibia_transmission_LM">
    <type>transmission_interface/SimpleTransmission</type>
    <joint name="tibia_joint_LM">
      <hardwareInterface>EffortJointInterface</hardwareInterface>
    </joint>
    <actuator name="tibia_motor_LM">
      <hardwareInterface>EffortJointInterface</hardwareInterface>
      <mechanicalReduction>1</mechanicalReduction>
    </actuator>
  </transmission>
  <!-- ****************************************************** end of Macro *************************************************************  -->
  <!-- ****************************************************** Leg Center Joint *********************************************************  -->
  <joint name="leg_center_joint_LF" type="fixed">
    <origin rpy="0 0 0" xyz="0.147 0.08475 0.0"/>
    <parent link="base_link"/>
    <child link="leg_center_LF"/>
  </joint>
  <!-- ****************************************************** Leg Center Link **********************************************************  -->
  <link name="leg_center_LF">
    <inertial>
      <origin rpy="0 0 0" xyz="0 0 0"/>
      <mass value="0.00001"/>
      <inertia ixx="1.0" ixy="0.0" ixz="0.0" iyy="1.0" iyz="0.0" izz="1.0"/>
    </inertial>
  </link>
  <!-- ****************************************************** Coxa Joint **************************************************************  -->
  <joint name="coxa_joint_LF" type="revolute">
    <origin rpy="0.0 0.0 0.5235987755982988" xyz="0 0 0"/>
    <parent link="leg_center_LF"/>
    <child link="coxa_LF"/>
    <axis xyz="0.0 0.0 1.0"/>
    <limit effort="6.0" lower="-3.141592653589793" upper="3.141592653589793" velocity="5.235987755982989"/>
  </joint>
  <!-- ****************************************************** Coxa Link *****************************************************************  -->
  <link name="coxa_LF">
    <visual>
      <origin rpy="0 0 0" xyz="0 0 0"/>
      <geometry>
        <mesh filename="package://robot_gazebo/meshes/razbot/coxa.stl" scale="0.001 0.001 0.001"/>
      </geometry>
      <material name="green"/>
    </visual>
    <collision>
      <origin rpy="0 0 0" xyz="0 0 0"/>
      <geometry>
        <mesh filename="package://robot_gazebo/meshes/razbot/coxa.stl" scale="0.001 0.001 0.001"/>
      </geometry>
      <material name="green"/>
    </collision>
    <inertial>
      <origin rpy="0 0 0" xyz="0 0 0"/>
      <mass value="0.00001"/>
      <inertia ixx="1.0" ixy="0.0" ixz="0.0" iyy="1.0" iyz="0.0" izz="1.0"/>
    </inertial>
  </link>
  <gazebo reference="coxa_LF">
    <material>Gazebo/Red</material>
  </gazebo>
  <!-- ****************************************************** Coxa Transmission ********************************************************  -->
  <transmission name="coxa_transmission_LF">
    <type>transmission_interface/SimpleTransmission</type>
    <joint name="coxa_joint_LF">
      <hardwareInterface>EffortJointInterface</hardwareInterface>
    </joint>
    <actuator name="coxa_motor_LF">
      <hardwareInterface>EffortJointInterface</hardwareInterface>
      <mechanicalReduction>1</mechanicalReduction>
    </actuator>
  </transmission>
  <!-- ****************************************************** Femur Joint **************************************************************  -->
  <joint name="femur_joint_LF" type="revolute">
    <origin rpy="-1.5707963267948966 1.5707963267948966 0.0" xyz="0.052 0.0 0.0"/>
    <parent link="coxa_LF"/>
    <child link="femur_LF"/>
    <axis xyz="0.0 0.0 1"/>
    <limit effort="6.0" lower="-3.141592653589793" upper="3.141592653589793" velocity="5.235987755982989"/>
  </joint>
  <!-- ****************************************************** Femur Link ***************************************************************  -->
  <link name="femur_LF">
    <visual>
      <origin rpy="0 0 0" xyz="0 0 0"/>
      <geometry>
        <mesh filename="package://robot_gazebo/meshes/razbot/femur.stl" scale="0.001 0.001 0.001"/>
      </geometry>
      <material name="red"/>
    </visual>
    <collision>
      <origin rpy="0 0 0" xyz="0 0 0"/>
      <geometry>
        <mesh filename="package://robot_gazebo/meshes/razbot/femur.stl" scale="0.001 0.001 0.001"/>
      </geometry>
      <material name="red"/>
    </collision>
    <inertial>
      <origin rpy="0 0 0" xyz="0 0 0"/>
      <mass value="0.00001"/>
      <inertia ixx="1.0" ixy="0.0" ixz="0.0" iyy="1.0" iyz="0.0" izz="1.0"/>
    </inertial>
  </link>
  <gazebo reference="femur_LF">
    <material>Gazebo/Green</material>
  </gazebo>
  <!-- ****************************************************** Femur Transmission *******************************************************  -->
  <transmission name="femur_transmission_LF">
    <type>transmission_interface/SimpleTransmission</type>
    <joint name="femur_joint_LF">
      <hardwareInterface>EffortJointInterface</hardwareInterface>
    </joint>
    <actuator name="femur_motor_LF">
      <hardwareInterface>EffortJointInterface</hardwareInterface>
      <mechanicalReduction>1</mechanicalReduction>
    </actuator>
  </transmission>
  <!-- ****************************************************** Tibia Joint *************************************************************  -->
  <joint name="tibia_joint_LF" type="revolute">
    <origin rpy="3.141592653589793 0 0" xyz="0.0 -0.065 0.0"/>
    <parent link="femur_LF"/>
    <child link="tibia_LF"/>
    <axis xyz="0.0 0.0 -1"/>
    <limit effort="6.0" lower="-3.141592653589793" upper="3.141592653589793" velocity="5.235987755982989"/>
  </joint>
  <!-- ****************************************************** Tibia Link **************************************************************  -->
  <link name="tibia_LF">
    <visual>
      <origin rpy="0 0 0" xyz="0 0 0"/>
      <geometry>
        <mesh filename="package://robot_gazebo/meshes/razbot/tibia.stl" scale="0.001 0.001 0.001"/>
      </geometry>
      <material name="green"/>
    </visual>
    <collision>
      <origin rpy="0 0 0" xyz="0 0.0 0.0"/>
      <geometry>
        <mesh filename="package://robot_gazebo/meshes/razbot/tibia.stl" scale="0.001 0.001 0.001"/>
      </geometry>
      <material name="green"/>
    </collision>
    <inertial>
      <origin rpy="0 0 0" xyz="0 0.0 0.0"/>
      <mass value="0.00001"/>
      <inertia ixx="1.0" ixy="0.0" ixz="0.0" iyy="1.0" iyz="0.0" izz="1.0"/>
    </inertial>
  </link>
  <gazebo reference="tibia_LF">
    <material>Gazebo/Red</material>
  </gazebo>
  <!-- ****************************************************** Tibia Transmission *****************************************************  -->
  <transmission name="tibia_transmission_LF">
    <type>transmission_interface/SimpleTransmission</type>
    <joint name="tibia_joint_LF">
      <hardwareInterface>EffortJointInterface</hardwareInterface>
    </joint>
    <actuator name="tibia_motor_LF">
      <hardwareInterface>EffortJointInterface</hardwareInterface>
      <mechanicalReduction>1</mechanicalReduction>
    </actuator>
  </transmission>
  <!-- ****************************************************** end of Macro *************************************************************  -->
  <!-- ******************************************************  *************************************************************************  -->
</robot>
