<?xml version="1.0" ?>
<!-- =================================================================================== -->
<!-- |    This document was autogenerated by xacro from src/bots/xacro/skidbot.xacro   | -->
<!-- |    EDITING THIS FILE BY HAND IS NOT RECOMMENDED                                 | -->
<!-- =================================================================================== -->
<robot name="skidbot">
  <!-- ****************************************************** skidbot Robot *************************************************************  -->
  <!-- Muthanna Alwahash                                                                                                                  -->
  <!-- March 2022                                                                                                                         -->
  <!-- *********************************************************************************************************************************  -->
  <!-- ****************************************************** Parameters ***************************************************************  -->
  <!-- x offset from base center -->
  <!-- ****************************************************** Includes *****************************************************************  -->
  <material name="red">
    <color rgba="1.0 0.0 0.0 1.0"/>
  </material>
  <material name="green">
    <color rgba="0.0 1.0 0.0 1.0"/>
  </material>
  <material name="blue">
    <color rgba="0.0 0.0 1.0 1.0"/>
  </material>
  <material name="black">
    <color rgba="0.3 0.3 0.3 1.0"/>
  </material>
  <material name="white">
    <color rgba="1.0 1.0 1.0 1.0"/>
  </material>
  <material name="grey">
    <color rgba="0.2 0.2 0.2 1.0"/>
  </material>
  <material name="orange">
    <color rgba="1.0 0.4235294117647059 0.0392156862745098 1.0"/>
  </material>
  <material name="brown">
    <color rgba="0.8705882352941177 0.8117647058823529 0.7647058823529411 1.0"/>
  </material>
  <material name="yellow">
    <color rgba="1.0 1.0 0.0 1.0"/>
  </material>
  <!-- ****************************************************** diffbot Robot ************************************************************  -->
  <!-- Muthanna Alwahash                                                                                                                  -->
  <!-- March 2022                                                                                                                         -->
  <!-- *********************************************************************************************************************************  -->
  <!-- ****************************************************** Base Link ****************************************************************  -->
  <gazebo reference="base">
    <material>Gazebo/Blue</material>
  </gazebo>
  <!-- ****************************************************** Front caster Link ********************************************************  -->
  <gazebo reference="front_caster">
    <material>Gazebo/White</material>
  </gazebo>
  <!-- ******************************************************  Joint States Publisher **************************************************  -->
  <!-- ******************************************************  Diff Steer Drive Controller *********************************************  -->
  <!-- ******************************************************  Camera ******************************************************************  -->
  <!-- ****************************************************** hokuyo  ******************************************************************  -->
  <!-- ****************************************************** END **********************************************************************  -->
  <!-- Gazebo                                          -->
  <!-- ****************************************************** Base Footprint ***********************************************************  -->
  <link name="footprint"/>
  <!-- ****************************************************** Footprint Joint **********************************************************  -->
  <joint name="footprint_joint" type="fixed">
    <origin rpy="0 0 0" xyz="0 0 0"/>
    <parent link="footprint"/>
    <child link="base"/>
  </joint>
  <!-- ****************************************************** Base Link ****************************************************************  -->
  <link name="base">
    <pose>0 0 0 0 0 0</pose>
    <inertial>
      <mass value="15.0"/>
      <origin rpy=" 0 0 0" xyz="0 0 0"/>
      <inertia ixx="0.1" ixy="0" ixz="0" iyy="0.1" iyz="0" izz="0.1"/>
    </inertial>
    <collision name="collision">
      <origin rpy=" 0 0 0" xyz="0 0 0"/>
      <geometry>
        <mesh filename="package://bots/meshes/skidbot/base.stl" scale="1 1 1"/>
        <!--  <box size="${base_length} ${base_width} ${base_height}"/> -->
      </geometry>
    </collision>
    <visual name="base_visual">
      <origin rpy=" 0 0 0" xyz="0 0 0"/>
      <geometry>
        <mesh filename="package://bots/meshes/skidbot/base.stl" scale="1 1 1"/>
        <!--  <box size="${base_length} ${base_width} ${base_height}"/> -->
      </geometry>
      <material name="blue"/>
    </visual>
  </link>
  <!-- ****************************************************** Wheels Macro *************************************************************  -->
  <!-- ****************************************************** Expand Wheels Macro ******************************************************  -->
  <!-- ****************************************************** Wheel Link ***************************************************************  -->
  <link name="front_right_wheel">
    <inertial>
      <mass value="15.0"/>
      <origin rpy=" 0 1.5707963267948966 1.5707963267948966" xyz="0 0 0"/>
      <inertia ixx="0.1" ixy="0" ixz="0" iyy="0.1" iyz="0" izz="0.1"/>
    </inertial>
    <visual>
      <origin rpy=" 0 1.5707963267948966 1.5707963267948966" xyz="0 0 0"/>
      <geometry>
        <mesh filename="package://bots/meshes/skidbot/wheel.dae"/>
        <!--  <cylinder length="${wheel_width}" radius="${wheel_radius}"/> -->
      </geometry>
      <material name="grey"/>
    </visual>
    <collision>
      <origin rpy=" 0 1.5707963267948966 1.5707963267948966" xyz="0 0 0"/>
      <geometry>
        <mesh filename="package://bots/meshes/skidbot/wheel.dae"/>
        <!--  <cylinder length="${wheel_width}" radius="${wheel_radius}"/> -->
      </geometry>
    </collision>
  </link>
  <!-- ****************************************************** Wheel Joint **************************************************************  -->
  <joint name="front_right_wheel_joint" type="continuous">
    <origin rpy="0 0 0" xyz="0.12 -0.135 0"/>
    <child link="front_right_wheel"/>
    <parent link="base"/>
    <axis rpy="0 0 0" xyz="0 1 0"/>
    <limit effort="10000" velocity="1000"/>
    <dynamics damping="1.0" friction="1.0"/>
  </joint>
  <!-- ****************************************************** End of Macro *************************************************************  -->
  <!-- ****************************************************** Wheel Link ***************************************************************  -->
  <link name="front_left_wheel">
    <inertial>
      <mass value="15.0"/>
      <origin rpy=" 0 1.5707963267948966 1.5707963267948966" xyz="0 0 0"/>
      <inertia ixx="0.1" ixy="0" ixz="0" iyy="0.1" iyz="0" izz="0.1"/>
    </inertial>
    <visual>
      <origin rpy=" 0 1.5707963267948966 1.5707963267948966" xyz="0 0 0"/>
      <geometry>
        <mesh filename="package://bots/meshes/skidbot/wheel.dae"/>
        <!--  <cylinder length="${wheel_width}" radius="${wheel_radius}"/> -->
      </geometry>
      <material name="grey"/>
    </visual>
    <collision>
      <origin rpy=" 0 1.5707963267948966 1.5707963267948966" xyz="0 0 0"/>
      <geometry>
        <mesh filename="package://bots/meshes/skidbot/wheel.dae"/>
        <!--  <cylinder length="${wheel_width}" radius="${wheel_radius}"/> -->
      </geometry>
    </collision>
  </link>
  <!-- ****************************************************** Wheel Joint **************************************************************  -->
  <joint name="front_left_wheel_joint" type="continuous">
    <origin rpy="0 0 0" xyz="0.12 0.135 0"/>
    <child link="front_left_wheel"/>
    <parent link="base"/>
    <axis rpy="0 0 0" xyz="0 1 0"/>
    <limit effort="10000" velocity="1000"/>
    <dynamics damping="1.0" friction="1.0"/>
  </joint>
  <!-- ****************************************************** End of Macro *************************************************************  -->
  <!-- ****************************************************** Wheel Link ***************************************************************  -->
  <link name="back_right_wheel">
    <inertial>
      <mass value="15.0"/>
      <origin rpy=" 0 1.5707963267948966 1.5707963267948966" xyz="0 0 0"/>
      <inertia ixx="0.1" ixy="0" ixz="0" iyy="0.1" iyz="0" izz="0.1"/>
    </inertial>
    <visual>
      <origin rpy=" 0 1.5707963267948966 1.5707963267948966" xyz="0 0 0"/>
      <geometry>
        <mesh filename="package://bots/meshes/skidbot/wheel.dae"/>
        <!--  <cylinder length="${wheel_width}" radius="${wheel_radius}"/> -->
      </geometry>
      <material name="grey"/>
    </visual>
    <collision>
      <origin rpy=" 0 1.5707963267948966 1.5707963267948966" xyz="0 0 0"/>
      <geometry>
        <mesh filename="package://bots/meshes/skidbot/wheel.dae"/>
        <!--  <cylinder length="${wheel_width}" radius="${wheel_radius}"/> -->
      </geometry>
    </collision>
  </link>
  <!-- ****************************************************** Wheel Joint **************************************************************  -->
  <joint name="back_right_wheel_joint" type="continuous">
    <origin rpy="0 0 0" xyz="-0.12 -0.135 0"/>
    <child link="back_right_wheel"/>
    <parent link="base"/>
    <axis rpy="0 0 0" xyz="0 1 0"/>
    <limit effort="10000" velocity="1000"/>
    <dynamics damping="1.0" friction="1.0"/>
  </joint>
  <!-- ****************************************************** End of Macro *************************************************************  -->
  <!-- ****************************************************** Wheel Link ***************************************************************  -->
  <link name="back_left_wheel">
    <inertial>
      <mass value="15.0"/>
      <origin rpy=" 0 1.5707963267948966 1.5707963267948966" xyz="0 0 0"/>
      <inertia ixx="0.1" ixy="0" ixz="0" iyy="0.1" iyz="0" izz="0.1"/>
    </inertial>
    <visual>
      <origin rpy=" 0 1.5707963267948966 1.5707963267948966" xyz="0 0 0"/>
      <geometry>
        <mesh filename="package://bots/meshes/skidbot/wheel.dae"/>
        <!--  <cylinder length="${wheel_width}" radius="${wheel_radius}"/> -->
      </geometry>
      <material name="grey"/>
    </visual>
    <collision>
      <origin rpy=" 0 1.5707963267948966 1.5707963267948966" xyz="0 0 0"/>
      <geometry>
        <mesh filename="package://bots/meshes/skidbot/wheel.dae"/>
        <!--  <cylinder length="${wheel_width}" radius="${wheel_radius}"/> -->
      </geometry>
    </collision>
  </link>
  <!-- ****************************************************** Wheel Joint **************************************************************  -->
  <joint name="back_left_wheel_joint" type="continuous">
    <origin rpy="0 0 0" xyz="-0.12 0.135 0"/>
    <child link="back_left_wheel"/>
    <parent link="base"/>
    <axis rpy="0 0 0" xyz="0 1 0"/>
    <limit effort="10000" velocity="1000"/>
    <dynamics damping="1.0" friction="1.0"/>
  </joint>
  <!-- ****************************************************** End of Macro *************************************************************  -->
  <!-- ****************************************************** Camera Link **************************************************************  -->
  <link name="camera">
    <inertial>
      <mass value="1e-05"/>
      <origin rpy=" 0 0 0" xyz="0 0 0"/>
      <inertia ixx="1e-6" ixy="0" ixz="0" iyy="1e-6" iyz="0" izz="1e-6"/>
    </inertial>
    <visual name="camera_visual">
      <origin rpy="0 0 0" xyz="0 0 0"/>
      <geometry>
        <box size="0.05 0.05 0.05"/>
      </geometry>
      <material name="green"/>
    </visual>
    <collision name="camera_colision">
      <origin rpy="0 0 0" xyz="0 0 0"/>
      <geometry>
        <box size="0.05 0.05 0.05"/>
      </geometry>
    </collision>
  </link>
  <!-- ****************************************************** Camera Joint *************************************************************  -->
  <joint name="camera_joint" type="fixed">
    <origin rpy="0 0 0" xyz="0.2 0 0"/>
    <child link="camera"/>
    <parent link="base"/>
    <axis rpy="0 0 0" xyz="0 1 0"/>
  </joint>
  <!-- ****************************************************** Camera Optical Joint *****************************************************  -->
  <!-- generate an optical frame http://www.ros.org/reps/rep-0103.html#suffix-frames so that ros and opencv can operate on the camera     -->
  <!-- frame correctly. these values have to be these values otherwise the gazebo camera image won't be aligned properly with the frame   -->
  <!-- it is supposedly originating from                                                                                                  -->
                                                                                                                     --&gt;

  
  <joint name="camera_optical_joint" type="fixed">
    <origin rpy="-1.5707963267948966 0 -1.5707963267948966" xyz="0 0 0"/>
    <parent link="camera"/>
    <child link="camera_optical"/>
  </joint>
  <!-- ****************************************************** Camera Optical Link ******************************************************  -->
  <link name="camera_optical"/>
  <!-- ****************************************************** Hokuyo Link **************************************************************  -->
  <link name="hokuyo">
    <inertial>
      <mass value="1e-05"/>
      <origin rpy=" 0 0 0" xyz="0 0 0"/>
      <inertia ixx="1e-6" ixy="0" ixz="0" iyy="1e-6" iyz="0" izz="1e-6"/>
    </inertial>
    <visual name="hokuyo_visual">
      <origin rpy="0 0 0" xyz="0 0 0"/>
      <geometry>
        <mesh filename="package://bots/meshes/skidbot/hokuyo.dae"/>
        <!--  <box size="${hokuyo_length} ${hokuyo_width} ${hokuyo_height}"/> -->
      </geometry>
      <!-- <material name="red"/> -->
    </visual>
    <collision name="hokuyo_colision">
      <origin rpy="0 0 0" xyz="0 0 0"/>
      <geometry>
        <box size="0.05 0.05 0.0706"/>
      </geometry>
    </collision>
  </link>
  <!-- ****************************************************** Hokuyo Joint *************************************************************  -->
  <joint name="hokuyo_joint" type="fixed">
    <origin rpy="0 0 0" xyz="0.11 0 0.0853"/>
    <child link="hokuyo"/>
    <parent link="base"/>
    <axis rpy="0 0 0" xyz="0 1 0"/>
  </joint>
  <!-- ****************************************************** end **********************************************************************  -->
</robot>
