<?xml version="1.0" ?>
<!-- =================================================================================== -->
<!-- |    This document was autogenerated by xacro from src/bots/xacro/twr.xacro | -->
<!-- |    EDITING THIS FILE BY HAND IS NOT RECOMMENDED                                 | -->
<!-- =================================================================================== -->
<robot name="twr">
  <!-- ****************************************************** Two Wheeled Robot ********************************************************  -->
  <!-- Muthanna Alwahash                                                                                                                  -->
  <!-- March 2022                                                                                                                         -->
  <!-- *********************************************************************************************************************************  -->
  <!-- ****************************************************** Parameters ***************************************************************  -->
  <!-- Position the caster wheel along the x-axis                                   -->
  <!-- ****************************************************** Includes *****************************************************************  -->
  <material name="red">
    <color rgba="1.0 0.0 0.0 1.0"/>
  </material>
  <material name="green">
    <color rgba="0.0 1.0 0.0 1.0"/>
  </material>
  <material name="blue">
    <color rgba="0.0 0.0 1.0 1.0"/>
  </material>
  <material name="black">
    <color rgba="0.3 0.3 0.3 1.0"/>
  </material>
  <material name="white">
    <color rgba="1.0 1.0 1.0 1.0"/>
  </material>
  <material name="grey">
    <color rgba="0.2 0.2 0.2 1.0"/>
  </material>
  <material name="orange">
    <color rgba="1.0 0.4235294117647059 0.0392156862745098 1.0"/>
  </material>
  <material name="brown">
    <color rgba="0.8705882352941177 0.8117647058823529 0.7647058823529411 1.0"/>
  </material>
  <material name="yellow">
    <color rgba="1.0 1.0 0.0 1.0"/>
  </material>
  <!-- ****************************************************** Two Wheeled Robot ********************************************************  -->
  <!-- Muthanna Alwahash                                                                                                                  -->
  <!-- March 2022                                                                                                                         -->
  <!-- *********************************************************************************************************************************  -->
  <!-- ****************************************************** Base Link ****************************************************************  -->
  <gazebo reference="base_link">
    <material>Gazebo/Red</material>
  </gazebo>
  <!-- ****************************************************** Drive Wheels Link Macro **************************************************  -->
  <!-- ****************************************************** Drive Wheels Link and Joint **********************************************  -->
  <gazebo reference="drivewhl_l_link">
    <material>Gazebo/FlatBlack</material>
  </gazebo>
  <gazebo reference="drivewhl_r_link">
    <material>Gazebo/FlatBlack</material>
  </gazebo>
  <!-- ****************************************************** Front Caster Link ********************************************************  -->
  <gazebo reference="front_caster">
    <material>Gazebo/White</material>
  </gazebo>
  <!-- ****************************************************** LIDAR Link ***************************************************************  -->
  <gazebo reference="lidar_link">
    <material>Gazebo/Green</material>
  </gazebo>
  <!-- *********************************************************************************************************************************  -->
  <!-- Gazebo                                     -->
  <!-- ****************************************************** Macros *******************************************************************  -->
  <!-- Define intertial property macros                                                                                                   -->
  <!-- ****************************************************** Base Footprint Link ******************************************************  -->
  <!-- Define the center of the main robot chassis projected on the ground                                                                -->
  <link name="base_footprint"/>
  <!-- ****************************************************** Base Footprint Joint *****************************************************  -->
  <!-- The base footprint of the robot is located underneath the chassis                                                                  -->
  <joint name="base_joint" type="fixed">
    <parent link="base_footprint"/>
    <child link="base_link"/>
    <origin rpy="0 0 0" xyz="0.0 0.0 0.19"/>
  </joint>
  <!-- ****************************************************** Base Link ****************************************************************  -->
  <link name="base_link">
    <visual>
      <origin rpy="0 0 0" xyz="0 0 0"/>
      <geometry>
        <mesh filename="package://bots/meshes/twr/robot_base.stl"/>
      </geometry>
      <material name="red"/>
    </visual>
    <collision>
      <geometry>
        <box size="0.7 0.39 0.2"/>
      </geometry>
    </collision>
    <inertial>
      <origin rpy="1.5707963267948966 0 1.5707963267948966" xyz="0 0 0"/>
      <mass value="40.0"/>
      <inertia ixx="1.7666666666666664" ixy="0.0" ixz="0.0" iyy="2.140333333333333" iyz="0.0" izz="0.6403333333333334"/>
    </inertial>
  </link>
  <!-- ****************************************************** Drive Wheels Link Macro **************************************************  -->
  <!-- ****************************************************** Drive Wheels Link and Joint **********************************************  -->
  <!-- Instantiate two wheels using the macro we just made through the xacro:wheel tags. We also define the parameters to have one        -->
  <!-- wheel on both sides at the back of our robot (i.e. x_reflect=-1).                                                                  -->
  <link name="drivewhl_l_link">
    <visual>
      <origin rpy="1.5707963267948966 0 0" xyz="0 0 0"/>
      <geometry>
        <cylinder length="0.06" radius="0.14"/>
      </geometry>
      <material name="black"/>
    </visual>
    <collision>
      <origin rpy="1.5707963267948966 0 0" xyz="0 0 0"/>
      <geometry>
        <cylinder length="0.06" radius="0.14"/>
      </geometry>
    </collision>
    <inertial>
      <origin rpy="1.5707963267948966 0 0" xyz="0 0 0"/>
      <mass value="110.5"/>
      <inertia ixx="0.5746000000000001" ixy="0" ixz="0" iyy="0.5746000000000001" iyz="0" izz="1.0829000000000002"/>
    </inertial>
  </link>
  <!-- ****************************************************** Drive Wheels Joint Macro *************************************************  -->
  <!-- Connect the wheels to the base_link at the appropriate location, and define a continuous joint to allow the wheels to freely       -->
  <!-- rotate about an axis                                                                                                               -->
  <joint name="drivewhl_l_joint" type="revolute">
    <parent link="base_link"/>
    <child link="drivewhl_l_link"/>
    <origin rpy="0 0 0" xyz="-0.221 0.23 -0.05"/>
    <limit effort="30" lower="-3.141592653589793" upper="3.141592653589793" velocity="5.0"/>
    <axis xyz="0 1 0"/>
  </joint>
  <!-- ****************************************************** End of Macro *************************************************************  -->
  <link name="drivewhl_r_link">
    <visual>
      <origin rpy="1.5707963267948966 0 0" xyz="0 0 0"/>
      <geometry>
        <cylinder length="0.06" radius="0.14"/>
      </geometry>
      <material name="black"/>
    </visual>
    <collision>
      <origin rpy="1.5707963267948966 0 0" xyz="0 0 0"/>
      <geometry>
        <cylinder length="0.06" radius="0.14"/>
      </geometry>
    </collision>
    <inertial>
      <origin rpy="1.5707963267948966 0 0" xyz="0 0 0"/>
      <mass value="110.5"/>
      <inertia ixx="0.5746000000000001" ixy="0" ixz="0" iyy="0.5746000000000001" iyz="0" izz="1.0829000000000002"/>
    </inertial>
  </link>
  <!-- ****************************************************** Drive Wheels Joint Macro *************************************************  -->
  <!-- Connect the wheels to the base_link at the appropriate location, and define a continuous joint to allow the wheels to freely       -->
  <!-- rotate about an axis                                                                                                               -->
  <joint name="drivewhl_r_joint" type="revolute">
    <parent link="base_link"/>
    <child link="drivewhl_r_link"/>
    <origin rpy="0 0 0" xyz="-0.221 -0.23 -0.05"/>
    <limit effort="30" lower="-3.141592653589793" upper="3.141592653589793" velocity="5.0"/>
    <axis xyz="0 1 0"/>
  </joint>
  <!-- ****************************************************** End of Macro *************************************************************  -->
  <!-- ****************************************************** Front Caster Link ********************************************************  -->
  <!-- We add a caster wheel. It will be modeled as sphere. We define the wheel’s geometry, material and the joint to connect it to       -->
  <!-- base_link at the appropriate location.                                                                                             -->
  <link name="front_caster">
    <visual>
      <geometry>
        <sphere radius="0.09"/>
      </geometry>
      <material name="white"/>
    </visual>
    <collision>
      <origin rpy="0 0 0" xyz="0 0 0"/>
      <geometry>
        <sphere radius="0.09"/>
      </geometry>
    </collision>
    <inertial>
      <mass value="10.05"/>
      <inertia ixx="0.032562" ixy="0.0" ixz="0.0" iyy="0.032562" iyz="0.0" izz="0.032562"/>
    </inertial>
  </link>
  <!-- **************************************************** Front Caster Joint *********************************************************  -->
  <joint name="caster_joint" type="fixed">
    <parent link="base_link"/>
    <child link="front_caster"/>
    <origin rpy="0 0 0" xyz="0.217 0.0 -0.1"/>
  </joint>
  <!-- ****************************************************** IMU Joint ****************************************************************  -->
  <!-- Each sensor must be attached to a link.                                                                                            -->
  <joint name="imu_joint" type="fixed">
    <parent link="base_link"/>
    <child link="imu_link"/>
    <origin rpy="0 0 0" xyz="-0.10 0 0.05"/>
  </joint>
  <!-- ****************************************************** IMU Link *****************************************************************  -->
  <link name="imu_link"/>
  <!-- ****************************************************** LIDAR Joint **************************************************************  -->
  <joint name="lidar_joint" type="fixed">
    <parent link="base_link"/>
    <child link="lidar_link"/>
    <origin rpy="0 0 0" xyz="0.215 0 0.13"/>
  </joint>
  <!-- ****************************************************** LIDAR Link ***************************************************************  -->
  <link name="lidar_link">
    <collision>
      <origin rpy="0 0 0" xyz="0 0 0"/>
      <geometry>
        <cylinder length="0.18" radius="0.0508"/>
      </geometry>
    </collision>
    <visual>
      <origin rpy="0 0 0" xyz="0 0 0"/>
      <geometry>
        <cylinder length="0.18" radius="0.0508"/>
      </geometry>
      <material name="green"/>
    </visual>
    <inertial>
      <mass value="0.114"/>
      <origin rpy="0 0 0" xyz="0 0 0"/>
      <inertia ixx="0.001" ixy="0" ixz="0" iyy="0.001" iyz="0" izz="0.001"/>
    </inertial>
  </link>
  <!-- *********************************************************************************************************************************  -->
</robot>
