<sdf version='1.7'>
  <model name='diffbot'>
    <link name='footprint'>
      <inertial>
        <pose>0.043126 0 0.098751 0 -0 0</pose>
        <mass>0.80001</mass>
        <inertia>
          <ixx>0.00884183</ixx>
          <ixy>0</ixy>
          <ixz>0.000509314</ixz>
          <iyy>0.00745657</iyy>
          <iyz>0</iyz>
          <izz>0.0147377</izz>
        </inertia>
      </inertial>
      <collision name='footprint_fixed_joint_lump__base_collision'>
        <pose>0 0 0.105 0 -0 0</pose>
        <geometry>
          <mesh>
            <scale>1 1 1</scale>
            <uri>model://robot_gazebo/meshes/diffbot/base.stl</uri>
          </mesh>
        </geometry>
        <surface>
          <contact>
            <ode/>
          </contact>
          <friction>
            <ode/>
          </friction>
        </surface>
      </collision>
      <collision name='footprint_fixed_joint_lump__camera_colision_collision_1'>
        <pose>0.2 0 0.105 0 -0 0</pose>
        <geometry>
          <box>
            <size>0.05 0.05 0.05</size>
          </box>
        </geometry>
      </collision>
      <collision name='footprint_fixed_joint_lump__front_caster_collision_2'>
        <pose>0.145 0 0.055 0 -0 0</pose>
        <geometry>
          <sphere>
            <radius>0.055</radius>
          </sphere>
        </geometry>
        <surface>
          <contact>
            <ode/>
          </contact>
          <friction>
            <ode/>
          </friction>
        </surface>
      </collision>
      <collision name='footprint_fixed_joint_lump__hokuyo_colision_collision_3'>
        <pose>0.11 0 0.1903 0 -0 0</pose>
        <geometry>
          <mesh>
            <scale>1 1 1</scale>
            <uri>model://robot_gazebo/meshes/diffbot/hokuyo.dae</uri>
          </mesh>
        </geometry>
      </collision>
      <visual name='footprint_fixed_joint_lump__base_visual'>
        <pose>0 0 0.105 0 -0 0</pose>
        <geometry>
          <mesh>
            <scale>1 1 1</scale>
            <uri>model://robot_gazebo/meshes/diffbot/base.stl</uri>
          </mesh>
        </geometry>
        <material>
          <script>
            <name>Gazebo/Blue</name>
            <uri>file://media/materials/scripts/gazebo.material</uri>
          </script>
        </material>
      </visual>
      <visual name='footprint_fixed_joint_lump__camera_visual_visual_1'>
        <pose>0.2 0 0.105 0 -0 0</pose>
        <geometry>
          <box>
            <size>0.05 0.05 0.05</size>
          </box>
        </geometry>
        <material>
          <script>
            <name>Gazebo/Green</name>
            <uri>file://media/materials/scripts/gazebo.material</uri>
          </script>
        </material>
      </visual>
      <visual name='footprint_fixed_joint_lump__front_caster_visual_2'>
        <pose>0.145 0 0.055 0 -0 0</pose>
        <geometry>
          <sphere>
            <radius>0.055</radius>
          </sphere>
        </geometry>
        <material>
          <script>
            <name>Gazebo/White</name>
            <uri>file://media/materials/scripts/gazebo.material</uri>
          </script>
        </material>
      </visual>
      <visual name='footprint_fixed_joint_lump__hokuyo_visual_visual_3'>
        <pose>0.11 0 0.1903 0 -0 0</pose>
        <geometry>
          <mesh>
            <scale>1 1 1</scale>
            <uri>model://robot_gazebo/meshes/diffbot/hokuyo.dae</uri>
          </mesh>
        </geometry>
      </visual>
      <sensor name='camera_sensor' type='camera'>
        <plugin name='camera' filename='libgazebo_ros_camera.so'>
          <ros>
            <namespace>diffbot</namespace>
          </ros>
          <camera_name>camera</camera_name>
          <frame_name>camera</frame_name>
          <hack_baseline>0.07</hack_baseline>
        </plugin>
        <update_rate>30</update_rate>
        <always_on>1</always_on>
        <camera name='camera'>
          <horizontal_fov>1.39626</horizontal_fov>
          <image>
            <width>1280</width>
            <height>720</height>
            <format>R8G8B8</format>
          </image>
          <clip>
            <near>0.02</near>
            <far>300</far>
          </clip>
          <distortion>
            <k1>0</k1>
            <k2>0</k2>
            <k3>0</k3>
            <p1>0</p1>
            <p2>0</p2>
            <center>0.5 0.5</center>
          </distortion>
        </camera>
        <pose>0.2 0 0.105 0 -0 0</pose>
      </sensor>
      <sensor name='head_hokuyo_sensor' type='ray'>
        <plugin name='hokuyo' filename='libgazebo_ros_ray_sensor.so'>
          <ros>
            <namespace>diffbot</namespace>
          </ros>
          <output_type>sensor_msgs/LaserScan</output_type>
        </plugin>
        <update_rate>30</update_rate>
        <visualize>0</visualize>
        <ray>
          <scan>
            <horizontal>
              <samples>720</samples>
              <resolution>1</resolution>
              <min_angle>-3.14159</min_angle>
              <max_angle>3.14159</max_angle>
            </horizontal>
          </scan>
          <range>
            <min>0.1</min>
            <max>30</max>
            <resolution>0.01</resolution>
          </range>
          <noise>
            <type>gaussian</type>
            <mean>0</mean>
            <stddev>0.01</stddev>
          </noise>
        </ray>
        <pose>0.11 0 0.1903 0 -0 0</pose>
      </sensor>
    </link>
    <joint name='left_wheel_joint' type='revolute'>
      <pose relative_to='footprint'>-0.12 -0.135 0.08 0 -0 0</pose>
      <parent>footprint</parent>
      <child>left_wheel</child>
      <axis>
        <xyz>0 1 0</xyz>
        <limit>
          <effort>30</effort>
          <velocity>5</velocity>
          <lower>-1e+16</lower>
          <upper>1e+16</upper>
        </limit>
        <dynamics>
          <damping>0.2</damping>
          <friction>0</friction>
          <spring_reference>0</spring_reference>
          <spring_stiffness>0</spring_stiffness>
        </dynamics>
      </axis>
    </joint>
    <link name='left_wheel'>
      <pose relative_to='left_wheel_joint'>0 0 0 0 -0 0</pose>
      <inertial>
        <pose>0 0 0 1.5708 -0 0</pose>
        <mass>5</mass>
        <inertia>
          <ixx>0.101042</ixx>
          <ixy>0</ixy>
          <ixz>0</ixz>
          <iyy>0.00266667</iyy>
          <iyz>0</iyz>
          <izz>0.00266667</izz>
        </inertia>
      </inertial>
      <collision name='left_wheel_collision'>
        <pose>0 0 0 1.5708 -0 0</pose>
        <geometry>
          <mesh>
            <scale>1 1 1</scale>
            <uri>model://robot_gazebo/meshes/diffbot/wheel.dae</uri>
          </mesh>
        </geometry>
      </collision>
      <visual name='left_wheel_visual'>
        <pose>0 0 0 1.5708 -0 0</pose>
        <geometry>
          <mesh>
            <scale>1 1 1</scale>
            <uri>model://robot_gazebo/meshes/diffbot/wheel.dae</uri>
          </mesh>
        </geometry>
      </visual>
    </link>
    <joint name='right_wheel_joint' type='revolute'>
      <pose relative_to='footprint'>-0.12 0.135 0.08 0 -0 0</pose>
      <parent>footprint</parent>
      <child>right_wheel</child>
      <axis>
        <xyz>0 1 0</xyz>
        <limit>
          <effort>30</effort>
          <velocity>5</velocity>
          <lower>-1e+16</lower>
          <upper>1e+16</upper>
        </limit>
        <dynamics>
          <damping>0.2</damping>
          <friction>0</friction>
          <spring_reference>0</spring_reference>
          <spring_stiffness>0</spring_stiffness>
        </dynamics>
      </axis>
    </joint>
    <link name='right_wheel'>
      <pose relative_to='right_wheel_joint'>0 0 0 0 -0 0</pose>
      <inertial>
        <pose>0 0 0 1.5708 -0 0</pose>
        <mass>5</mass>
        <inertia>
          <ixx>0.101042</ixx>
          <ixy>0</ixy>
          <ixz>0</ixz>
          <iyy>0.00266667</iyy>
          <iyz>0</iyz>
          <izz>0.00266667</izz>
        </inertia>
      </inertial>
      <collision name='right_wheel_collision'>
        <pose>0 0 0 1.5708 -0 0</pose>
        <geometry>
          <mesh>
            <scale>1 1 1</scale>
            <uri>model://robot_gazebo/meshes/diffbot/wheel.dae</uri>
          </mesh>
        </geometry>
      </collision>
      <visual name='right_wheel_visual'>
        <pose>0 0 0 1.5708 -0 0</pose>
        <geometry>
          <mesh>
            <scale>1 1 1</scale>
            <uri>model://robot_gazebo/meshes/diffbot/wheel.dae</uri>
          </mesh>
        </geometry>
      </visual>
    </link>
    <plugin name='joint_states_pub' filename='libgazebo_ros_joint_state_publisher.so'>
      <ros>
        <namespace>diffbot</namespace>
      </ros>
      <joint_name>right_wheel_joint</joint_name>
      <joint_name>left_wheel_joint</joint_name>
      <update_rate>100.0</update_rate>
    </plugin>
    <static>0</static>
    <plugin name='skid_drive' filename='libgazebo_ros_diff_drive.so'>
      <ros>
        <namespace>diffbot</namespace>
      </ros>
      <num_wheel_pairs>1</num_wheel_pairs>
      <right_joint>right_wheel_joint</right_joint>
      <left_joint>left_wheel_joint</left_joint>
      <wheel_separation>0.27</wheel_separation>
      <wheel_diameter>0.16</wheel_diameter>
      <max_wheel_torque>20</max_wheel_torque>
      <max_wheel_acceleration>1.0</max_wheel_acceleration>
      <update_rate>100.0</update_rate>
      <robot_base_frame>footprint</robot_base_frame>
      <odometry_frame>odom</odometry_frame>
      <publish_odom>1</publish_odom>
      <publish_odom_tf>1</publish_odom_tf>
      <publish_wheel_tf>1</publish_wheel_tf>
    </plugin>
  </model>
</sdf>
