<sdf version='1.7'>
  <model name='diffbot'>
    <link name='footprint'>
      <inertial>
        <pose>0.043126 0 0.098751 0 -0 0</pose>
        <mass>0.80001</mass>
        <inertia>
          <ixx>0.00884183</ixx>
          <ixy>0</ixy>
          <ixz>0.000509314</ixz>
          <iyy>0.00745657</iyy>
          <iyz>0</iyz>
          <izz>0.0147377</izz>
        </inertia>
      </inertial>
      <collision name='footprint_fixed_joint_lump__base_collision'>
        <pose>0 0 0.105 0 -0 0</pose>
        <geometry>
          <mesh>
            <scale>1 1 1</scale>
            <uri>model://bots/meshes/diffbot/base.stl</uri>
          </mesh>
        </geometry>
        <surface>
          <contact>
            <ode/>
          </contact>
          <friction>
            <ode/>
          </friction>
        </surface>
      </collision>
      <collision name='footprint_fixed_joint_lump__camera_colision_collision_1'>
        <pose>0.2 0 0.105 0 -0 0</pose>
        <geometry>
          <box>
            <size>0.05 0.05 0.05</size>
          </box>
        </geometry>
      </collision>
      <collision name='footprint_fixed_joint_lump__front_caster_collision_2'>
        <pose>0.145 0 0.055 0 -0 0</pose>
        <geometry>
          <sphere>
            <radius>0.055</radius>
          </sphere>
        </geometry>
        <surface>
          <contact>
            <ode/>
          </contact>
          <friction>
            <ode/>
          </friction>
        </surface>
      </collision>
      <collision name='footprint_fixed_joint_lump__hokuyo_colision_collision_3'>
        <pose>0.11 0 0.1903 0 -0 0</pose>
        <geometry>
          <box>
            <size>0.05 0.05 0.0706</size>
          </box>
        </geometry>
      </collision>
      <visual name='footprint_fixed_joint_lump__base_visual'>
        <pose>0 0 0.105 0 -0 0</pose>
        <geometry>
          <mesh>
            <scale>1 1 1</scale>
            <uri>model://bots/meshes/diffbot/base.stl</uri>
          </mesh>
        </geometry>
        <material>
          <script>
            <name>Gazebo/Blue</name>
            <uri>file://media/materials/scripts/gazebo.material</uri>
          </script>
        </material>
      </visual>
      <visual name='footprint_fixed_joint_lump__camera_visual_visual_1'>
        <pose>0.2 0 0.105 0 -0 0</pose>
        <geometry>
          <box>
            <size>0.05 0.05 0.05</size>
          </box>
        </geometry>
      </visual>
      <visual name='footprint_fixed_joint_lump__front_caster_visual_2'>
        <pose>0.145 0 0.055 0 -0 0</pose>
        <geometry>
          <sphere>
            <radius>0.055</radius>
          </sphere>
        </geometry>
        <material>
          <script>
            <name>Gazebo/White</name>
            <uri>file://media/materials/scripts/gazebo.material</uri>
          </script>
        </material>
      </visual>
      <visual name='footprint_fixed_joint_lump__hokuyo_visual_visual_3'>
        <pose>0.11 0 0.1903 0 -0 0</pose>
        <geometry>
          <mesh>
            <scale>1 1 1</scale>
            <uri>model://bots/meshes/diffbot/hokuyo.dae</uri>
          </mesh>
        </geometry>
      </visual>
    </link>
    <joint name='left_wheel_joint' type='revolute'>
      <pose relative_to='footprint'>-0.12 -0.135 0.08 0 -0 0</pose>
      <parent>footprint</parent>
      <child>left_wheel</child>
      <axis>
        <xyz>0 1 0</xyz>
        <limit>
          <effort>30</effort>
          <velocity>5</velocity>
          <lower>-1e+16</lower>
          <upper>1e+16</upper>
        </limit>
        <dynamics>
          <damping>0.2</damping>
          <friction>0</friction>
          <spring_reference>0</spring_reference>
          <spring_stiffness>0</spring_stiffness>
        </dynamics>
      </axis>
    </joint>
    <link name='left_wheel'>
      <pose relative_to='left_wheel_joint'>0 0 0 0 -0 0</pose>
      <inertial>
        <pose>0 0 0 1.5708 -0 0</pose>
        <mass>5</mass>
        <inertia>
          <ixx>0.101042</ixx>
          <ixy>0</ixy>
          <ixz>0</ixz>
          <iyy>0.00266667</iyy>
          <iyz>0</iyz>
          <izz>0.00266667</izz>
        </inertia>
      </inertial>
      <collision name='left_wheel_collision'>
        <pose>0 0 0 1.5708 -0 0</pose>
        <geometry>
          <mesh>
            <scale>1 1 1</scale>
            <uri>model://bots/meshes/diffbot/wheel.dae</uri>
          </mesh>
        </geometry>
      </collision>
      <visual name='left_wheel_visual'>
        <pose>0 0 0 1.5708 -0 0</pose>
        <geometry>
          <mesh>
            <scale>1 1 1</scale>
            <uri>model://bots/meshes/diffbot/wheel.dae</uri>
          </mesh>
        </geometry>
      </visual>
    </link>
    <joint name='right_wheel_joint' type='revolute'>
      <pose relative_to='footprint'>-0.12 0.135 0.08 0 -0 0</pose>
      <parent>footprint</parent>
      <child>right_wheel</child>
      <axis>
        <xyz>0 1 0</xyz>
        <limit>
          <effort>30</effort>
          <velocity>5</velocity>
          <lower>-1e+16</lower>
          <upper>1e+16</upper>
        </limit>
        <dynamics>
          <damping>0.2</damping>
          <friction>0</friction>
          <spring_reference>0</spring_reference>
          <spring_stiffness>0</spring_stiffness>
        </dynamics>
      </axis>
    </joint>
    <link name='right_wheel'>
      <pose relative_to='right_wheel_joint'>0 0 0 0 -0 0</pose>
      <inertial>
        <pose>0 0 0 1.5708 -0 0</pose>
        <mass>5</mass>
        <inertia>
          <ixx>0.101042</ixx>
          <ixy>0</ixy>
          <ixz>0</ixz>
          <iyy>0.00266667</iyy>
          <iyz>0</iyz>
          <izz>0.00266667</izz>
        </inertia>
      </inertial>
      <collision name='right_wheel_collision'>
        <pose>0 0 0 1.5708 -0 0</pose>
        <geometry>
          <mesh>
            <scale>1 1 1</scale>
            <uri>model://bots/meshes/diffbot/wheel.dae</uri>
          </mesh>
        </geometry>
      </collision>
      <visual name='right_wheel_visual'>
        <pose>0 0 0 1.5708 -0 0</pose>
        <geometry>
          <mesh>
            <scale>1 1 1</scale>
            <uri>model://bots/meshes/diffbot/wheel.dae</uri>
          </mesh>
        </geometry>
      </visual>
    </link>
  </model>
</sdf>
